Workbook

Sheet OUT Before Season
A1: From | B1: 2025 | C1: Bank | D1: Drop Box | E1: Total
A2: Opening | B2: 2717.69 | C2: 89327.83 | D2: 89827 | E2: =C2+D2 -> 179154.83
A3: Obra-Cafe | B3: 2717.69 | C3: =SUMIFS(Dados!$N:$N,Dados!$D:$D,$C$1,Dados!$A:$A,A3,Dados!$P:$P,"") -> 38815.79 | D3: =SUMIFS(Dados!$N:$N,Dados!$D:$D,$D$1,Dados!$A:$A,A3) -> 37346.96 | E3: =SUM(B3:D3) -> 78880.44
A4: Contabilidade | C4: =SUMIFS(Dados!$N:$N,Dados!$D:$D,$C$1,Dados!$B:$B,A4,Dados!$P:$P,"") -> 1758 | D4: =SUMIFS(Dados!$N:$N,Dados!$D:$D,$D$1,Dados!$B:$B,A4) -> 0 | E4: =SUM(B4:D4) -> 1758
A5: Adrien | C5: =SUMIFS(Dados!$N:$N,Dados!$D:$D,$C$1,Dados!$B:$B,A5,Dados!$P:$P,"") -> 9078.77 | D5: =SUMIFS(Dados!$N:$N,Dados!$D:$D,$D$1,Dados!$B:$B,A5) -> 0 | E5: =SUM(B5:D5) -> 9078.77
A6: NOSInternet | C6: =SUMIFS(Dados!$N:$N,Dados!$D:$D,$C$1,Dados!$B:$B,A6,Dados!$P:$P,"") -> 466.56 | D6: =SUMIFS(Dados!$N:$N,Dados!$D:$D,$D$1,Dados!$B:$B,A6) -> 0 | E6: =SUM(B6:D6) -> 466.56
A7: Fees | C7: =SUMIFS(Dados!$N:$N,Dados!$D:$D,$C$1,Dados!$B:$B,A7,Dados!$P:$P,"") -> 39.45 | D7: =SUMIFS(Dados!$N:$N,Dados!$D:$D,$D$1,Dados!$B:$B,A7) -> 0 | E7: =SUM(B7:D7) -> 39.45
A8: Aggema | C8: =SUMIFS(Dados!$N:$N,Dados!$D:$D,$C$1,Dados!$B:$B,A8,Dados!$P:$P,"") -> 1153.1 | D8: =SUMIFS(Dados!$N:$N,Dados!$D:$D,$D$1,Dados!$B:$B,A8) -> 0 | E8: =SUM(B8:D8) -> 1153.1
A9: EnergiaEDP | C9: =SUMIFS(Dados!$N:$N,Dados!$D:$D,$C$1,Dados!$B:$B,A9,Dados!$P:$P,"") -> 1461.94 | D9: =SUMIFS(Dados!$N:$N,Dados!$D:$D,$D$1,Dados!$B:$B,A9) -> 0 | E9: =SUM(B9:D9) -> 1461.94
A10: ÁguaFAGAR | C10: =SUMIFS(Dados!$N:$N,Dados!$D:$D,$C$1,Dados!$B:$B,A10,Dados!$P:$P,"") -> 1055.45 | D10: =SUMIFS(Dados!$N:$N,Dados!$D:$D,$D$1,Dados!$B:$B,A10) -> 0 | E10: =SUM(B10:D10) -> 1055.45
A11: CFE | C11: =SUMIFS(Dados!$N:$N,Dados!$D:$D,$C$1,Dados!$B:$B,A11,Dados!$P:$P,"") -> 780 | D11: =SUMIFS(Dados!$N:$N,Dados!$D:$D,$D$1,Dados!$B:$B,A11) -> 0 | E11: =SUM(B11:D11) -> 780
A12: Invest | C12: =SUMIFS(Dados!$N:$N,Dados!$D:$D,$C$1,Dados!$B:$B,A12,Dados!$P:$P,"") -> 18500 | D12: =SUMIFS(Dados!$N:$N,Dados!$D:$D,$D$1,Dados!$B:$B,A12) -> 0 | E12: =SUM(B12:D12) -> 18500
A13: Seg.Soc. | C13: =SUMIFS(Dados!$N:$N,Dados!$D:$D,$C$1,Dados!$B:$B,A13,Dados!$P:$P,"") -> 812.4 | D13: =SUMIFS(Dados!$N:$N,Dados!$D:$D,$D$1,Dados!$B:$B,A13) -> 0 | E13: =SUM(B13:D13) -> 812.4
A14: IVA | C14: =SUMIFS(Dados!$N:$N,Dados!$D:$D,$C$1,Dados!$B:$B,A14,Dados!$P:$P,"") -> 224.05 | D14: =SUMIFS(Dados!$N:$N,Dados!$D:$D,$D$1,Dados!$B:$B,A14) -> 0 | E14: =SUM(B14:D14) -> 224.05
A15: UberCopter | C15: =SUMIFS(Dados!$N:$N,Dados!$D:$D,$C$1,Dados!$B:$B,A15,Dados!$P:$P,"") -> 34.66 | D15: =SUMIFS(Dados!$N:$N,Dados!$D:$D,$D$1,Dados!$B:$B,A15) -> 0 | E15: =SUM(B15:D15) -> 34.66
... A17: Cloudbeds | C17: =SUMIFS(Dados!$N:$N,Dados!$D:$D,$C$1,Dados!$B:$B,A17,Dados!$P:$P,"") -> 436.5 | D17: =SUMIFS(Dados!$N:$N,Dados!$D:$D,$D$1,Dados!$B:$B,A17) -> 0 | E17: =SUM(B17:D17) -> 436.5
A18: Total OUT | B18: =SUM(B3:B17) -> 2717.69 | C18: =SUM(C3:C17) -> 74735.4 | D18: =SUM(D3:D17) -> 37346.96 | E18: =SUM(E3:E17) -> 114800.05
A19: Final | B19: =B2-B18 -> 0 | C19: =C2-C18 -> 14592.43 | D19: =D2-D18 -> 52480.04 | E19: =SUM(C19:D19) -> 67072.47
A20: Final for reals | E20: =SUM(C20:D20) -> 0
A21: Difference | E21: =SUM(C21:D21) -> 0

Sheet Obra cash flow 1
A1: From | B1: 10k1 | C1: 10k2 | D1: 10k3 | E1: 5k4 | F1: 5k5 | G1: 2025 | H1: Bank | I1: Revolut | J1: AdrianMoney | K1: MoneyBox | L1: Total
A2: Coluna M | B2: Drop10.000-01/01/2026 | C2: Drop10.000-20/02/2026 | D2: Drop10.000-28/02/2026 | E2: Drop5.000-01/05/2026 | F2: Drop5.000-01/06/2026 | G2: 2025
A3: Date | B3: 46023 | C3: 46073 | D3: 46081 | E3: 46143 | F3: 46174 | G3: 46023
A4: Opening | B4: 10000 | C4: 10000 | D4: 10000 | E4: 5000 | F4: 5000
A5: Cafe/food-Cafe | B5: =SUMIFS(Dados!$N:$N,Dados!$P:$P,$B$2,Dados!$B:$B,A5) -> 418.5 | C5: =SUMIFS(Dados!$N:$N,Dados!$P:$P,$C$2,Dados!$B:$B,A5) -> 10 | D5: =SUMIFS(Dados!$N:$N,Dados!$P:$P,$D$2,Dados!$B:$B,A5) -> 0 | E5: =SUMIFS(Dados!$N:$N,Dados!$P:$P,$E$2,Dados!$B:$B,A5) -> 0 | F5: =SUMIFS(Dados!$N:$N,Dados!$P:$P,$F$2,Dados!$B:$B,A5) -> 0 | G5: =SUMIFS(Dados!$N:$N,Dados!$P:$P,$G$2,Dados!$B:$B,A5) -> 0 | H5: =SUMIFS(Dados!$N:$N,Dados!$D:$D,$H$1,Dados!$B:$B,A5,Dados!$P:$P,"") -> 409.32 | I5: =SUMIFS(Dados!$N:$N,Dados!$D:$D,$I$1,Dados!$B:$B,A5) -> 0 | J5: =SUMIFS(Dados!$N:$N,Dados!$D:$D,$J$1,Dados!$B:$B,A5) -> 0 | K5: =SUMIFS(Dados!$N:$N,Dados!$D:$D,$K$1,Dados!$B:$B,A5) -> 0 | L5: =SUM(B5:K5) -> 837.82
A6: Furnitures-Cafe | B6: =SUMIFS(Dados!$N:$N,Dados!$P:$P,$B$2,Dados!$B:$B,A6) -> 0 | C6: =SUMIFS(Dados!$N:$N,Dados!$P:$P,$C$2,Dados!$B:$B,A6) -> 7000 | D6: =SUMIFS(Dados!$N:$N,Dados!$P:$P,$D$2,Dados!$B:$B,A6) -> 50 | E6: =SUMIFS(Dados!$N:$N,Dados!$P:$P,$E$2,Dados!$B:$B,A6) -> 1200 | F6: =SUMIFS(Dados!$N:$N,Dados!$P:$P,$F$2,Dados!$B:$B,A6) -> 1665 | G6: =SUMIFS(Dados!$N:$N,Dados!$P:$P,$G$2,Dados!$B:$B,A6) -> 0 | H6: =SUMIFS(Dados!$N:$N,Dados!$D:$D,$H$1,Dados!$B:$B,A6,Dados!$P:$P,"") -> 8196.86 | I6: =SUMIFS(Dados!$N:$N,Dados!$D:$D,$I$1,Dados!$B:$B,A6) -> 0 | J6: =SUMIFS(Dados!$N:$N,Dados!$D:$D,$J$1,Dados!$B:$B,A6) -> 0 | K6: =SUMIFS(Dados!$N:$N,Dados!$D:$D,$K$1,Dados!$B:$B,A6) -> 0 | L6: =SUM(B6:K6) -> 18111.86
A7: Maodeobra-Cafe | B7: =SUMIFS(Dados!$N:$N,Dados!$P:$P,$B$2,Dados!$B:$B,A7) -> 6605.4 | C7: =SUMIFS(Dados!$N:$N,Dados!$P:$P,$C$2,Dados!$B:$B,A7) -> 2600 | D7: =SUMIFS(Dados!$N:$N,Dados!$P:$P,$D$2,Dados!$B:$B,A7) -> 8690 | E7: =SUMIFS(Dados!$N:$N,Dados!$P:$P,$E$2,Dados!$B:$B,A7) -> 3765 | F7: =SUMIFS(Dados!$N:$N,Dados!$P:$P,$F$2,Dados!$B:$B,A7) -> 700 | G7: =SUMIFS(Dados!$N:$N,Dados!$P:$P,$G$2,Dados!$B:$B,A7) -> 0 | H7: =SUMIFS(Dados!$N:$N,Dados!$D:$D,$H$1,Dados!$B:$B,A7,Dados!$P:$P,"") -> 1245.13 | I7: =SUMIFS(Dados!$N:$N,Dados!$D:$D,$I$1,Dados!$B:$B,A7) -> 0 | J7: =SUMIFS(Dados!$N:$N,Dados!$D:$D,$J$1,Dados!$B:$B,A7) -> 0 | K7: =SUMIFS(Dados!$N:$N,Dados!$D:$D,$K$1,Dados!$B:$B,A7) -> 0 | L7: =SUM(B7:K7) -> 23605.53
A8: Material/Tools-Cafe | B8: =SUMIFS(Dados!$N:$N,Dados!$P:$P,$B$2,Dados!$B:$B,A8) -> 2927.33 | C8: =SUMIFS(Dados!$N:$N,Dados!$P:$P,$C$2,Dados!$B:$B,A8) -> 320.73 | D8: =SUMIFS(Dados!$N:$N,Dados!$P:$P,$D$2,Dados!$B:$B,A8) -> 900 | E8: =SUMIFS(Dados!$N:$N,Dados!$P:$P,$E$2,Dados!$B:$B,A8) -> 0 | F8: =SUMIFS(Dados!$N:$N,Dados!$P:$P,$F$2,Dados!$B:$B,A8) -> 0 | G8: =SUMIFS(Dados!$N:$N,Dados!$P:$P,$G$2,Dados!$B:$B,A8) -> 337.59 | H8: =SUMIFS(Dados!$N:$N,Dados!$D:$D,$H$1,Dados!$B:$B,A8,Dados!$P:$P,"") -> 22285.12 | I8: =SUMIFS(Dados!$N:$N,Dados!$D:$D,$I$1,Dados!$B:$B,A8) -> 0 | J8: =SUMIFS(Dados!$N:$N,Dados!$D:$D,$J$1,Dados!$B:$B,A8) -> 0 | K8: =SUMIFS(Dados!$N:$N,Dados!$D:$D,$K$1,Dados!$B:$B,A8) -> 0 | L8: =SUM(B8:K8) -> 26770.77
A9: Project/Admin-Cafe | B9: =SUMIFS(Dados!$N:$N,Dados!$P:$P,$B$2,Dados!$B:$B,A9) -> 0 | C9: =SUMIFS(Dados!$N:$N,Dados!$P:$P,$C$2,Dados!$B:$B,A9) -> 15 | D9: =SUMIFS(Dados!$N:$N,Dados!$P:$P,$D$2,Dados!$B:$B,A9) -> 350 | E9: =SUMIFS(Dados!$N:$N,Dados!$P:$P,$E$2,Dados!$B:$B,A9) -> 0 | F9: =SUMIFS(Dados!$N:$N,Dados!$P:$P,$F$2,Dados!$B:$B,A9) -> 0 | G9: =SUMIFS(Dados!$N:$N,Dados!$P:$P,$G$2,Dados!$B:$B,A9) -> 2380.1 | H9: =SUMIFS(Dados!$N:$N,Dados!$D:$D,$H$1,Dados!$B:$B,A9,Dados!$P:$P,"") -> 6340.51 | I9: =SUMIFS(Dados!$N:$N,Dados!$D:$D,$I$1,Dados!$B:$B,A9) -> 0 | J9: =SUMIFS(Dados!$N:$N,Dados!$D:$D,$J$1,Dados!$B:$B,A9) -> 0 | K9: =SUMIFS(Dados!$N:$N,Dados!$D:$D,$K$1,Dados!$B:$B,A9) -> 0 | L9: =SUM(B9:K9) -> 9085.61
A10: Uber/ Transporte-Cafe | B10: =SUMIFS(Dados!$N:$N,Dados!$P:$P,$B$2,Dados!$B:$B,A10) -> 50 | C10: =SUMIFS(Dados!$N:$N,Dados!$P:$P,$C$2,Dados!$B:$B,A10) -> 0 | D10: =SUMIFS(Dados!$N:$N,Dados!$P:$P,$D$2,Dados!$B:$B,A10) -> 0 | E10: =SUMIFS(Dados!$N:$N,Dados!$P:$P,$E$2,Dados!$B:$B,A10) -> 0 | F10: =SUMIFS(Dados!$N:$N,Dados!$P:$P,$F$2,Dados!$B:$B,A10) -> 0 | G10: =SUMIFS(Dados!$N:$N,Dados!$P:$P,$G$2,Dados!$B:$B,A10) -> 0 | H10: =SUMIFS(Dados!$N:$N,Dados!$D:$D,$H$1,Dados!$B:$B,A10,Dados!$P:$P,"") -> 338.85 | I10: =SUMIFS(Dados!$N:$N,Dados!$D:$D,$I$1,Dados!$B:$B,A10) -> 7.52 | J10: =SUMIFS(Dados!$N:$N,Dados!$D:$D,$J$1,Dados!$B:$B,A10) -> 0 | K10: =SUMIFS(Dados!$N:$N,Dados!$D:$D,$K$1,Dados!$B:$B,A10) -> 0 | L10: =SUM(B10:K10) -> 396.37
A11: Total OUT | B11: =SUM(B5:B10) -> 10001.23 | C11: =SUM(C5:C10) -> 9945.73 | D11: =SUM(D5:D10) -> 9990 | E11: =SUM(E5:E10) -> 4965 | F11: =SUM(F5:F10) -> 2365 | G11: =SUM(G5:G10) -> 2717.69 | H11: =SUM(H5:H10) -> 38815.79 | I11: =SUM(I5:I10) -> 7.52 | ... L11: =SUM(L5:L10) -> 78807.96
A12: Final | B12: =B4-B11 -> -1.23 | C12: =C4-C11 -> 54.27 | D12: =D4-D11 -> 10 | E12: =E4-E11 -> 35 | F12: =F4-F11 -> 2635 | L12: =SUM(B12:J12) -> 2733.04
A13: Final for reals | B13: 0 | C13: 0 | D13: 0 | E13: 45 | F13: 2635 | L13: =SUM(B13:J13) -> 2680
A14: Difference | B14: =B12-B13 -> -1.23 | C14: =C12-C13 -> 54.27 | D14: =D12-D13 -> 10 | E14: =E12-E13 -> -10 | F14: =F12-F13 -> 0 | G14: =G12-G13 -> 0 | H14: =H12-H13 -> 0 | I14: =I12-I13 -> 0 | ... K14: =K12-K13 -> 0 | L14: =SUM(B14:J14) -> 53.04

Sheet Obra cash flow
A1: From | B1: 10k1 | C1: 10k2 | D1: 10k3 | E1: 5k4 | F1: 5k5 | G1: 2025 | H1: Bank | I1: Revolut | J1: Total
A2: Opening | B2: 10000 | C2: 10000 | D2: 10000 | E2: 5000 | F2: 5000
A3: Cafe/food-Cafe | B3: 418.5 | C3: 10 | D3: 0 | E3: 0 | F3: 0 | G3: 0 | H3: 409.32 | I3: 0 | J3: 837.82
A4: Furnitures-Cafe | B4: 0 | C4: 7000 | D4: 50 | E4: 1200 | F4: 1665 | G4: 0 | H4: 8196.86 | I4: 0 | J4: 18111.86
A5: Maodeobra-Cafe | B5: 6605.4 | C5: 2600 | D5: 8690 | E5: 3765 | F5: 700 | G5: 0 | H5: 1245.13 | I5: 0 | J5: 23605.53
A6: Material/Tools-Cafe | B6: 2927.33 | C6: 320.73 | D6: 900 | E6: 0 | F6: 0 | G6: 337.59 | H6: 22285.12 | I6: 0 | J6: 26770.77
A7: Project/Admin-Cafe | B7: 0 | C7: 15 | D7: 350 | E7: 0 | F7: 0 | G7: 2380.1 | H7: 6340.51 | I7: 0 | J7: 9085.61
A8: Uber/ Transporte-Cafe | B8: 50 | C8: 0 | D8: 0 | E8: 0 | F8: 0 | G8: 0 | H8: 338.85 | I8: 7.52 | J8: 396.37
A9: Total OUT | B9: 10001.23 | C9: 9945.73 | D9: 9990 | E9: 4965 | F9: 2365 | G9: 2717.69 | H9: 38815.79 | I9: 7.52 | J9: 78807.96

Sheet Receptor
A1: Receptor
A3: Ano | B3: 2025 | C3: 2025 | D3: 2025 | E3: 2025 | F3: 2025 | G3: 2025 | H3: 2025 | I3: 2025 | J3: 2025 | K3: 2025 | L3: 2025 | M3: 2025 | N3: 2025
A4: By Check in / No commission | B4: 1 | C4: 2 | D4: 3 | E4: 4 | F4: 5 | G4: 6 | H4: 7 | I4: 8 | J4: 9 | K4: 10 | L4: 11 | M4: 12 | N4: TOTAL
A5: Booking | F5: =sumifs(CloudBed!$U:$U,CloudBed!$K:$K,$A$5,CloudBed!$E:$E,F4) -> 6758 | G5: =sumifs(CloudBed!$U:$U,CloudBed!$K:$K,$A$5,CloudBed!$E:$E,G4) -> 8459.71 | H5: =sumifs(CloudBed!$U:$U,CloudBed!$K:$K,$A$5,CloudBed!$E:$E,H4) -> 8025.79 | I5: =sumifs(CloudBed!$U:$U,CloudBed!$K:$K,$A$5,CloudBed!$E:$E,I4) -> 0 | J5: =sumifs(CloudBed!$U:$U,CloudBed!$K:$K,$A$5,CloudBed!$E:$E,J4) -> 0 | K5: =sumifs(CloudBed!$U:$U,CloudBed!$K:$K,$A$5,CloudBed!$E:$E,K4) -> 0 | L5: =sumifs(CloudBed!$U:$U,CloudBed!$K:$K,$A$5,CloudBed!$E:$E,L4) -> 0 | M5: =sumifs(CloudBed!$U:$U,CloudBed!$K:$K,$A$5,CloudBed!$E:$E,M4) -> 0 | N5: =SUM(B5:M5) -> 23243.5
A6: HW | F6: =sumifs(CloudBed!$U:$U,CloudBed!$K:$K,$A$6,CloudBed!$E:$E,F4) -> 2470.5 | G6: =sumifs(CloudBed!$U:$U,CloudBed!$K:$K,$A$6,CloudBed!$E:$E,G4) -> 5678 | H6: =sumifs(CloudBed!$U:$U,CloudBed!$K:$K,$A$6,CloudBed!$E:$E,H4) -> 8233.95 | I6: =sumifs(CloudBed!$U:$U,CloudBed!$K:$K,$A$6,CloudBed!$E:$E,I4) -> 0 | J6: =sumifs(CloudBed!$J:$J,CloudBed!$H:$H,"Hostelworld (Hotel Collect Booking)",CloudBed!$T:$T,J4) -> 0 | K6: =sumifs(CloudBed!$J:$J,CloudBed!$H:$H,"Hostelworld (Hotel Collect Booking)",CloudBed!$T:$T,K4) -> 0 | L6: =sumifs(CloudBed!$J:$J,CloudBed!$H:$H,"Hostelworld (Hotel Collect Booking)",CloudBed!$T:$T,L4) -> 0 | M6: =sumifs(CloudBed!$J:$J,CloudBed!$H:$H,"Hostelworld (Hotel Collect Booking)",CloudBed!$T:$T,M4) -> 0 | N6: =SUM(B6:M6) -> 16382.45
A7: Airbnb | F7: =sumifs(CloudBed!$U:$U,CloudBed!$K:$K,$A$7,CloudBed!$E:$E,F4) -> 5253.2089 | G7: =sumifs(CloudBed!$U:$U,CloudBed!$K:$K,$A$7,CloudBed!$E:$E,G4) -> 6570.14 | H7: =sumifs(CloudBed!$U:$U,CloudBed!$K:$K,$A$7,CloudBed!$E:$E,H4) -> 4760.15 | I7: =sumifs(CloudBed!$U:$U,CloudBed!$K:$K,$A$7,CloudBed!$E:$E,I4) -> 0 | J7: =sumifs(CloudBed!$U:$U,CloudBed!$K:$K,$A$7,CloudBed!$E:$E,J4) -> 0 | K7: =sumifs(CloudBed!$J:$J,CloudBed!$H:$H,"Airbnb (API) (Channel Collect Booking)",CloudBed!$T:$T,K4) -> 0 | L7: =sumifs(CloudBed!$J:$J,CloudBed!$H:$H,"Airbnb (API) (Channel Collect Booking)",CloudBed!$T:$T,L4) -> 0 | M7: =sumifs(CloudBed!$J:$J,CloudBed!$H:$H,"Airbnb (API) (Channel Collect Booking)",CloudBed!$T:$T,M4) -> 0 | N7: =SUM(B7:M7) -> 16583.499
A8: Website | F8: =sumifs(CloudBed!$U:$U,CloudBed!$K:$K,"*Website*",CloudBed!$E:$E,F4) -> 0 | G8: =sumifs(CloudBed!$U:$U,CloudBed!$K:$K,"*Website*",CloudBed!$E:$E,G4) -> 483.26 | H8: =sumifs(CloudBed!$U:$U,CloudBed!$K:$K,"*Website*",CloudBed!$E:$E,H4) -> 224.5 | I8: =sumifs(CloudBed!$U:$U,CloudBed!$K:$K,"*Website*",CloudBed!$E:$E,I4) -> 0 | J8: =sumifs(CloudBed!$U:$U,CloudBed!$K:$K,"*Website*",CloudBed!$E:$E,J4) -> 0 | N8: =SUM(B8:M8) -> 707.76
A9: TotalOTA | B9: =SUM(B5:B8) -> 0 | C9: =SUM(C5:C8) -> 0 | D9: =SUM(D5:D8) -> 0 | E9: =SUM(E5:E8) -> 0 | F9: =SUM(F5:F8) -> 14481.709 | G9: =SUM(G5:G8) -> 21191.11 | H9: =SUM(H5:H8) -> 21244.39 | I9: =SUM(I5:I8) -> 0 | ... M9: =SUM(M5:M8) -> 0 | N9: =SUM(B9:M9) -> 56917.209
A10: Walk-In | F10: =sumifs(CloudBed!$U:$U,CloudBed!$K:$K,"Walk-In",CloudBed!$E:$E,F4) -> 0 | G10: =sumifs(CloudBed!$U:$U,CloudBed!$K:$K,"Walk-In",CloudBed!$E:$E,G4) -> 32 | H10: =sumifs(CloudBed!$U:$U,CloudBed!$K:$K,"Walk-In",CloudBed!$E:$E,H4) -> 0 | I10: =sumifs(CloudBed!$U:$U,CloudBed!$K:$K,"Walk-In",CloudBed!$E:$E,I4) -> 0 | N10: =SUM(B10:M10) -> 32
A11: Friends & Family | F11: =sumifs(CloudBed!$U:$U,CloudBed!$K:$K,$A$11,CloudBed!$E:$E,F4) -> 0 | G11: =sumifs(CloudBed!$U:$U,CloudBed!$K:$K,$A$11,CloudBed!$E:$E,G4) -> 214.5 | H11: =sumifs(CloudBed!$U:$U,CloudBed!$K:$K,$A$11,CloudBed!$E:$E,H4) -> 220 | I11: =sumifs(CloudBed!$U:$U,CloudBed!$K:$K,$A$11,CloudBed!$E:$E,I4) -> 0 | J11: =sumifs(CloudBed!$U:$U,CloudBed!$K:$K,$A$11,CloudBed!$E:$E,J4) -> 0 | K11: =sumifs(FF!$E:$E,FF!$C:$C,K4) -> 0 | L11: =sumifs(FF!$E:$E,FF!$C:$C,L4) -> 0 | M11: =sumifs(FF!$E:$E,FF!$C:$C,M4) -> 82 | N11: =SUM(B11:M11) -> 516.5
A12: Friends & Family | F12: =sumifs(FF!$E:$E,FF!$C:$C,F4) -> 1331 | G12: =sumifs(FF!$E:$E,FF!$C:$C,G4) -> 2027 | H12: =sumifs(FF!$E:$E,FF!$C:$C,H4) -> 2825 | I12: =sumifs(FF!$E:$E,FF!$C:$C,I4) -> 0 | J12: =sumifs(FF!$E:$E,FF!$C:$C,J4) -> 0
A13: Friends & Family | F13: =F11+F12 -> 1331 | G13: =G11+G12 -> 2241.5 | H13: =H11+H12 -> 3045 | I13: =I11+I12 -> 0 | J13: =J11+J12 -> 0 | K13: =K11+K12 -> 0 | L13: =L11+L12 -> 0 | M13: =M11+M12 -> 82 | N13: =N11+N12 -> 516.5
A14: TotalWalk | B14: =SUM(B10:B12) -> 0 | C14: =SUM(C10:C12) -> 0 | D14: =SUM(D10:D12) -> 0 | E14: =SUM(E10:E12) -> 0 | F14: =F10+F13 -> 1331 | G14: =G10+G13 -> 2273.5 | H14: =H10+H13 -> 3045 | I14: =I10+I13 -> 0 | J14: =J10+J13 -> 0 | K14: =K10+K13 -> 0 | L14: =L10+L13 -> 0 | M14: =M10+M13 -> 82 | N14: =SUM(B14:M14) -> 6731.5
A16: CityTax | F16: =sumifs(CloudBed!$O:$O,CloudBed!$E:$E,F4) -> 666 | G16: =sumifs(CloudBed!$O:$O,CloudBed!$E:$E,G4) -> 1216 | H16: =sumifs(CloudBed!$O:$O,CloudBed!$E:$E,H4) -> 1154 | I16: =sumifs(CloudBed!$O:$O,CloudBed!$E:$E,I4) -> 0 | J16: =sumifs(CloudBed!$O:$O,CloudBed!$E:$E,J4) -> 0 | K16: =sumifs(CloudBed!$O:$O,CloudBed!$E:$E,K4) -> 0 | L16: =sumifs(CloudBed!$O:$O,CloudBed!$E:$E,L4) -> 0 | M16: =sumifs(CloudBed!$O:$O,CloudBed!$E:$E,M4) -> 0 | N16: =SUM(B16:M16) -> 3036
A18: TotalAcomodation | E18: 0 | F18: =F9+F14 -> 15812.709 | G18: =G9+G14 -> 23464.61 | H18: =H9+H14 -> 24289.39 | I18: =I9+I14 -> 0 | J18: =J9+J14 -> 0 | K18: =K9+K14 -> 0 | L18: =L9+L14 -> 0 | M18: =M9+M14 -> 82 | N18: =SUM(B18:M18) -> 63648.709
A19: Lastyear(planilha2025) | E19: 5662.45 | F19: 16662.5 | G19: 18547.4 | H19: 28367.36 | I19: 38195.5 | J19: 28669.66 | K19: 20442.63 | L19: 0 | M19: 0 | N19: =SUM(B19:M19) -> 156547.5
A20: %comparação | E20: =(E18-E19)/E19 -> -1 | F20: =(F18-F19)/F19 -> -0.051000217 | G20: =(G18-G19)/G19 -> 0.26511587 | H20: =(H18-H19)/H19 -> -0.14375571 | I20: =(I18-I19)/I19 -> -1 | J20: =(J18-J19)/J19 -> -1 | K20: =(K18-K19)/K19 -> -1 | N20: =AVERAGE(D20:K20) -> -0.56137715
A22: Number of Guest | F22: 177 | G22: 286 | H22: 295
A23: Number of Beds | F23: 391 | G23: 619 | H23: 515
A24: Occupancy Rate | F24: 0.5341 | G24: 0.8456 | H24: 0.7
A25: Last Year | E25: 0.35101254 | F25: 0.81581485 | G25: 0.87753134 | H25: 0.9057377 | I25: 1.0177596 | J25: 0.97404372 | K25: 0.84153005
A26: %comparação | F26: =F24-F25 -> -0.28171485 | G26: =G24-G25 -> -0.03193134 | H26: =H24-H25 -> -0.2057377
A28: Average Price | F28: 37.9 | G28: 34.19 | H28: 34.55
A29: Last Year | E29: 31.112363 | F29: 39.391253 | G29: 40.763516 | H29: 42.786365 | I29: 51.269128 | J29: 40.209902 | K29: 33.186088
A30: %comparação | F30: =F28/F29 -> 0.96214254 | G30: =G28/G29 -> 0.8387402 | H30: =H28/H29 -> 0.80750024
A32: Bed Cost by nights | F32: ='Final Result'!F22/F23 -> 24.970512 | G32: ='Final Result'!G22/G23 -> 23.337464 | H32: ='Final Result'!H22/H23 -> 21.197825 | I32: ='Final Result'!I22/I23 -> #DIV/0! | J32: ='Final Result'!J22/J23 -> #DIV/0! | K32: ='Final Result'!K22/K23 -> #DIV/0! | L32: ='Final Result'!L22/L23 -> #DIV/0! | M32: ='Final Result'!M22/M23 -> #DIV/0!
A33: Last Year | E33: 22.824894 | F33: 19.62553 | G33: 24.827332 | H33: 25.706003 | I33: 22.821302 | J33: 19.086553 | K33: 20.938889
A34: %comparação | F34: =F32/F33 -> 1.2723484 | G34: =G32/G33 -> 0.93999078 | H34: =H32/H33 -> 0.82462549
A36: Bed Cost if full | E36: ='Final Result'!E22/(24*30.5) -> 2.5428142 | F36: ='Final Result'!F22/(24*30.5) -> 13.338074 | G36: ='Final Result'!G22/(24*30.5) -> 19.734822 | H36: ='Final Result'!H22/(24*30.5) -> 14.91377 | I36: ='Final Result'!I22/(24*30.5) -> 0 | J36: ='Final Result'!J22/(24*30.5) -> 0 | K36: ='Final Result'!K22/(24*30.5) -> 0 | L36: ='Final Result'!L22/(24*30.5) -> 0 | M36: ='Final Result'!M22/(24*30.5) -> 0
A37: Last Year | E37: 8.0118238 | F37: 16.010799 | G37: 21.786762 | H37: 23.282896 | I37: 23.226598 | J37: 18.591137 | K37: 17.620705 | L37: 10.454495 | M37: 9.632582 | N37: 13.302401
A38: %comparação | F38: =F36/F37 -> 0.83306733 | G38: =G36/G37 -> 0.90581713 | H38: =H36/H37 -> 0.64054619

Sheet Receptor by pay
A1: Receptor
A3: Ano | B3: 2025 | C3: 2025 | D3: 2025 | E3: 2025 | F3: 2025 | G3: 2025 | H3: 2025 | I3: 2025 | J3: 2025 | K3: 2025 | L3: 2025 | M3: 2025 | N3: 2025
A4: By Payment/ No commission | B4: 1 | C4: 2 | D4: 3 | E4: 4 | F4: 5 | G4: 6 | H4: 7 | I4: 8 | J4: 9 | K4: 10 | L4: 11 | M4: 12 | N4: TOTAL
A5: Booking | F5: =sumifs(CloudBed!$U:$U,CloudBed!$K:$K,$A$5,CloudBed!$X:$X,F4) -> 0 | G5: =sumifs(CloudBed!$U:$U,CloudBed!$K:$K,$A$5,CloudBed!$X:$X,G4) -> 6419.64 | H5: =sumifs(CloudBed!$U:$U,CloudBed!$K:$K,$A$5,CloudBed!$X:$X,H4) -> 8072.45 | I5: =sumifs(CloudBed!$U:$U,CloudBed!$K:$K,$A$5,CloudBed!$X:$X,I4) -> 8751.41 | J5: =sumifs(CloudBed!$U:$U,CloudBed!$K:$K,$A$5,CloudBed!$X:$X,J4) -> 0 | K5: =sumifs(CloudBed!$U:$U,CloudBed!$K:$K,$A$5,CloudBed!$X:$X,K4) -> 0 | L5: =sumifs(CloudBed!$U:$U,CloudBed!$K:$K,$A$5,CloudBed!$X:$X,L4) -> 0 | M5: =sumifs(CloudBed!$U:$U,CloudBed!$K:$K,$A$5,CloudBed!$X:$X,M4) -> 0 | N5: =SUM(B5:M5) -> 23243.5
A6: HW | F6: =sumifs(CloudBed!$U:$U,CloudBed!$K:$K,$A$6,CloudBed!$X:$X,F4) -> 2470.5 | G6: =sumifs(CloudBed!$U:$U,CloudBed!$K:$K,$A$6,CloudBed!$X:$X,G4) -> 5610 | H6: =sumifs(CloudBed!$U:$U,CloudBed!$K:$K,$A$6,CloudBed!$X:$X,H4) -> 7634.7 | I6: =sumifs(CloudBed!$U:$U,CloudBed!$K:$K,$A$6,CloudBed!$X:$X,I4) -> 667.25 | J6: =sumifs(CloudBed!$J:$J,CloudBed!$H:$H,"Hostelworld (Hotel Collect Booking)",CloudBed!$T:$T,J4) -> 0 | K6: =sumifs(CloudBed!$J:$J,CloudBed!$H:$H,"Hostelworld (Hotel Collect Booking)",CloudBed!$T:$T,K4) -> 0 | L6: =sumifs(CloudBed!$J:$J,CloudBed!$H:$H,"Hostelworld (Hotel Collect Booking)",CloudBed!$T:$T,L4) -> 0 | M6: =sumifs(CloudBed!$J:$J,CloudBed!$H:$H,"Hostelworld (Hotel Collect Booking)",CloudBed!$T:$T,M4) -> 0 | N6: =SUM(B6:M6) -> 16382.45
A7: Airbnb | F7: =sumifs(CloudBed!$U:$U,CloudBed!$K:$K,"Airbnb",CloudBed!$X:$X,F4) -> 4244.3589 | G7: =sumifs(CloudBed!$U:$U,CloudBed!$K:$K,"Airbnb",CloudBed!$X:$X,G4) -> 7211.42 | H7: =sumifs(CloudBed!$U:$U,CloudBed!$K:$K,"Airbnb",CloudBed!$X:$X,H4) -> 5127.72 | I7: =sumifs(CloudBed!$U:$U,CloudBed!$K:$K,"Airbnb",CloudBed!$X:$X,I4) -> 0 | J7: =sumifs(CloudBed!$U:$U,CloudBed!$K:$K,"Airbnb",CloudBed!$X:$X,J4) -> 0 | K7: =sumifs(CloudBed!$U:$U,CloudBed!$K:$K,"Airbnb",CloudBed!$X:$X,K4) -> 0 | L7: =sumifs(CloudBed!$U:$U,CloudBed!$K:$K,"Airbnb",CloudBed!$X:$X,L4) -> 0 | M7: =sumifs(CloudBed!$U:$U,CloudBed!$K:$K,"Airbnb",CloudBed!$X:$X,M4) -> 0 | N7: =SUM(B7:M7) -> 16583.499
A8: Website | F8: =sumifs(CloudBed!$U:$U,CloudBed!$K:$K,"*Website*",CloudBed!$X:$X,F4) -> 0 | G8: =sumifs(CloudBed!$U:$U,CloudBed!$K:$K,"*Website*",CloudBed!$X:$X,G4) -> 450 | H8: =sumifs(CloudBed!$U:$U,CloudBed!$K:$K,"*Website*",CloudBed!$X:$X,H4) -> 257.76 | I8: =sumifs(CloudBed!$U:$U,CloudBed!$K:$K,"*Website*",CloudBed!$X:$X,I4) -> 0 | J8: =sumifs(CloudBed!$U:$U,CloudBed!$K:$K,"*Website*",CloudBed!$X:$X,J4) -> 0 | N8: =SUM(B8:M8) -> 707.76
A9: TotalOTA | B9: =SUM(B5:B8) -> 0 | C9: =SUM(C5:C8) -> 0 | D9: =SUM(D5:D8) -> 0 | E9: =SUM(E5:E8) -> 0 | F9: =SUM(F5:F8) -> 6714.8589 | G9: =SUM(G5:G8) -> 19691.06 | H9: =SUM(H5:H8) -> 21092.63 | I9: =SUM(I5:I8) -> 9418.66 | ... M9: =SUM(M5:M8) -> 0 | N9: =SUM(B9:M9) -> 56917.209
A10: Walk-In | F10: =sumifs(CloudBed!$U:$U,CloudBed!$K:$K,"Walk-In",CloudBed!$X:$X,F4) -> 0 | G10: =sumifs(CloudBed!$U:$U,CloudBed!$K:$K,"Walk-In",CloudBed!$X:$X,G4) -> 32 | H10: =sumifs(CloudBed!$U:$U,CloudBed!$K:$K,"Walk-In",CloudBed!$X:$X,H4) -> 0 | I10: =sumifs(CloudBed!$U:$U,CloudBed!$K:$K,"Walk-In",CloudBed!$X:$X,I4) -> 0 | N10: =SUM(B10:M10) -> 32
A11: Friends & Family | F11: =sumifs(CloudBed!$U:$U,CloudBed!$K:$K,$A$11,CloudBed!$X:$X,F4) -> 0 | G11: =sumifs(CloudBed!$U:$U,CloudBed!$K:$K,$A$11,CloudBed!$X:$X,G4) -> 214.5 | H11: =sumifs(CloudBed!$U:$U,CloudBed!$K:$K,$A$11,CloudBed!$X:$X,H4) -> 220 | I11: =sumifs(CloudBed!$U:$U,CloudBed!$K:$K,$A$11,CloudBed!$X:$X,I4) -> 0 | J11: =sumifs(CloudBed!$U:$U,CloudBed!$K:$K,$A$11,CloudBed!$X:$X,J4) -> 0 | K11: =sumifs(FF!$X:$X,FF!$C:$C,K4) -> 0 | L11: =sumifs(FF!$X:$X,FF!$C:$C,L4) -> 0 | M11: =sumifs(FF!$X:$X,FF!$C:$C,M4) -> 0 | N11: =SUM(B11:M11) -> 434.5
A12: Friends & Family from the paper | F12: =sumifs(FF!$E:$E,FF!$C:$C,F4) -> 1331 | G12: =sumifs(FF!$E:$E,FF!$C:$C,G4) -> 2027 | H12: =sumifs(FF!$E:$E,FF!$C:$C,H4) -> 2825 | I12: =sumifs(FF!$E:$E,FF!$C:$C,I4) -> 0 | J12: =sumifs(FF!$E:$E,FF!$C:$C,J4) -> 0 | K12: =sumifs(FF!$E:$E,FF!$C:$C,K4) -> 0 | L12: =sumifs(FF!$E:$E,FF!$C:$C,L4) -> 0 | M12: =sumifs(FF!$E:$E,FF!$C:$C,M4) -> 82
A13: Friends & Family | F13: =F11+F12 -> 1331 | G13: =G11+G12 -> 2241.5 | H13: =H11+H12 -> 3045 | I13: =I11+I12 -> 0 | J13: =J11+J12 -> 0 | K13: =K11+K12 -> 0 | L13: =L11+L12 -> 0 | M13: =M11+M12 -> 82 | N13: =SUM(B13:M13) -> 6699.5
A14: TotalWalk | B14: =SUM(B10:B12) -> 0 | C14: =SUM(C10:C12) -> 0 | D14: =SUM(D10:D12) -> 0 | E14: =SUM(E10:E12) -> 0 | F14: =F10+F13 -> 1331 | G14: =G10+G13 -> 2273.5 | H14: =H10+H13 -> 3045 | I14: =I10+I13 -> 0 | J14: =J10+J13 -> 0 | K14: =K10+K13 -> 0 | L14: =L10+L13 -> 0 | M14: =M10+M13 -> 82 | N14: =SUM(B14:M14) -> 6731.5
A16: CityTax | F16: =sumifs(CloudBed!$O:$O,CloudBed!$X:$X,F4) -> 260 | G16: =sumifs(CloudBed!$O:$O,CloudBed!$X:$X,G4) -> 1094 | H16: =sumifs(CloudBed!$O:$O,CloudBed!$X:$X,H4) -> 1156 | I16: =sumifs(CloudBed!$O:$O,CloudBed!$X:$X,I4) -> 526 | J16: =sumifs(CloudBed!$O:$O,CloudBed!$X:$X,J4) -> 0 | K16: =sumifs(CloudBed!$O:$O,CloudBed!$X:$X,K4) -> 0 | L16: =sumifs(CloudBed!$O:$O,CloudBed!$X:$X,L4) -> 0 | M16: =sumifs(CloudBed!$O:$O,CloudBed!$X:$X,M4) -> 0 | N16: =SUM(B16:M16) -> 3036
A17: Total com CT | E17: =Receptor!E9+Receptor!E14 -> 0 | F17: =F9+F14+F16 -> 8305.8589 | G17: =G9+G14+G16 -> 23058.56 | H17: =H9+H14+H16 -> 25293.63 | I17: =I9+I14+I16 -> 9944.66 | J17: =J9+J14+J16 -> 0 | K17: =K9+K14+K16 -> 0 | L17: =L9+L14+L16 -> 0 | M17: =M9+M14+M16 -> 82 | N17: =N9+N14+N16 -> 66684.709
A18: Receptor by event | F18: =Receptor!F9+Receptor!F14+Receptor!F16 -> 16478.709 | G18: =Receptor!G9+Receptor!G14+Receptor!G16 -> 24680.61 | H18: =Receptor!H9+Receptor!H14+Receptor!H16 -> 25443.39 | I18: =Receptor!I9+Receptor!I14+Receptor!I16 -> 0 | J18: =Receptor!J9+Receptor!J14+Receptor!J16 -> 0 | K18: =Receptor!K9+Receptor!K14+Receptor!K16 -> 0 | L18: =Receptor!L9+Receptor!L14+Receptor!L16 -> 0 | M18: =Receptor!M9+Receptor!M14+Receptor!M16 -> 82 | N18: =Receptor!N9+Receptor!N14+Receptor!N16 -> 66684.709
A19: Diferença | F19: =F17-F18 -> -8172.85 | G19: =G17-G18 -> -1622.05 | H19: =H17-H18 -> -149.76 | I19: =I17-I18 -> 9944.66 | J19: =J17-J18 -> 0 | K19: =K17-K18 -> 0 | L19: =L17-L18 -> 0 | M19: =M17-M18 -> 0 | N19: =N17-N18 -> 0

Sheet Analysis OUT by pay
D1: 2026
A2: PELA DATA DO PAGAMENTO
A3: CATEGORIA | B3: PRODUTO | D3: TOTAL2026 | E3: Jan | F3: Fev | G3: Mar | H3: Apr | I3: May | J3: Jun | K3: Jul | L3: Aug | M3: Sep | N3: Oct | O3: Nov | P3: Dez
D4: TOTAL | E4: 1 | F4: 2 | G4: 3 | H4: 4 | I4: 5 | J4: 6 | K4: 7 | L4: 8 | M4: 9 | N4: 10 | O4: 11 | P4: 12
B5: Aqua Lab Water Test | D5: =SUM(E5:P5) -> 435.86 | E5: =sumifs(Dados!$N:$N,Dados!$B:$B,B5,Dados!$H:$H,$D$1,Dados!$G:$G,$E$4) -> 0 | F5: =sumifs(Dados!$N:$N,Dados!$B:$B,B5,Dados!$H:$H,$D$1,Dados!$G:$G,$F$4) -> 0 | G5: =sumifs(Dados!$N:$N,Dados!$B:$B,B5,Dados!$H:$H,$D$1,Dados!$G:$G,$G$4) -> 0 | H5: =sumifs(Dados!$N:$N,Dados!$B:$B,B5,Dados!$H:$H,$D$1,Dados!$G:$G,$H$4) -> 0 | I5: =sumifs(Dados!$N:$N,Dados!$B:$B,B5,Dados!$H:$H,$D$1,Dados!$G:$G,$I$4) -> 0 | J5: =sumifs(Dados!$N:$N,Dados!$B:$B,B5,Dados!$H:$H,$D$1,Dados!$G:$G,$J$4) -> 435.86 | K5: =sumifs(Dados!$N:$N,Dados!$B:$B,B5,Dados!$H:$H,$D$1,Dados!$G:$G,$K$4) -> 0 | L5: =sumifs(Dados!$N:$N,Dados!$B:$B,B5,Dados!$H:$H,$D$1,Dados!$G:$G,$L$4) -> 0 | M5: =sumifs(Dados!$N:$N,Dados!$B:$B,B5,Dados!$H:$H,$D$1,Dados!$G:$G,$M$4) -> 0 | N5: =sumifs(Dados!$N:$N,Dados!$B:$B,B5,Dados!$H:$H,$D$1,Dados!$G:$G,$N$4) -> 0 | O5: =sumifs(Dados!$N:$N,Dados!$B:$B,B5,Dados!$H:$H,$D$1,Dados!$G:$G,$O$4) -> 0 | P5: =sumifs(Dados!$N:$N,Dados!$B:$B,B5,Dados!$H:$H,$D$1,Dados!$G:$G,$P$4) -> 0
B6: Gas inspection | D6: =SUM(E6:P6) -> 0 | E6: =sumifs(Dados!$N:$N,Dados!$B:$B,B6,Dados!$H:$H,$D$1,Dados!$G:$G,$E$4) -> 0 | F6: =sumifs(Dados!$N:$N,Dados!$B:$B,B6,Dados!$H:$H,$D$1,Dados!$G:$G,$F$4) -> 0 | G6: =sumifs(Dados!$N:$N,Dados!$B:$B,B6,Dados!$H:$H,$D$1,Dados!$G:$G,$G$4) -> 0 | H6: =sumifs(Dados!$N:$N,Dados!$B:$B,B6,Dados!$H:$H,$D$1,Dados!$G:$G,$H$4) -> 0 | I6: =sumifs(Dados!$N:$N,Dados!$B:$B,B6,Dados!$H:$H,$D$1,Dados!$G:$G,$I$4) -> 0 | J6: =sumifs(Dados!$N:$N,Dados!$B:$B,B6,Dados!$H:$H,$D$1,Dados!$G:$G,$J$4) -> 0 | K6: =sumifs(Dados!$N:$N,Dados!$B:$B,B6,Dados!$H:$H,$D$1,Dados!$G:$G,$K$4) -> 0 | L6: =sumifs(Dados!$N:$N,Dados!$B:$B,B6,Dados!$H:$H,$D$1,Dados!$G:$G,$L$4) -> 0 | M6: =sumifs(Dados!$N:$N,Dados!$B:$B,B6,Dados!$H:$H,$D$1,Dados!$G:$G,$M$4) -> 0 | N6: =sumifs(Dados!$N:$N,Dados!$B:$B,B6,Dados!$H:$H,$D$1,Dados!$G:$G,$N$4) -> 0 | O6: =sumifs(Dados!$N:$N,Dados!$B:$B,B6,Dados!$H:$H,$D$1,Dados!$G:$G,$O$4) -> 0 | P6: =sumifs(Dados!$N:$N,Dados!$B:$B,B6,Dados!$H:$H,$D$1,Dados!$G:$G,$P$4) -> 0
B7: INTERPREV-Fiscalisacao | D7: =SUM(E7:P7) -> 285.85 | E7: =sumifs(Dados!$N:$N,Dados!$B:$B,B7,Dados!$H:$H,$D$1,Dados!$G:$G,$E$4) -> 0 | F7: =sumifs(Dados!$N:$N,Dados!$B:$B,B7,Dados!$H:$H,$D$1,Dados!$G:$G,$F$4) -> 0 | G7: =sumifs(Dados!$N:$N,Dados!$B:$B,B7,Dados!$H:$H,$D$1,Dados!$G:$G,$G$4) -> 0 | H7: =sumifs(Dados!$N:$N,Dados!$B:$B,B7,Dados!$H:$H,$D$1,Dados!$G:$G,$H$4) -> 0 | I7: =sumifs(Dados!$N:$N,Dados!$B:$B,B7,Dados!$H:$H,$D$1,Dados!$G:$G,$I$4) -> 0 | J7: =sumifs(Dados!$N:$N,Dados!$B:$B,B7,Dados!$H:$H,$D$1,Dados!$G:$G,$J$4) -> 285.85 | K7: =sumifs(Dados!$N:$N,Dados!$B:$B,B7,Dados!$H:$H,$D$1,Dados!$G:$G,$K$4) -> 0 | L7: =sumifs(Dados!$N:$N,Dados!$B:$B,B7,Dados!$H:$H,$D$1,Dados!$G:$G,$L$4) -> 0 | M7: =sumifs(Dados!$N:$N,Dados!$B:$B,B7,Dados!$H:$H,$D$1,Dados!$G:$G,$M$4) -> 0 | N7: =sumifs(Dados!$N:$N,Dados!$B:$B,B7,Dados!$H:$H,$D$1,Dados!$G:$G,$N$4) -> 0 | O7: =sumifs(Dados!$N:$N,Dados!$B:$B,B7,Dados!$H:$H,$D$1,Dados!$G:$G,$O$4) -> 0 | P7: =sumifs(Dados!$N:$N,Dados!$B:$B,B7,Dados!$H:$H,$D$1,Dados!$G:$G,$P$4) -> 0
B8: INTERPREV-Segurancaesaude | D8: =SUM(E8:P8) -> 0 | E8: =sumifs(Dados!$N:$N,Dados!$B:$B,B8,Dados!$H:$H,$D$1,Dados!$G:$G,$E$4) -> 0 | F8: =sumifs(Dados!$N:$N,Dados!$B:$B,B8,Dados!$H:$H,$D$1,Dados!$G:$G,$F$4) -> 0 | G8: =sumifs(Dados!$N:$N,Dados!$B:$B,B8,Dados!$H:$H,$D$1,Dados!$G:$G,$G$4) -> 0 | H8: =sumifs(Dados!$N:$N,Dados!$B:$B,B8,Dados!$H:$H,$D$1,Dados!$G:$G,$H$4) -> 0 | I8: =sumifs(Dados!$N:$N,Dados!$B:$B,B8,Dados!$H:$H,$D$1,Dados!$G:$G,$I$4) -> 0 | J8: =sumifs(Dados!$N:$N,Dados!$B:$B,B8,Dados!$H:$H,$D$1,Dados!$G:$G,$J$4) -> 0 | K8: =sumifs(Dados!$N:$N,Dados!$B:$B,B8,Dados!$H:$H,$D$1,Dados!$G:$G,$K$4) -> 0 | L8: =sumifs(Dados!$N:$N,Dados!$B:$B,B8,Dados!$H:$H,$D$1,Dados!$G:$G,$L$4) -> 0 | M8: =sumifs(Dados!$N:$N,Dados!$B:$B,B8,Dados!$H:$H,$D$1,Dados!$G:$G,$M$4) -> 0 | N8: =sumifs(Dados!$N:$N,Dados!$B:$B,B8,Dados!$H:$H,$D$1,Dados!$G:$G,$N$4) -> 0 | O8: =sumifs(Dados!$N:$N,Dados!$B:$B,B8,Dados!$H:$H,$D$1,Dados!$G:$G,$O$4) -> 0 | P8: =sumifs(Dados!$N:$N,Dados!$B:$B,B8,Dados!$H:$H,$D$1,Dados!$G:$G,$P$4) -> 0
B9: License | D9: =SUM(E9:P9) -> 0 | E9: =sumifs(Dados!$N:$N,Dados!$B:$B,B9,Dados!$H:$H,$D$1,Dados!$G:$G,$E$4) -> 0 | F9: =sumifs(Dados!$N:$N,Dados!$B:$B,B9,Dados!$H:$H,$D$1,Dados!$G:$G,$F$4) -> 0 | G9: =sumifs(Dados!$N:$N,Dados!$B:$B,B9,Dados!$H:$H,$D$1,Dados!$G:$G,$G$4) -> 0 | H9: =sumifs(Dados!$N:$N,Dados!$B:$B,B9,Dados!$H:$H,$D$1,Dados!$G:$G,$H$4) -> 0 | I9: =sumifs(Dados!$N:$N,Dados!$B:$B,B9,Dados!$H:$H,$D$1,Dados!$G:$G,$I$4) -> 0 | J9: =sumifs(Dados!$N:$N,Dados!$B:$B,B9,Dados!$H:$H,$D$1,Dados!$G:$G,$J$4) -> 0 | K9: =sumifs(Dados!$N:$N,Dados!$B:$B,B9,Dados!$H:$H,$D$1,Dados!$G:$G,$K$4) -> 0 | L9: =sumifs(Dados!$N:$N,Dados!$B:$B,B9,Dados!$H:$H,$D$1,Dados!$G:$G,$L$4) -> 0 | M9: =sumifs(Dados!$N:$N,Dados!$B:$B,B9,Dados!$H:$H,$D$1,Dados!$G:$G,$M$4) -> 0 | N9: =sumifs(Dados!$N:$N,Dados!$B:$B,B9,Dados!$H:$H,$D$1,Dados!$G:$G,$N$4) -> 0 | O9: =sumifs(Dados!$N:$N,Dados!$B:$B,B9,Dados!$H:$H,$D$1,Dados!$G:$G,$O$4) -> 0 | P9: =sumifs(Dados!$N:$N,Dados!$B:$B,B9,Dados!$H:$H,$D$1,Dados!$G:$G,$P$4) -> 0
B10: SOPFOGO-Extinctores | D10: =SUM(E10:P10) -> 0 | E10: =sumifs(Dados!$N:$N,Dados!$B:$B,B10,Dados!$H:$H,$D$1,Dados!$G:$G,$E$4) -> 0 | F10: =sumifs(Dados!$N:$N,Dados!$B:$B,B10,Dados!$H:$H,$D$1,Dados!$G:$G,$F$4) -> 0 | G10: =sumifs(Dados!$N:$N,Dados!$B:$B,B10,Dados!$H:$H,$D$1,Dados!$G:$G,$G$4) -> 0 | H10: =sumifs(Dados!$N:$N,Dados!$B:$B,B10,Dados!$H:$H,$D$1,Dados!$G:$G,$H$4) -> 0 | I10: =sumifs(Dados!$N:$N,Dados!$B:$B,B10,Dados!$H:$H,$D$1,Dados!$G:$G,$I$4) -> 0 | J10: =sumifs(Dados!$N:$N,Dados!$B:$B,B10,Dados!$H:$H,$D$1,Dados!$G:$G,$J$4) -> 0 | K10: =sumifs(Dados!$N:$N,Dados!$B:$B,B10,Dados!$H:$H,$D$1,Dados!$G:$G,$K$4) -> 0 | L10: =sumifs(Dados!$N:$N,Dados!$B:$B,B10,Dados!$H:$H,$D$1,Dados!$G:$G,$L$4) -> 0 | M10: =sumifs(Dados!$N:$N,Dados!$B:$B,B10,Dados!$H:$H,$D$1,Dados!$G:$G,$M$4) -> 0 | N10: =sumifs(Dados!$N:$N,Dados!$B:$B,B10,Dados!$H:$H,$D$1,Dados!$G:$G,$N$4) -> 0 | O10: =sumifs(Dados!$N:$N,Dados!$B:$B,B10,Dados!$H:$H,$D$1,Dados!$G:$G,$O$4) -> 0 | P10: =sumifs(Dados!$N:$N,Dados!$B:$B,B10,Dados!$H:$H,$D$1,Dados!$G:$G,$P$4) -> 0
B11: SOPFOGO-Manutencao Central Incendio | D11: =SUM(E11:P11) -> 0 | E11: =sumifs(Dados!$N:$N,Dados!$B:$B,B11,Dados!$H:$H,$D$1,Dados!$G:$G,$E$4) -> 0 | F11: =sumifs(Dados!$N:$N,Dados!$B:$B,B11,Dados!$H:$H,$D$1,Dados!$G:$G,$F$4) -> 0 | G11: =sumifs(Dados!$N:$N,Dados!$B:$B,B11,Dados!$H:$H,$D$1,Dados!$G:$G,$G$4) -> 0 | H11: =sumifs(Dados!$N:$N,Dados!$B:$B,B11,Dados!$H:$H,$D$1,Dados!$G:$G,$H$4) -> 0 | I11: =sumifs(Dados!$N:$N,Dados!$B:$B,B11,Dados!$H:$H,$D$1,Dados!$G:$G,$I$4) -> 0 | J11: =sumifs(Dados!$N:$N,Dados!$B:$B,B11,Dados!$H:$H,$D$1,Dados!$G:$G,$J$4) -> 0 | K11: =sumifs(Dados!$N:$N,Dados!$B:$B,B11,Dados!$H:$H,$D$1,Dados!$G:$G,$K$4) -> 0 | L11: =sumifs(Dados!$N:$N,Dados!$B:$B,B11,Dados!$H:$H,$D$1,Dados!$G:$G,$L$4) -> 0 | M11: =sumifs(Dados!$N:$N,Dados!$B:$B,B11,Dados!$H:$H,$D$1,Dados!$G:$G,$M$4) -> 0 | N11: =sumifs(Dados!$N:$N,Dados!$B:$B,B11,Dados!$H:$H,$D$1,Dados!$G:$G,$N$4) -> 0 | O11: =sumifs(Dados!$N:$N,Dados!$B:$B,B11,Dados!$H:$H,$D$1,Dados!$G:$G,$O$4) -> 0 | P11: =sumifs(Dados!$N:$N,Dados!$B:$B,B11,Dados!$H:$H,$D$1,Dados!$G:$G,$P$4) -> 0
B12: SPA | D12: =SUM(E12:P12) -> 0 | E12: =sumifs(Dados!$N:$N,Dados!$B:$B,B12,Dados!$H:$H,$D$1,Dados!$G:$G,$E$4) -> 0 | F12: =sumifs(Dados!$N:$N,Dados!$B:$B,B12,Dados!$H:$H,$D$1,Dados!$G:$G,$F$4) -> 0 | G12: =sumifs(Dados!$N:$N,Dados!$B:$B,B12,Dados!$H:$H,$D$1,Dados!$G:$G,$G$4) -> 0 | H12: =sumifs(Dados!$N:$N,Dados!$B:$B,B12,Dados!$H:$H,$D$1,Dados!$G:$G,$H$4) -> 0 | I12: =sumifs(Dados!$N:$N,Dados!$B:$B,B12,Dados!$H:$H,$D$1,Dados!$G:$G,$I$4) -> 0 | J12: =sumifs(Dados!$N:$N,Dados!$B:$B,B12,Dados!$H:$H,$D$1,Dados!$G:$G,$J$4) -> 0 | K12: =sumifs(Dados!$N:$N,Dados!$B:$B,B12,Dados!$H:$H,$D$1,Dados!$G:$G,$K$4) -> 0 | L12: =sumifs(Dados!$N:$N,Dados!$B:$B,B12,Dados!$H:$H,$D$1,Dados!$G:$G,$L$4) -> 0 | M12: =sumifs(Dados!$N:$N,Dados!$B:$B,B12,Dados!$H:$H,$D$1,Dados!$G:$G,$M$4) -> 0 | N12: =sumifs(Dados!$N:$N,Dados!$B:$B,B12,Dados!$H:$H,$D$1,Dados!$G:$G,$N$4) -> 0 | O12: =sumifs(Dados!$N:$N,Dados!$B:$B,B12,Dados!$H:$H,$D$1,Dados!$G:$G,$O$4) -> 0 | P12: =sumifs(Dados!$N:$N,Dados!$B:$B,B12,Dados!$H:$H,$D$1,Dados!$G:$G,$P$4) -> 0
A13: Annualidad-Fixa | B13: =sumifs(Dados!$N:$N,Dados!$A:$A,A13,Dados!$H:$H,$D$1) -> 721.71 | C13: =B13-D13 -> 0 | D13: =SUM(D5:D12) -> 721.71 | E13: =SUM(E5:E12) -> 0 | F13: =SUM(F5:F12) -> 0 | G13: =SUM(G5:G12) -> 0 | H13: =SUM(H5:H12) -> 0 | I13: =SUM(I5:I12) -> 0 | J13: =SUM(J5:J12) -> 721.71 | K13: =SUM(K5:K12) -> 0 | ... P13: =SUM(P5:P12) -> 0
B14: Desinfection | D14: =SUM(E14:P14) -> 0 | E14: =sumifs(Dados!$N:$N,Dados!$B:$B,B14,Dados!$H:$H,$D$1,Dados!$G:$G,$E$4) -> 0 | F14: =sumifs(Dados!$N:$N,Dados!$B:$B,B14,Dados!$H:$H,$D$1,Dados!$G:$G,$F$4) -> 0 | G14: =sumifs(Dados!$N:$N,Dados!$B:$B,B14,Dados!$H:$H,$D$1,Dados!$G:$G,$G$4) -> 0 | H14: =sumifs(Dados!$N:$N,Dados!$B:$B,B14,Dados!$H:$H,$D$1,Dados!$G:$G,$H$4) -> 0 | I14: =sumifs(Dados!$N:$N,Dados!$B:$B,B14,Dados!$H:$H,$D$1,Dados!$G:$G,$I$4) -> 0 | J14: =sumifs(Dados!$N:$N,Dados!$B:$B,B14,Dados!$H:$H,$D$1,Dados!$G:$G,$J$4) -> 0 | K14: =sumifs(Dados!$N:$N,Dados!$B:$B,B14,Dados!$H:$H,$D$1,Dados!$G:$G,$K$4) -> 0 | L14: =sumifs(Dados!$N:$N,Dados!$B:$B,B14,Dados!$H:$H,$D$1,Dados!$G:$G,$L$4) -> 0 | M14: =sumifs(Dados!$N:$N,Dados!$B:$B,B14,Dados!$H:$H,$D$1,Dados!$G:$G,$M$4) -> 0 | N14: =sumifs(Dados!$N:$N,Dados!$B:$B,B14,Dados!$H:$H,$D$1,Dados!$G:$G,$N$4) -> 0 | O14: =sumifs(Dados!$N:$N,Dados!$B:$B,B14,Dados!$H:$H,$D$1,Dados!$G:$G,$O$4) -> 0 | P14: =sumifs(Dados!$N:$N,Dados!$B:$B,B14,Dados!$H:$H,$D$1,Dados!$G:$G,$P$4) -> 0
B15: Diverso – bed bug | D15: =SUM(E15:P15) -> 0 | E15: =sumifs(Dados!$N:$N,Dados!$B:$B,B15,Dados!$H:$H,$D$1,Dados!$G:$G,$E$4) -> 0 | F15: =sumifs(Dados!$N:$N,Dados!$B:$B,B15,Dados!$H:$H,$D$1,Dados!$G:$G,$F$4) -> 0 | G15: =sumifs(Dados!$N:$N,Dados!$B:$B,B15,Dados!$H:$H,$D$1,Dados!$G:$G,$G$4) -> 0 | H15: =sumifs(Dados!$N:$N,Dados!$B:$B,B15,Dados!$H:$H,$D$1,Dados!$G:$G,$H$4) -> 0 | I15: =sumifs(Dados!$N:$N,Dados!$B:$B,B15,Dados!$H:$H,$D$1,Dados!$G:$G,$I$4) -> 0 | J15: =sumifs(Dados!$N:$N,Dados!$B:$B,B15,Dados!$H:$H,$D$1,Dados!$G:$G,$J$4) -> 0 | K15: =sumifs(Dados!$N:$N,Dados!$B:$B,B15,Dados!$H:$H,$D$1,Dados!$G:$G,$K$4) -> 0 | L15: =sumifs(Dados!$N:$N,Dados!$B:$B,B15,Dados!$H:$H,$D$1,Dados!$G:$G,$L$4) -> 0 | M15: =sumifs(Dados!$N:$N,Dados!$B:$B,B15,Dados!$H:$H,$D$1,Dados!$G:$G,$M$4) -> 0 | N15: =sumifs(Dados!$N:$N,Dados!$B:$B,B15,Dados!$H:$H,$D$1,Dados!$G:$G,$N$4) -> 0 | O15: =sumifs(Dados!$N:$N,Dados!$B:$B,B15,Dados!$H:$H,$D$1,Dados!$G:$G,$O$4) -> 0 | P15: =sumifs(Dados!$N:$N,Dados!$B:$B,B15,Dados!$H:$H,$D$1,Dados!$G:$G,$P$4) -> 0
B16: laundry | D16: =SUM(E16:P16) -> 0 | E16: =sumifs(Dados!$N:$N,Dados!$B:$B,B16,Dados!$H:$H,$D$1,Dados!$G:$G,$E$4) -> 0 | F16: =sumifs(Dados!$N:$N,Dados!$B:$B,B16,Dados!$H:$H,$D$1,Dados!$G:$G,$F$4) -> 0 | G16: =sumifs(Dados!$N:$N,Dados!$B:$B,B16,Dados!$H:$H,$D$1,Dados!$G:$G,$G$4) -> 0 | H16: =sumifs(Dados!$N:$N,Dados!$B:$B,B16,Dados!$H:$H,$D$1,Dados!$G:$G,$H$4) -> 0 | I16: =sumifs(Dados!$N:$N,Dados!$B:$B,B16,Dados!$H:$H,$D$1,Dados!$G:$G,$I$4) -> 0 | J16: =sumifs(Dados!$N:$N,Dados!$B:$B,B16,Dados!$H:$H,$D$1,Dados!$G:$G,$J$4) -> 0 | K16: =sumifs(Dados!$N:$N,Dados!$B:$B,B16,Dados!$H:$H,$D$1,Dados!$G:$G,$K$4) -> 0 | L16: =sumifs(Dados!$N:$N,Dados!$B:$B,B16,Dados!$H:$H,$D$1,Dados!$G:$G,$L$4) -> 0 | M16: =sumifs(Dados!$N:$N,Dados!$B:$B,B16,Dados!$H:$H,$D$1,Dados!$G:$G,$M$4) -> 0 | N16: =sumifs(Dados!$N:$N,Dados!$B:$B,B16,Dados!$H:$H,$D$1,Dados!$G:$G,$N$4) -> 0 | O16: =sumifs(Dados!$N:$N,Dados!$B:$B,B16,Dados!$H:$H,$D$1,Dados!$G:$G,$O$4) -> 0 | P16: =sumifs(Dados!$N:$N,Dados!$B:$B,B16,Dados!$H:$H,$D$1,Dados!$G:$G,$P$4) -> 0
B17: Weapons | D17: =SUM(E17:P17) -> 0 | E17: =sumifs(Dados!$N:$N,Dados!$B:$B,B17,Dados!$H:$H,$D$1,Dados!$G:$G,$E$4) -> 0 | F17: =sumifs(Dados!$N:$N,Dados!$B:$B,B17,Dados!$H:$H,$D$1,Dados!$G:$G,$F$4) -> 0 | G17: =sumifs(Dados!$N:$N,Dados!$B:$B,B17,Dados!$H:$H,$D$1,Dados!$G:$G,$G$4) -> 0 | H17: =sumifs(Dados!$N:$N,Dados!$B:$B,B17,Dados!$H:$H,$D$1,Dados!$G:$G,$H$4) -> 0 | I17: =sumifs(Dados!$N:$N,Dados!$B:$B,B17,Dados!$H:$H,$D$1,Dados!$G:$G,$I$4) -> 0 | J17: =sumifs(Dados!$N:$N,Dados!$B:$B,B17,Dados!$H:$H,$D$1,Dados!$G:$G,$J$4) -> 0 | K17: =sumifs(Dados!$N:$N,Dados!$B:$B,B17,Dados!$H:$H,$D$1,Dados!$G:$G,$K$4) -> 0 | L17: =sumifs(Dados!$N:$N,Dados!$B:$B,B17,Dados!$H:$H,$D$1,Dados!$G:$G,$L$4) -> 0 | M17: =sumifs(Dados!$N:$N,Dados!$B:$B,B17,Dados!$H:$H,$D$1,Dados!$G:$G,$M$4) -> 0 | N17: =sumifs(Dados!$N:$N,Dados!$B:$B,B17,Dados!$H:$H,$D$1,Dados!$G:$G,$N$4) -> 0 | O17: =sumifs(Dados!$N:$N,Dados!$B:$B,B17,Dados!$H:$H,$D$1,Dados!$G:$G,$O$4) -> 0 | P17: =sumifs(Dados!$N:$N,Dados!$B:$B,B17,Dados!$H:$H,$D$1,Dados!$G:$G,$P$4) -> 0
A18: bedbugsprotocol | B18: =sumifs(Dados!$N:$N,Dados!$A:$A,A18,Dados!$H:$H,$D$1) -> 0 | C18: =B18-D18 -> 0 | D18: =SUM(D14:D17) -> 0 | E18: =SUM(E14:E17) -> 0 | F18: =SUM(F14:F17) -> 0 | G18: =SUM(G14:G17) -> 0 | H18: =SUM(H14:H17) -> 0 | I18: =SUM(I14:I17) -> 0 | J18: =SUM(J14:J17) -> 0 | K18: =SUM(K14:K17) -> 0 | ... P18: =SUM(P14:P17) -> 0
B25: Airbnb cancelation | D25: =SUM(E25:P25) -> 0 | E25: =sumifs(Dados!$N:$N,Dados!$B:$B,B25,Dados!$H:$H,$D$1,Dados!$G:$G,$E$4) -> 0 | F25: =sumifs(Dados!$N:$N,Dados!$B:$B,B25,Dados!$H:$H,$D$1,Dados!$G:$G,$F$4) -> 0 | G25: =sumifs(Dados!$N:$N,Dados!$B:$B,B25,Dados!$H:$H,$D$1,Dados!$G:$G,$G$4) -> 0 | H25: =sumifs(Dados!$N:$N,Dados!$B:$B,B25,Dados!$H:$H,$D$1,Dados!$G:$G,$H$4) -> 0 | I25: =sumifs(Dados!$N:$N,Dados!$B:$B,B25,Dados!$H:$H,$D$1,Dados!$G:$G,$I$4) -> 0 | J25: =sumifs(Dados!$N:$N,Dados!$B:$B,B25,Dados!$H:$H,$D$1,Dados!$G:$G,$J$4) -> 0 | K25: =sumifs(Dados!$N:$N,Dados!$B:$B,B25,Dados!$H:$H,$D$1,Dados!$G:$G,$K$4) -> 0 | L25: =sumifs(Dados!$N:$N,Dados!$B:$B,B25,Dados!$H:$H,$D$1,Dados!$G:$G,$L$4) -> 0 | M25: =sumifs(Dados!$N:$N,Dados!$B:$B,B25,Dados!$H:$H,$D$1,Dados!$G:$G,$M$4) -> 0 | N25: =sumifs(Dados!$N:$N,Dados!$B:$B,B25,Dados!$H:$H,$D$1,Dados!$G:$G,$N$4) -> 0 | O25: =sumifs(Dados!$N:$N,Dados!$B:$B,B25,Dados!$H:$H,$D$1,Dados!$G:$G,$O$4) -> 0 | P25: =sumifs(Dados!$N:$N,Dados!$B:$B,B25,Dados!$H:$H,$D$1,Dados!$G:$G,$P$4) -> 0
B26: Airbnb comission | D26: =SUM(E26:P26) -> 0 | E26: =sumifs(Dados!$N:$N,Dados!$B:$B,B26,Dados!$H:$H,$D$1,Dados!$G:$G,$E$4) -> 0 | F26: =sumifs(Dados!$N:$N,Dados!$B:$B,B26,Dados!$H:$H,$D$1,Dados!$G:$G,$F$4) -> 0 | G26: =sumifs(Dados!$N:$N,Dados!$B:$B,B26,Dados!$H:$H,$D$1,Dados!$G:$G,$G$4) -> 0 | H26: =sumifs(Dados!$N:$N,Dados!$B:$B,B26,Dados!$H:$H,$D$1,Dados!$G:$G,$H$4) -> 0 | I26: =sumifs(Dados!$N:$N,Dados!$B:$B,B26,Dados!$H:$H,$D$1,Dados!$G:$G,$I$4) -> 0 | J26: =sumifs(Dados!$N:$N,Dados!$B:$B,B26,Dados!$H:$H,$D$1,Dados!$G:$G,$J$4) -> 0 | K26: =sumifs(Dados!$N:$N,Dados!$B:$B,B26,Dados!$H:$H,$D$1,Dados!$G:$G,$K$4) -> 0 | L26: =sumifs(Dados!$N:$N,Dados!$B:$B,B26,Dados!$H:$H,$D$1,Dados!$G:$G,$L$4) -> 0 | M26: =sumifs(Dados!$N:$N,Dados!$B:$B,B26,Dados!$H:$H,$D$1,Dados!$G:$G,$M$4) -> 0 | N26: =sumifs(Dados!$N:$N,Dados!$B:$B,B26,Dados!$H:$H,$D$1,Dados!$G:$G,$N$4) -> 0 | O26: =sumifs(Dados!$N:$N,Dados!$B:$B,B26,Dados!$H:$H,$D$1,Dados!$G:$G,$O$4) -> 0 | P26: =sumifs(Dados!$N:$N,Dados!$B:$B,B26,Dados!$H:$H,$D$1,Dados!$G:$G,$P$4) -> 0
B27: Booking Other taxs | D27: =SUM(E27:P27) -> 0 | E27: =sumifs(Dados!$N:$N,Dados!$B:$B,$B$27,Dados!$H:$H,$D$1,Dados!$G:$G,E4) -> 0 | F27: =sumifs(Dados!$N:$N,Dados!$B:$B,$B$27,Dados!$H:$H,$D$1,Dados!$G:$G,F4) -> 0 | G27: =sumifs(Dados!$N:$N,Dados!$B:$B,$B$27,Dados!$H:$H,$D$1,Dados!$G:$G,G4) -> 0 | H27: =sumifs(Dados!$N:$N,Dados!$B:$B,$B$27,Dados!$H:$H,$D$1,Dados!$G:$G,H4) -> 0 | I27: =sumifs(Dados!$N:$N,Dados!$B:$B,$B$27,Dados!$H:$H,$D$1,Dados!$G:$G,I4) -> 0 | J27: =sumifs(Dados!$N:$N,Dados!$B:$B,$B$27,Dados!$H:$H,$D$1,Dados!$G:$G,J4) -> 0 | K27: =sumifs(Dados!$N:$N,Dados!$B:$B,$B$27,Dados!$H:$H,$D$1,Dados!$G:$G,K4) -> 0 | L27: =sumifs(Dados!$N:$N,Dados!$B:$B,$B$27,Dados!$H:$H,$D$1,Dados!$G:$G,L4) -> 0 | ... P27: =sumifs(Dados!$N:$N,Dados!$B:$B,$B$27,Dados!$H:$H,$D$1,Dados!$G:$G,P4) -> 0
B28: Booking Payment commision | D28: =SUM(E28:P28) -> 0 | E28: =sumifs(Dados!$N:$N,Dados!$B:$B,$B$28,Dados!$H:$H,$D$1,Dados!$G:$G,E4) -> 0 | F28: =sumifs(Dados!$N:$N,Dados!$B:$B,$B$28,Dados!$H:$H,$D$1,Dados!$G:$G,F4) -> 0 | G28: =sumifs(Dados!$N:$N,Dados!$B:$B,$B$28,Dados!$H:$H,$D$1,Dados!$G:$G,G4) -> 0 | H28: =sumifs(Dados!$N:$N,Dados!$B:$B,$B$28,Dados!$H:$H,$D$1,Dados!$G:$G,H4) -> 0 | I28: =sumifs(Dados!$N:$N,Dados!$B:$B,$B$28,Dados!$H:$H,$D$1,Dados!$G:$G,I4) -> 0 | J28: =sumifs(Dados!$N:$N,Dados!$B:$B,$B$28,Dados!$H:$H,$D$1,Dados!$G:$G,J4) -> 0 | K28: =sumifs(Dados!$N:$N,Dados!$B:$B,$B$28,Dados!$H:$H,$D$1,Dados!$G:$G,K4) -> 0 | L28: =sumifs(Dados!$N:$N,Dados!$B:$B,$B$28,Dados!$H:$H,$D$1,Dados!$G:$G,L4) -> 0 | ... P28: =sumifs(Dados!$N:$N,Dados!$B:$B,$B$28,Dados!$H:$H,$D$1,Dados!$G:$G,P4) -> 0
A29: Commission | B29: =sumifs(Dados!$N:$N,Dados!$A:$A,A29,Dados!$H:$H,$D$1) -> 0 | C29: =B29-D29 -> 0 | D29: =SUM(D25:D28) -> 0 | E29: =SUM(E25:E28) -> 0 | F29: =SUM(F25:F28) -> 0 | G29: =SUM(G25:G28) -> 0 | H29: =SUM(H25:H28) -> 0 | I29: =SUM(I25:I28) -> 0 | J29: =SUM(J25:J28) -> 0 | K29: =SUM(K25:K28) -> 0 | ... P29: =SUM(P25:P28) -> 0
B30: Aliguer TPEREDUNICRE MENSAL | D30: =SUM(E30:P30) -> 0 | E30: =sumifs(Dados!$N:$N,Dados!$B:$B,B30,Dados!$H:$H,$D$1,Dados!$G:$G,$E$4) -> 0 | F30: =sumifs(Dados!$N:$N,Dados!$B:$B,B30,Dados!$H:$H,$D$1,Dados!$G:$G,$F$4) -> 0 | G30: =sumifs(Dados!$N:$N,Dados!$B:$B,B30,Dados!$H:$H,$D$1,Dados!$G:$G,$G$4) -> 0 | H30: =sumifs(Dados!$N:$N,Dados!$B:$B,B30,Dados!$H:$H,$D$1,Dados!$G:$G,$H$4) -> 0 | I30: =sumifs(Dados!$N:$N,Dados!$B:$B,B30,Dados!$H:$H,$D$1,Dados!$G:$G,$I$4) -> 0 | J30: =sumifs(Dados!$N:$N,Dados!$B:$B,B30,Dados!$H:$H,$D$1,Dados!$G:$G,$J$4) -> 0 | K30: =sumifs(Dados!$N:$N,Dados!$B:$B,B30,Dados!$H:$H,$D$1,Dados!$G:$G,$K$4) -> 0 | L30: =sumifs(Dados!$N:$N,Dados!$B:$B,B30,Dados!$H:$H,$D$1,Dados!$G:$G,$L$4) -> 0 | M30: =sumifs(Dados!$N:$N,Dados!$B:$B,B30,Dados!$H:$H,$D$1,Dados!$G:$G,$M$4) -> 0 | N30: =sumifs(Dados!$N:$N,Dados!$B:$B,B30,Dados!$H:$H,$D$1,Dados!$G:$G,$N$4) -> 0 | O30: =sumifs(Dados!$N:$N,Dados!$B:$B,B30,Dados!$H:$H,$D$1,Dados!$G:$G,$O$4) -> 0 | P30: =sumifs(Dados!$N:$N,Dados!$B:$B,B30,Dados!$H:$H,$D$1,Dados!$G:$G,$P$4) -> 0
B31: Fees | D31: =SUM(E31:P31) -> 39.45 | E31: =sumifs(Dados!$N:$N,Dados!$B:$B,$B$31,Dados!$H:$H,$D$1,Dados!$G:$G,E4) -> 5.19 | F31: =sumifs(Dados!$N:$N,Dados!$B:$B,$B$31,Dados!$H:$H,$D$1,Dados!$G:$G,F4) -> 8.31 | G31: =sumifs(Dados!$N:$N,Dados!$B:$B,$B$31,Dados!$H:$H,$D$1,Dados!$G:$G,G4) -> 5.19 | H31: =sumifs(Dados!$N:$N,Dados!$B:$B,$B$31,Dados!$H:$H,$D$1,Dados!$G:$G,H4) -> 5.19 | I31: =sumifs(Dados!$N:$N,Dados!$B:$B,$B$31,Dados!$H:$H,$D$1,Dados!$G:$G,I4) -> 5.19 | J31: =sumifs(Dados!$N:$N,Dados!$B:$B,$B$31,Dados!$H:$H,$D$1,Dados!$G:$G,J4) -> 5.19 | K31: =sumifs(Dados!$N:$N,Dados!$B:$B,$B$31,Dados!$H:$H,$D$1,Dados!$G:$G,K4) -> 5.19 | L31: =sumifs(Dados!$N:$N,Dados!$B:$B,$B$31,Dados!$H:$H,$D$1,Dados!$G:$G,L4) -> 0 | ... P31: =sumifs(Dados!$N:$N,Dados!$B:$B,$B$31,Dados!$H:$H,$D$1,Dados!$G:$G,P4) -> 0
B32: Madalena8-BPI | D32: =SUM(E32:P32) -> 0 | E32: =sumifs(Dados!$N:$N,Dados!$B:$B,B32,Dados!$H:$H,$D$1,Dados!$G:$G,$E$4) -> 0 | F32: =sumifs(Dados!$N:$N,Dados!$B:$B,B32,Dados!$H:$H,$D$1,Dados!$G:$G,$F$4) -> 0 | G32: =sumifs(Dados!$N:$N,Dados!$B:$B,B32,Dados!$H:$H,$D$1,Dados!$G:$G,$G$4) -> 0 | H32: =sumifs(Dados!$N:$N,Dados!$B:$B,B32,Dados!$H:$H,$D$1,Dados!$G:$G,$H$4) -> 0 | I32: =sumifs(Dados!$N:$N,Dados!$B:$B,B32,Dados!$H:$H,$D$1,Dados!$G:$G,$I$4) -> 0 | J32: =sumifs(Dados!$N:$N,Dados!$B:$B,B32,Dados!$H:$H,$D$1,Dados!$G:$G,$J$4) -> 0 | K32: =sumifs(Dados!$N:$N,Dados!$B:$B,B32,Dados!$H:$H,$D$1,Dados!$G:$G,$K$4) -> 0 | L32: =sumifs(Dados!$N:$N,Dados!$B:$B,B32,Dados!$H:$H,$D$1,Dados!$G:$G,$L$4) -> 0 | M32: =sumifs(Dados!$N:$N,Dados!$B:$B,B32,Dados!$H:$H,$D$1,Dados!$G:$G,$M$4) -> 0 | N32: =sumifs(Dados!$N:$N,Dados!$B:$B,B32,Dados!$H:$H,$D$1,Dados!$G:$G,$N$4) -> 0 | O32: =sumifs(Dados!$N:$N,Dados!$B:$B,B32,Dados!$H:$H,$D$1,Dados!$G:$G,$O$4) -> 0 | P32: =sumifs(Dados!$N:$N,Dados!$B:$B,B32,Dados!$H:$H,$D$1,Dados!$G:$G,$P$4) -> 0
B33: Paylink | D33: =SUM(E33:P33) -> 21.01 | E33: =sumifs(Dados!$N:$N,Dados!$B:$B,B33,Dados!$H:$H,$D$1,Dados!$G:$G,$E$4) -> 0 | F33: =sumifs(Dados!$N:$N,Dados!$B:$B,B33,Dados!$H:$H,$D$1,Dados!$G:$G,$F$4) -> 0 | G33: =sumifs(Dados!$N:$N,Dados!$B:$B,B33,Dados!$H:$H,$D$1,Dados!$G:$G,$G$4) -> 0 | H33: =sumifs(Dados!$N:$N,Dados!$B:$B,B33,Dados!$H:$H,$D$1,Dados!$G:$G,$H$4) -> 0 | I33: =sumifs(Dados!$N:$N,Dados!$B:$B,B33,Dados!$H:$H,$D$1,Dados!$G:$G,$I$4) -> 0 | J33: =sumifs(Dados!$N:$N,Dados!$B:$B,B33,Dados!$H:$H,$D$1,Dados!$G:$G,$J$4) -> 21.01 | K33: =sumifs(Dados!$N:$N,Dados!$B:$B,B33,Dados!$H:$H,$D$1,Dados!$G:$G,$K$4) -> 0 | L33: =sumifs(Dados!$N:$N,Dados!$B:$B,B33,Dados!$H:$H,$D$1,Dados!$G:$G,$L$4) -> 0 | M33: =sumifs(Dados!$N:$N,Dados!$B:$B,B33,Dados!$H:$H,$D$1,Dados!$G:$G,$M$4) -> 0 | N33: =sumifs(Dados!$N:$N,Dados!$B:$B,B33,Dados!$H:$H,$D$1,Dados!$G:$G,$N$4) -> 0 | O33: =sumifs(Dados!$N:$N,Dados!$B:$B,B33,Dados!$H:$H,$D$1,Dados!$G:$G,$O$4) -> 0 | P33: =sumifs(Dados!$N:$N,Dados!$B:$B,B33,Dados!$H:$H,$D$1,Dados!$G:$G,$P$4) -> 0
A34: Bpi | B34: =sumifs(Dados!$N:$N,Dados!$A:$A,A34,Dados!$H:$H,$D$1) -> 60.46 | C34: =B34-D34 -> 0 | D34: =SUM(D30:D33) -> 60.46 | E34: =SUM(E30:E33) -> 5.19 | F34: =SUM(F30:F33) -> 8.31 | G34: =SUM(G30:G33) -> 5.19 | H34: =SUM(H30:H33) -> 5.19 | I34: =SUM(I30:I33) -> 5.19 | J34: =SUM(J30:J33) -> 26.2 | K34: =SUM(K30:K33) -> 5.19 | ... P34: =SUM(P30:P33) -> 0
B35: Banana | D35: =SUM(E35:P35) -> 6.26 | E35: =sumifs(Dados!$N:$N,Dados!$B:$B,B35,Dados!$H:$H,$D$1,Dados!$G:$G,$E$4) -> 0 | F35: =sumifs(Dados!$N:$N,Dados!$B:$B,B35,Dados!$H:$H,$D$1,Dados!$G:$G,$F$4) -> 0 | G35: =sumifs(Dados!$N:$N,Dados!$B:$B,B35,Dados!$H:$H,$D$1,Dados!$G:$G,$G$4) -> 0 | H35: =sumifs(Dados!$N:$N,Dados!$B:$B,B35,Dados!$H:$H,$D$1,Dados!$G:$G,$H$4) -> 0 | I35: =sumifs(Dados!$N:$N,Dados!$B:$B,B35,Dados!$H:$H,$D$1,Dados!$G:$G,$I$4) -> 0 | J35: =sumifs(Dados!$N:$N,Dados!$B:$B,B35,Dados!$H:$H,$D$1,Dados!$G:$G,$J$4) -> 5.1 | K35: =sumifs(Dados!$N:$N,Dados!$B:$B,B35,Dados!$H:$H,$D$1,Dados!$G:$G,$K$4) -> 1.16 | L35: =sumifs(Dados!$N:$N,Dados!$B:$B,B35,Dados!$H:$H,$D$1,Dados!$G:$G,$L$4) -> 0 | M35: =sumifs(Dados!$N:$N,Dados!$B:$B,B35,Dados!$H:$H,$D$1,Dados!$G:$G,$M$4) -> 0 | N35: =sumifs(Dados!$N:$N,Dados!$B:$B,B35,Dados!$H:$H,$D$1,Dados!$G:$G,$N$4) -> 0 | O35: =sumifs(Dados!$N:$N,Dados!$B:$B,B35,Dados!$H:$H,$D$1,Dados!$G:$G,$O$4) -> 0 | P35: =sumifs(Dados!$N:$N,Dados!$B:$B,B35,Dados!$H:$H,$D$1,Dados!$G:$G,$P$4) -> 0
B36: Butter | D36: =SUM(E36:P36) -> 86.98 | E36: =sumifs(Dados!$N:$N,Dados!$B:$B,B36,Dados!$H:$H,$D$1,Dados!$G:$G,$E$4) -> 0 | F36: =sumifs(Dados!$N:$N,Dados!$B:$B,B36,Dados!$H:$H,$D$1,Dados!$G:$G,$F$4) -> 0 | G36: =sumifs(Dados!$N:$N,Dados!$B:$B,B36,Dados!$H:$H,$D$1,Dados!$G:$G,$G$4) -> 0 | H36: =sumifs(Dados!$N:$N,Dados!$B:$B,B36,Dados!$H:$H,$D$1,Dados!$G:$G,$H$4) -> 25.08 | I36: =sumifs(Dados!$N:$N,Dados!$B:$B,B36,Dados!$H:$H,$D$1,Dados!$G:$G,$I$4) -> 10.45 | J36: =sumifs(Dados!$N:$N,Dados!$B:$B,B36,Dados!$H:$H,$D$1,Dados!$G:$G,$J$4) -> 29.4 | K36: =sumifs(Dados!$N:$N,Dados!$B:$B,B36,Dados!$H:$H,$D$1,Dados!$G:$G,$K$4) -> 22.05 | L36: =sumifs(Dados!$N:$N,Dados!$B:$B,B36,Dados!$H:$H,$D$1,Dados!$G:$G,$L$4) -> 0 | M36: =sumifs(Dados!$N:$N,Dados!$B:$B,B36,Dados!$H:$H,$D$1,Dados!$G:$G,$M$4) -> 0 | N36: =sumifs(Dados!$N:$N,Dados!$B:$B,B36,Dados!$H:$H,$D$1,Dados!$G:$G,$N$4) -> 0 | O36: =sumifs(Dados!$N:$N,Dados!$B:$B,B36,Dados!$H:$H,$D$1,Dados!$G:$G,$O$4) -> 0 | P36: =sumifs(Dados!$N:$N,Dados!$B:$B,B36,Dados!$H:$H,$D$1,Dados!$G:$G,$P$4) -> 0
B37: Cacao | D37: =SUM(E37:P37) -> 4.29 | E37: =sumifs(Dados!$N:$N,Dados!$B:$B,B37,Dados!$H:$H,$D$1,Dados!$G:$G,$E$4) -> 0 | F37: =sumifs(Dados!$N:$N,Dados!$B:$B,B37,Dados!$H:$H,$D$1,Dados!$G:$G,$F$4) -> 0 | G37: =sumifs(Dados!$N:$N,Dados!$B:$B,B37,Dados!$H:$H,$D$1,Dados!$G:$G,$G$4) -> 0 | H37: =sumifs(Dados!$N:$N,Dados!$B:$B,B37,Dados!$H:$H,$D$1,Dados!$G:$G,$H$4) -> 4.29 | I37: =sumifs(Dados!$N:$N,Dados!$B:$B,B37,Dados!$H:$H,$D$1,Dados!$G:$G,$I$4) -> 0 | J37: =sumifs(Dados!$N:$N,Dados!$B:$B,B37,Dados!$H:$H,$D$1,Dados!$G:$G,$J$4) -> 0 | K37: =sumifs(Dados!$N:$N,Dados!$B:$B,B37,Dados!$H:$H,$D$1,Dados!$G:$G,$K$4) -> 0 | L37: =sumifs(Dados!$N:$N,Dados!$B:$B,B37,Dados!$H:$H,$D$1,Dados!$G:$G,$L$4) -> 0 | M37: =sumifs(Dados!$N:$N,Dados!$B:$B,B37,Dados!$H:$H,$D$1,Dados!$G:$G,$M$4) -> 0 | N37: =sumifs(Dados!$N:$N,Dados!$B:$B,B37,Dados!$H:$H,$D$1,Dados!$G:$G,$N$4) -> 0 | O37: =sumifs(Dados!$N:$N,Dados!$B:$B,B37,Dados!$H:$H,$D$1,Dados!$G:$G,$O$4) -> 0 | P37: =sumifs(Dados!$N:$N,Dados!$B:$B,B37,Dados!$H:$H,$D$1,Dados!$G:$G,$P$4) -> 0
B38: Canela | D38: =SUM(E38:P38) -> 2.49 | E38: =sumifs(Dados!$N:$N,Dados!$B:$B,B38,Dados!$H:$H,$D$1,Dados!$G:$G,$E$4) -> 0 | F38: =sumifs(Dados!$N:$N,Dados!$B:$B,B38,Dados!$H:$H,$D$1,Dados!$G:$G,$F$4) -> 0 | G38: =sumifs(Dados!$N:$N,Dados!$B:$B,B38,Dados!$H:$H,$D$1,Dados!$G:$G,$G$4) -> 0 | H38: =sumifs(Dados!$N:$N,Dados!$B:$B,B38,Dados!$H:$H,$D$1,Dados!$G:$G,$H$4) -> 2.49 | I38: =sumifs(Dados!$N:$N,Dados!$B:$B,B38,Dados!$H:$H,$D$1,Dados!$G:$G,$I$4) -> 0 | J38: =sumifs(Dados!$N:$N,Dados!$B:$B,B38,Dados!$H:$H,$D$1,Dados!$G:$G,$J$4) -> 0 | K38: =sumifs(Dados!$N:$N,Dados!$B:$B,B38,Dados!$H:$H,$D$1,Dados!$G:$G,$K$4) -> 0 | L38: =sumifs(Dados!$N:$N,Dados!$B:$B,B38,Dados!$H:$H,$D$1,Dados!$G:$G,$L$4) -> 0 | M38: =sumifs(Dados!$N:$N,Dados!$B:$B,B38,Dados!$H:$H,$D$1,Dados!$G:$G,$M$4) -> 0 | N38: =sumifs(Dados!$N:$N,Dados!$B:$B,B38,Dados!$H:$H,$D$1,Dados!$G:$G,$N$4) -> 0 | O38: =sumifs(Dados!$N:$N,Dados!$B:$B,B38,Dados!$H:$H,$D$1,Dados!$G:$G,$O$4) -> 0 | P38: =sumifs(Dados!$N:$N,Dados!$B:$B,B38,Dados!$H:$H,$D$1,Dados!$G:$G,$P$4) -> 0
B39: Coffee | D39: =SUM(E39:P39) -> 333.81 | E39: =sumifs(Dados!$N:$N,Dados!$B:$B,B39,Dados!$H:$H,$D$1,Dados!$G:$G,$E$4) -> 0 | F39: =sumifs(Dados!$N:$N,Dados!$B:$B,B39,Dados!$H:$H,$D$1,Dados!$G:$G,$F$4) -> 0 | G39: =sumifs(Dados!$N:$N,Dados!$B:$B,B39,Dados!$H:$H,$D$1,Dados!$G:$G,$G$4) -> 0 | H39: =sumifs(Dados!$N:$N,Dados!$B:$B,B39,Dados!$H:$H,$D$1,Dados!$G:$G,$H$4) -> 59 | I39: =sumifs(Dados!$N:$N,Dados!$B:$B,B39,Dados!$H:$H,$D$1,Dados!$G:$G,$I$4) -> 59.1 | J39: =sumifs(Dados!$N:$N,Dados!$B:$B,B39,Dados!$H:$H,$D$1,Dados!$G:$G,$J$4) -> 94.6 | K39: =sumifs(Dados!$N:$N,Dados!$B:$B,B39,Dados!$H:$H,$D$1,Dados!$G:$G,$K$4) -> 121.11 | L39: =sumifs(Dados!$N:$N,Dados!$B:$B,B39,Dados!$H:$H,$D$1,Dados!$G:$G,$L$4) -> 0 | M39: =sumifs(Dados!$N:$N,Dados!$B:$B,B39,Dados!$H:$H,$D$1,Dados!$G:$G,$M$4) -> 0 | N39: =sumifs(Dados!$N:$N,Dados!$B:$B,B39,Dados!$H:$H,$D$1,Dados!$G:$G,$N$4) -> 0 | O39: =sumifs(Dados!$N:$N,Dados!$B:$B,B39,Dados!$H:$H,$D$1,Dados!$G:$G,$O$4) -> 0 | P39: =sumifs(Dados!$N:$N,Dados!$B:$B,B39,Dados!$H:$H,$D$1,Dados!$G:$G,$P$4) -> 0
B40: Coffee filter | D40: =SUM(E40:P40) -> 0 | E40: =sumifs(Dados!$N:$N,Dados!$B:$B,B40,Dados!$H:$H,$D$1,Dados!$G:$G,$E$4) -> 0 | F40: =sumifs(Dados!$N:$N,Dados!$B:$B,B40,Dados!$H:$H,$D$1,Dados!$G:$G,$F$4) -> 0 | G40: =sumifs(Dados!$N:$N,Dados!$B:$B,B40,Dados!$H:$H,$D$1,Dados!$G:$G,$G$4) -> 0 | H40: =sumifs(Dados!$N:$N,Dados!$B:$B,B40,Dados!$H:$H,$D$1,Dados!$G:$G,$H$4) -> 0 | I40: =sumifs(Dados!$N:$N,Dados!$B:$B,B40,Dados!$H:$H,$D$1,Dados!$G:$G,$I$4) -> 0 | J40: =sumifs(Dados!$N:$N,Dados!$B:$B,B40,Dados!$H:$H,$D$1,Dados!$G:$G,$J$4) -> 0 | K40: =sumifs(Dados!$N:$N,Dados!$B:$B,B40,Dados!$H:$H,$D$1,Dados!$G:$G,$K$4) -> 0 | L40: =sumifs(Dados!$N:$N,Dados!$B:$B,B40,Dados!$H:$H,$D$1,Dados!$G:$G,$L$4) -> 0 | M40: =sumifs(Dados!$N:$N,Dados!$B:$B,B40,Dados!$H:$H,$D$1,Dados!$G:$G,$M$4) -> 0 | N40: =sumifs(Dados!$N:$N,Dados!$B:$B,B40,Dados!$H:$H,$D$1,Dados!$G:$G,$N$4) -> 0 | O40: =sumifs(Dados!$N:$N,Dados!$B:$B,B40,Dados!$H:$H,$D$1,Dados!$G:$G,$O$4) -> 0 | P40: =sumifs(Dados!$N:$N,Dados!$B:$B,B40,Dados!$H:$H,$D$1,Dados!$G:$G,$P$4) -> 0
B41: Flakes | D41: =SUM(E41:P41) -> 17.94 | E41: =sumifs(Dados!$N:$N,Dados!$B:$B,B41,Dados!$H:$H,$D$1,Dados!$G:$G,$E$4) -> 0 | F41: =sumifs(Dados!$N:$N,Dados!$B:$B,B41,Dados!$H:$H,$D$1,Dados!$G:$G,$F$4) -> 0 | G41: =sumifs(Dados!$N:$N,Dados!$B:$B,B41,Dados!$H:$H,$D$1,Dados!$G:$G,$G$4) -> 0 | H41: =sumifs(Dados!$N:$N,Dados!$B:$B,B41,Dados!$H:$H,$D$1,Dados!$G:$G,$H$4) -> 8.97 | I41: =sumifs(Dados!$N:$N,Dados!$B:$B,B41,Dados!$H:$H,$D$1,Dados!$G:$G,$I$4) -> 0 | J41: =sumifs(Dados!$N:$N,Dados!$B:$B,B41,Dados!$H:$H,$D$1,Dados!$G:$G,$J$4) -> 8.97 | K41: =sumifs(Dados!$N:$N,Dados!$B:$B,B41,Dados!$H:$H,$D$1,Dados!$G:$G,$K$4) -> 0 | L41: =sumifs(Dados!$N:$N,Dados!$B:$B,B41,Dados!$H:$H,$D$1,Dados!$G:$G,$L$4) -> 0 | M41: =sumifs(Dados!$N:$N,Dados!$B:$B,B41,Dados!$H:$H,$D$1,Dados!$G:$G,$M$4) -> 0 | N41: =sumifs(Dados!$N:$N,Dados!$B:$B,B41,Dados!$H:$H,$D$1,Dados!$G:$G,$N$4) -> 0 | O41: =sumifs(Dados!$N:$N,Dados!$B:$B,B41,Dados!$H:$H,$D$1,Dados!$G:$G,$O$4) -> 0 | P41: =sumifs(Dados!$N:$N,Dados!$B:$B,B41,Dados!$H:$H,$D$1,Dados!$G:$G,$P$4) -> 0
B42: Flour | D42: =SUM(E42:P42) -> 239.27 | E42: =sumifs(Dados!$N:$N,Dados!$B:$B,B42,Dados!$H:$H,$D$1,Dados!$G:$G,$E$4) -> 0 | F42: =sumifs(Dados!$N:$N,Dados!$B:$B,B42,Dados!$H:$H,$D$1,Dados!$G:$G,$F$4) -> 0 | G42: =sumifs(Dados!$N:$N,Dados!$B:$B,B42,Dados!$H:$H,$D$1,Dados!$G:$G,$G$4) -> 0 | H42: =sumifs(Dados!$N:$N,Dados!$B:$B,B42,Dados!$H:$H,$D$1,Dados!$G:$G,$H$4) -> 39.8 | I42: =sumifs(Dados!$N:$N,Dados!$B:$B,B42,Dados!$H:$H,$D$1,Dados!$G:$G,$I$4) -> 59.7 | J42: =sumifs(Dados!$N:$N,Dados!$B:$B,B42,Dados!$H:$H,$D$1,Dados!$G:$G,$J$4) -> 40.27 | K42: =sumifs(Dados!$N:$N,Dados!$B:$B,B42,Dados!$H:$H,$D$1,Dados!$G:$G,$K$4) -> 99.5 | L42: =sumifs(Dados!$N:$N,Dados!$B:$B,B42,Dados!$H:$H,$D$1,Dados!$G:$G,$L$4) -> 0 | M42: =sumifs(Dados!$N:$N,Dados!$B:$B,B42,Dados!$H:$H,$D$1,Dados!$G:$G,$M$4) -> 0 | N42: =sumifs(Dados!$N:$N,Dados!$B:$B,B42,Dados!$H:$H,$D$1,Dados!$G:$G,$N$4) -> 0 | O42: =sumifs(Dados!$N:$N,Dados!$B:$B,B42,Dados!$H:$H,$D$1,Dados!$G:$G,$O$4) -> 0 | P42: =sumifs(Dados!$N:$N,Dados!$B:$B,B42,Dados!$H:$H,$D$1,Dados!$G:$G,$P$4) -> 0
B43: Fruits | D43: =SUM(E43:P43) -> 5.45 | E43: =sumifs(Dados!$N:$N,Dados!$B:$B,B43,Dados!$H:$H,$D$1,Dados!$G:$G,$E$4) -> 0 | F43: =sumifs(Dados!$N:$N,Dados!$B:$B,B43,Dados!$H:$H,$D$1,Dados!$G:$G,$F$4) -> 0 | G43: =sumifs(Dados!$N:$N,Dados!$B:$B,B43,Dados!$H:$H,$D$1,Dados!$G:$G,$G$4) -> 0 | H43: =sumifs(Dados!$N:$N,Dados!$B:$B,B43,Dados!$H:$H,$D$1,Dados!$G:$G,$H$4) -> 0 | I43: =sumifs(Dados!$N:$N,Dados!$B:$B,B43,Dados!$H:$H,$D$1,Dados!$G:$G,$I$4) -> 5.45 | J43: =sumifs(Dados!$N:$N,Dados!$B:$B,B43,Dados!$H:$H,$D$1,Dados!$G:$G,$J$4) -> 0 | K43: =sumifs(Dados!$N:$N,Dados!$B:$B,B43,Dados!$H:$H,$D$1,Dados!$G:$G,$K$4) -> 0 | L43: =sumifs(Dados!$N:$N,Dados!$B:$B,B43,Dados!$H:$H,$D$1,Dados!$G:$G,$L$4) -> 0 | M43: =sumifs(Dados!$N:$N,Dados!$B:$B,B43,Dados!$H:$H,$D$1,Dados!$G:$G,$M$4) -> 0 | N43: =sumifs(Dados!$N:$N,Dados!$B:$B,B43,Dados!$H:$H,$D$1,Dados!$G:$G,$N$4) -> 0 | O43: =sumifs(Dados!$N:$N,Dados!$B:$B,B43,Dados!$H:$H,$D$1,Dados!$G:$G,$O$4) -> 0 | P43: =sumifs(Dados!$N:$N,Dados!$B:$B,B43,Dados!$H:$H,$D$1,Dados!$G:$G,$P$4) -> 0
B44: Gas-Café da manhã | D44: =SUM(E44:P44) -> 164 | E44: =sumifs(Dados!$N:$N,Dados!$B:$B,B44,Dados!$H:$H,$D$1,Dados!$G:$G,$E$4) -> 0 | F44: =sumifs(Dados!$N:$N,Dados!$B:$B,B44,Dados!$H:$H,$D$1,Dados!$G:$G,$F$4) -> 0 | G44: =sumifs(Dados!$N:$N,Dados!$B:$B,B44,Dados!$H:$H,$D$1,Dados!$G:$G,$G$4) -> 0 | H44: =sumifs(Dados!$N:$N,Dados!$B:$B,B44,Dados!$H:$H,$D$1,Dados!$G:$G,$H$4) -> 0 | I44: =sumifs(Dados!$N:$N,Dados!$B:$B,B44,Dados!$H:$H,$D$1,Dados!$G:$G,$I$4) -> 84 | J44: =sumifs(Dados!$N:$N,Dados!$B:$B,B44,Dados!$H:$H,$D$1,Dados!$G:$G,$J$4) -> 40 | K44: =sumifs(Dados!$N:$N,Dados!$B:$B,B44,Dados!$H:$H,$D$1,Dados!$G:$G,$K$4) -> 40 | L44: =sumifs(Dados!$N:$N,Dados!$B:$B,B44,Dados!$H:$H,$D$1,Dados!$G:$G,$L$4) -> 0 | M44: =sumifs(Dados!$N:$N,Dados!$B:$B,B44,Dados!$H:$H,$D$1,Dados!$G:$G,$M$4) -> 0 | N44: =sumifs(Dados!$N:$N,Dados!$B:$B,B44,Dados!$H:$H,$D$1,Dados!$G:$G,$N$4) -> 0 | O44: =sumifs(Dados!$N:$N,Dados!$B:$B,B44,Dados!$H:$H,$D$1,Dados!$G:$G,$O$4) -> 0 | P44: =sumifs(Dados!$N:$N,Dados!$B:$B,B44,Dados!$H:$H,$D$1,Dados!$G:$G,$P$4) -> 0
B45: Jam | D45: =SUM(E45:P45) -> 224.37 | E45: =sumifs(Dados!$N:$N,Dados!$B:$B,B45,Dados!$H:$H,$D$1,Dados!$G:$G,$E$4) -> 0 | F45: =sumifs(Dados!$N:$N,Dados!$B:$B,B45,Dados!$H:$H,$D$1,Dados!$G:$G,$F$4) -> 0 | G45: =sumifs(Dados!$N:$N,Dados!$B:$B,B45,Dados!$H:$H,$D$1,Dados!$G:$G,$G$4) -> 0 | H45: =sumifs(Dados!$N:$N,Dados!$B:$B,B45,Dados!$H:$H,$D$1,Dados!$G:$G,$H$4) -> 87.36 | I45: =sumifs(Dados!$N:$N,Dados!$B:$B,B45,Dados!$H:$H,$D$1,Dados!$G:$G,$I$4) -> 0 | J45: =sumifs(Dados!$N:$N,Dados!$B:$B,B45,Dados!$H:$H,$D$1,Dados!$G:$G,$J$4) -> 77.41 | K45: =sumifs(Dados!$N:$N,Dados!$B:$B,B45,Dados!$H:$H,$D$1,Dados!$G:$G,$K$4) -> 59.6 | L45: =sumifs(Dados!$N:$N,Dados!$B:$B,B45,Dados!$H:$H,$D$1,Dados!$G:$G,$L$4) -> 0 | M45: =sumifs(Dados!$N:$N,Dados!$B:$B,B45,Dados!$H:$H,$D$1,Dados!$G:$G,$M$4) -> 0 | N45: =sumifs(Dados!$N:$N,Dados!$B:$B,B45,Dados!$H:$H,$D$1,Dados!$G:$G,$N$4) -> 0 | O45: =sumifs(Dados!$N:$N,Dados!$B:$B,B45,Dados!$H:$H,$D$1,Dados!$G:$G,$O$4) -> 0 | P45: =sumifs(Dados!$N:$N,Dados!$B:$B,B45,Dados!$H:$H,$D$1,Dados!$G:$G,$P$4) -> 0
B46: Milk | D46: =SUM(E46:P46) -> 271.8 | E46: =sumifs(Dados!$N:$N,Dados!$B:$B,B46,Dados!$H:$H,$D$1,Dados!$G:$G,$E$4) -> 0 | F46: =sumifs(Dados!$N:$N,Dados!$B:$B,B46,Dados!$H:$H,$D$1,Dados!$G:$G,$F$4) -> 0 | G46: =sumifs(Dados!$N:$N,Dados!$B:$B,B46,Dados!$H:$H,$D$1,Dados!$G:$G,$G$4) -> 0 | H46: =sumifs(Dados!$N:$N,Dados!$B:$B,B46,Dados!$H:$H,$D$1,Dados!$G:$G,$H$4) -> 70.56 | I46: =sumifs(Dados!$N:$N,Dados!$B:$B,B46,Dados!$H:$H,$D$1,Dados!$G:$G,$I$4) -> 51.6 | J46: =sumifs(Dados!$N:$N,Dados!$B:$B,B46,Dados!$H:$H,$D$1,Dados!$G:$G,$J$4) -> 77.4 | K46: =sumifs(Dados!$N:$N,Dados!$B:$B,B46,Dados!$H:$H,$D$1,Dados!$G:$G,$K$4) -> 72.24 | L46: =sumifs(Dados!$N:$N,Dados!$B:$B,B46,Dados!$H:$H,$D$1,Dados!$G:$G,$L$4) -> 0 | M46: =sumifs(Dados!$N:$N,Dados!$B:$B,B46,Dados!$H:$H,$D$1,Dados!$G:$G,$M$4) -> 0 | N46: =sumifs(Dados!$N:$N,Dados!$B:$B,B46,Dados!$H:$H,$D$1,Dados!$G:$G,$N$4) -> 0 | O46: =sumifs(Dados!$N:$N,Dados!$B:$B,B46,Dados!$H:$H,$D$1,Dados!$G:$G,$O$4) -> 0 | P46: =sumifs(Dados!$N:$N,Dados!$B:$B,B46,Dados!$H:$H,$D$1,Dados!$G:$G,$P$4) -> 0
...

Sheet Analysis OUT
D1: 2026
A2: PELA DATA DO EVENTO
A3: CATEGORIA | B3: PRODUTO | D3: TOTAL2026 | E3: Jan | F3: Fev | G3: Mar | H3: Apr | I3: May | J3: Jun | K3: Jul | L3: Aug | M3: Sep | N3: Oct | O3: Nov | P3: Dez
D4: TOTAL | E4: 1 | F4: 2 | G4: 3 | H4: 4 | I4: 5 | J4: 6 | K4: 7 | L4: 8 | M4: 9 | N4: 10 | O4: 11 | P4: 12
