Workbook

Sheet OUT Before Season
A1: From | B1: 2025 | C1: Bank | D1: Drop Box | E1: Total
A2: Opening | B2: 2717.69 | C2: 89327.83 | D2: 89827 | E2: =C2+D2 -> 179154.83
A3: Obra-Cafe | B3: 2717.69 | C3: =SUMIFS(Dados!$N:$N,Dados!$D:$D,$C$1,Dados!$A:$A,A3,Dados!$P:$P,"") -> 39930.68 | D3: =SUMIFS(Dados!$N:$N,Dados!$D:$D,$D$1,Dados!$A:$A,A3) -> 40411.96 | E3: =SUM(B3:D3) -> 83060.33
A4: Contabilidade | C4: =SUMIFS(Dados!$N:$N,Dados!$D:$D,$C$1,Dados!$B:$B,A4,Dados!$P:$P,"") -> 3168 | D4: =SUMIFS(Dados!$N:$N,Dados!$D:$D,$D$1,Dados!$B:$B,A4) -> 0 | E4: =SUM(B4:D4) -> 3168
A5: Adrien | C5: =SUMIFS(Dados!$N:$N,Dados!$D:$D,$C$1,Dados!$B:$B,A5,Dados!$P:$P,"") -> 3382.27 | D5: =SUMIFS(Dados!$N:$N,Dados!$D:$D,$D$1,Dados!$B:$B,A5) -> 0 | E5: =SUM(B5:D5) -> 3382.27
A6: NOSInternet | C6: =SUMIFS(Dados!$N:$N,Dados!$D:$D,$C$1,Dados!$B:$B,A6,Dados!$P:$P,"") -> 594.52 | D6: =SUMIFS(Dados!$N:$N,Dados!$D:$D,$D$1,Dados!$B:$B,A6) -> 0 | E6: =SUM(B6:D6) -> 594.52
A7: Fees | C7: =SUMIFS(Dados!$N:$N,Dados!$D:$D,$C$1,Dados!$B:$B,A7,Dados!$P:$P,"") -> 49.83 | D7: =SUMIFS(Dados!$N:$N,Dados!$D:$D,$D$1,Dados!$B:$B,A7) -> 0 | E7: =SUM(B7:D7) -> 49.83
A8: Aggema | C8: =SUMIFS(Dados!$N:$N,Dados!$D:$D,$C$1,Dados!$B:$B,A8,Dados!$P:$P,"") -> 1330.28 | D8: =SUMIFS(Dados!$N:$N,Dados!$D:$D,$D$1,Dados!$B:$B,A8) -> 0 | E8: =SUM(B8:D8) -> 1330.28
A9: EnergiaEDP | C9: =SUMIFS(Dados!$N:$N,Dados!$D:$D,$C$1,Dados!$B:$B,A9,Dados!$P:$P,"") -> 2431.18 | D9: =SUMIFS(Dados!$N:$N,Dados!$D:$D,$D$1,Dados!$B:$B,A9) -> 0 | E9: =SUM(B9:D9) -> 2431.18
A10: ÁguaFAGAR | C10: =SUMIFS(Dados!$N:$N,Dados!$D:$D,$C$1,Dados!$B:$B,A10,Dados!$P:$P,"") -> 2314.65 | D10: =SUMIFS(Dados!$N:$N,Dados!$D:$D,$D$1,Dados!$B:$B,A10) -> 0 | E10: =SUM(B10:D10) -> 2314.65
A11: CFE | C11: =SUMIFS(Dados!$N:$N,Dados!$D:$D,$C$1,Dados!$B:$B,A11,Dados!$P:$P,"") -> 780 | D11: =SUMIFS(Dados!$N:$N,Dados!$D:$D,$D$1,Dados!$B:$B,A11) -> 0 | E11: =SUM(B11:D11) -> 780
A12: Invest | C12: =SUMIFS(Dados!$N:$N,Dados!$D:$D,$C$1,Dados!$B:$B,A12,Dados!$P:$P,"") -> 18500 | D12: =SUMIFS(Dados!$N:$N,Dados!$D:$D,$D$1,Dados!$B:$B,A12) -> 0 | E12: =SUM(B12:D12) -> 18500
A13: Seg.Soc. | C13: =SUMIFS(Dados!$N:$N,Dados!$D:$D,$C$1,Dados!$B:$B,A13,Dados!$P:$P,"") -> 3589.15 | D13: =SUMIFS(Dados!$N:$N,Dados!$D:$D,$D$1,Dados!$B:$B,A13) -> 0 | E13: =SUM(B13:D13) -> 3589.15
A14: IVA | C14: =SUMIFS(Dados!$N:$N,Dados!$D:$D,$C$1,Dados!$B:$B,A14,Dados!$P:$P,"") -> 224.05 | D14: =SUMIFS(Dados!$N:$N,Dados!$D:$D,$D$1,Dados!$B:$B,A14) -> 0 | E14: =SUM(B14:D14) -> 224.05
A15: UberCopter | C15: =SUMIFS(Dados!$N:$N,Dados!$D:$D,$C$1,Dados!$B:$B,A15,Dados!$P:$P,"") -> 34.66 | D15: =SUMIFS(Dados!$N:$N,Dados!$D:$D,$D$1,Dados!$B:$B,A15) -> 0 | E15: =SUM(B15:D15) -> 34.66
... A17: Cloudbeds | C17: =SUMIFS(Dados!$N:$N,Dados!$D:$D,$C$1,Dados!$B:$B,A17,Dados!$P:$P,"") -> 523.8 | D17: =SUMIFS(Dados!$N:$N,Dados!$D:$D,$D$1,Dados!$B:$B,A17) -> 0 | E17: =SUM(B17:D17) -> 523.8
A18: Total OUT | B18: =SUM(B3:B17) -> 2717.69 | C18: =SUM(C3:C17) -> 77002.58 | D18: =SUM(D3:D17) -> 40411.96 | E18: =SUM(E3:E17) -> 120132.23
A19: Final | B19: =B2-B18 -> 0 | C19: =C2-C18 -> 12325.25 | D19: =D2-D18 -> 49415.04 | E19: =SUM(C19:D19) -> 61740.29
A20: Final for reals | E20: =SUM(C20:D20) -> 0
A21: Difference | E21: =SUM(C21:D21) -> 0

Sheet Obra cash flow 1
A1: From | B1: 10k1 | C1: 10k2 | D1: 10k3 | E1: 5k4 | F1: 5k5 | G1: 5k6 | H1: 2025 | I1: Bank | J1: Revolut | K1: AdrianMoney | L1: MoneyBox | M1: Total
A2: Coluna M | B2: Drop10.000-01/01/2026 | C2: Drop10.000-20/02/2026 | D2: Drop10.000-28/02/2026 | E2: Drop5.000-01/05/2026 | F2: Drop5.000-01/06/2026 | G2: Drop5.000-01/09/2026 | H2: 2025
A3: Date | B3: 46023 | C3: 46073 | D3: 46081 | E3: 46143 | F3: 46174 | G3: 46266 | H3: 46023
A4: Opening | B4: 10000 | C4: 10000 | D4: 10000 | E4: 5000 | F4: 5000 | G4: 5000
A5: Cafe/food-Cafe | B5: =SUMIFS(Dados!$N:$N,Dados!$P:$P,$B$2,Dados!$B:$B,A5) -> 418.5 | C5: =SUMIFS(Dados!$N:$N,Dados!$P:$P,$C$2,Dados!$B:$B,A5) -> 10 | D5: =SUMIFS(Dados!$N:$N,Dados!$P:$P,$D$2,Dados!$B:$B,A5) -> 0 | E5: =SUMIFS(Dados!$N:$N,Dados!$P:$P,$E$2,Dados!$B:$B,A5) -> 0 | F5: =SUMIFS(Dados!$N:$N,Dados!$P:$P,$F$2,Dados!$B:$B,A5) -> 0 | G5: =SUMIFS(Dados!$N:$N,Dados!$P:$P,$G$2,Dados!$B:$B,A5) -> 0 | H5: =SUMIFS(Dados!$N:$N,Dados!$P:$P,$H$2,Dados!$B:$B,A5) -> 0 | I5: =SUMIFS(Dados!$N:$N,Dados!$D:$D,$I$1,Dados!$B:$B,A5,Dados!$P:$P,"") -> 409.32 | J5: =SUMIFS(Dados!$N:$N,Dados!$D:$D,$J$1,Dados!$B:$B,A5) -> 0 | K5: =SUMIFS(Dados!$N:$N,Dados!$D:$D,$K$1,Dados!$B:$B,A5) -> 0 | L5: =SUMIFS(Dados!$N:$N,Dados!$D:$D,$L$1,Dados!$B:$B,A5) -> 0 | M5: =SUM(B5:L5) -> 837.82
A6: Furnitures-Cafe | B6: =SUMIFS(Dados!$N:$N,Dados!$P:$P,$B$2,Dados!$B:$B,A6) -> 0 | C6: =SUMIFS(Dados!$N:$N,Dados!$P:$P,$C$2,Dados!$B:$B,A6) -> 7000 | D6: =SUMIFS(Dados!$N:$N,Dados!$P:$P,$D$2,Dados!$B:$B,A6) -> 50 | E6: =SUMIFS(Dados!$N:$N,Dados!$P:$P,$E$2,Dados!$B:$B,A6) -> 1200 | F6: =SUMIFS(Dados!$N:$N,Dados!$P:$P,$F$2,Dados!$B:$B,A6) -> 1665 | G6: =SUMIFS(Dados!$N:$N,Dados!$P:$P,$G$2,Dados!$B:$B,A6) -> 0 | H6: =SUMIFS(Dados!$N:$N,Dados!$P:$P,$H$2,Dados!$B:$B,A6) -> 0 | I6: =SUMIFS(Dados!$N:$N,Dados!$D:$D,$I$1,Dados!$B:$B,A6,Dados!$P:$P,"") -> 11557.13 | J6: =SUMIFS(Dados!$N:$N,Dados!$D:$D,$J$1,Dados!$B:$B,A6) -> 0 | K6: =SUMIFS(Dados!$N:$N,Dados!$D:$D,$K$1,Dados!$B:$B,A6) -> 0 | L6: =SUMIFS(Dados!$N:$N,Dados!$D:$D,$L$1,Dados!$B:$B,A6) -> 0 | M6: =SUM(B6:L6) -> 21472.13
A7: Maodeobra-Cafe | B7: =SUMIFS(Dados!$N:$N,Dados!$P:$P,$B$2,Dados!$B:$B,A7) -> 6605.4 | C7: =SUMIFS(Dados!$N:$N,Dados!$P:$P,$C$2,Dados!$B:$B,A7) -> 2600 | D7: =SUMIFS(Dados!$N:$N,Dados!$P:$P,$D$2,Dados!$B:$B,A7) -> 8690 | E7: =SUMIFS(Dados!$N:$N,Dados!$P:$P,$E$2,Dados!$B:$B,A7) -> 3765 | F7: =SUMIFS(Dados!$N:$N,Dados!$P:$P,$F$2,Dados!$B:$B,A7) -> 3020 | G7: =SUMIFS(Dados!$N:$N,Dados!$P:$P,$G$2,Dados!$B:$B,A7) -> 500 | H7: =SUMIFS(Dados!$N:$N,Dados!$P:$P,$H$2,Dados!$B:$B,A7) -> 0 | I7: =SUMIFS(Dados!$N:$N,Dados!$D:$D,$I$1,Dados!$B:$B,A7,Dados!$P:$P,"") -> 1245.13 | J7: =SUMIFS(Dados!$N:$N,Dados!$D:$D,$J$1,Dados!$B:$B,A7) -> 0 | K7: =SUMIFS(Dados!$N:$N,Dados!$D:$D,$K$1,Dados!$B:$B,A7) -> 0 | L7: =SUMIFS(Dados!$N:$N,Dados!$D:$D,$L$1,Dados!$B:$B,A7) -> 0 | M7: =SUM(B7:L7) -> 26425.53
A8: Material/Tools-Cafe | B8: =SUMIFS(Dados!$N:$N,Dados!$P:$P,$B$2,Dados!$B:$B,A8) -> 2927.33 | C8: =SUMIFS(Dados!$N:$N,Dados!$P:$P,$C$2,Dados!$B:$B,A8) -> 320.73 | D8: =SUMIFS(Dados!$N:$N,Dados!$P:$P,$D$2,Dados!$B:$B,A8) -> 900 | E8: =SUMIFS(Dados!$N:$N,Dados!$P:$P,$E$2,Dados!$B:$B,A8) -> 0 | F8: =SUMIFS(Dados!$N:$N,Dados!$P:$P,$F$2,Dados!$B:$B,A8) -> 245 | G8: =SUMIFS(Dados!$N:$N,Dados!$P:$P,$G$2,Dados!$B:$B,A8) -> 0 | H8: =SUMIFS(Dados!$N:$N,Dados!$P:$P,$H$2,Dados!$B:$B,A8) -> 337.59 | I8: =SUMIFS(Dados!$N:$N,Dados!$D:$D,$I$1,Dados!$B:$B,A8,Dados!$P:$P,"") -> 20039.74 | J8: =SUMIFS(Dados!$N:$N,Dados!$D:$D,$J$1,Dados!$B:$B,A8) -> 0 | K8: =SUMIFS(Dados!$N:$N,Dados!$D:$D,$K$1,Dados!$B:$B,A8) -> 0 | L8: =SUMIFS(Dados!$N:$N,Dados!$D:$D,$L$1,Dados!$B:$B,A8) -> 0 | M8: =SUM(B8:L8) -> 24770.39
A9: Project/Admin-Cafe | B9: =SUMIFS(Dados!$N:$N,Dados!$P:$P,$B$2,Dados!$B:$B,A9) -> 0 | C9: =SUMIFS(Dados!$N:$N,Dados!$P:$P,$C$2,Dados!$B:$B,A9) -> 15 | D9: =SUMIFS(Dados!$N:$N,Dados!$P:$P,$D$2,Dados!$B:$B,A9) -> 350 | E9: =SUMIFS(Dados!$N:$N,Dados!$P:$P,$E$2,Dados!$B:$B,A9) -> 0 | F9: =SUMIFS(Dados!$N:$N,Dados!$P:$P,$F$2,Dados!$B:$B,A9) -> 0 | G9: =SUMIFS(Dados!$N:$N,Dados!$P:$P,$G$2,Dados!$B:$B,A9) -> 0 | H9: =SUMIFS(Dados!$N:$N,Dados!$P:$P,$H$2,Dados!$B:$B,A9) -> 2380.1 | I9: =SUMIFS(Dados!$N:$N,Dados!$D:$D,$I$1,Dados!$B:$B,A9,Dados!$P:$P,"") -> 6340.51 | J9: =SUMIFS(Dados!$N:$N,Dados!$D:$D,$J$1,Dados!$B:$B,A9) -> 0 | K9: =SUMIFS(Dados!$N:$N,Dados!$D:$D,$K$1,Dados!$B:$B,A9) -> 0 | L9: =SUMIFS(Dados!$N:$N,Dados!$D:$D,$L$1,Dados!$B:$B,A9) -> 0 | M9: =SUM(B9:L9) -> 9085.61
A10: Uber/ Transporte-Cafe | B10: =SUMIFS(Dados!$N:$N,Dados!$P:$P,$B$2,Dados!$B:$B,A10) -> 50 | C10: =SUMIFS(Dados!$N:$N,Dados!$P:$P,$C$2,Dados!$B:$B,A10) -> 0 | D10: =SUMIFS(Dados!$N:$N,Dados!$P:$P,$D$2,Dados!$B:$B,A10) -> 0 | E10: =SUMIFS(Dados!$N:$N,Dados!$P:$P,$E$2,Dados!$B:$B,A10) -> 0 | F10: =SUMIFS(Dados!$N:$N,Dados!$P:$P,$F$2,Dados!$B:$B,A10) -> 0 | G10: =SUMIFS(Dados!$N:$N,Dados!$P:$P,$G$2,Dados!$B:$B,A10) -> 0 | H10: =SUMIFS(Dados!$N:$N,Dados!$P:$P,$H$2,Dados!$B:$B,A10) -> 0 | I10: =SUMIFS(Dados!$N:$N,Dados!$D:$D,$I$1,Dados!$B:$B,A10,Dados!$P:$P,"") -> 338.85 | J10: =SUMIFS(Dados!$N:$N,Dados!$D:$D,$J$1,Dados!$B:$B,A10) -> 7.52 | K10: =SUMIFS(Dados!$N:$N,Dados!$D:$D,$K$1,Dados!$B:$B,A10) -> 0 | L10: =SUMIFS(Dados!$N:$N,Dados!$D:$D,$L$1,Dados!$B:$B,A10) -> 0 | M10: =SUM(B10:L10) -> 396.37
A11: Total OUT | B11: =SUM(B5:B10) -> 10001.23 | C11: =SUM(C5:C10) -> 9945.73 | D11: =SUM(D5:D10) -> 9990 | E11: =SUM(E5:E10) -> 4965 | F11: =SUM(F5:F10) -> 4930 | G11: =SUM(G5:G10) -> 500 | H11: =SUM(H5:H10) -> 2717.69 | I11: =SUM(I5:I10) -> 39930.68 | ... M11: =SUM(M5:M10) -> 82987.85
A12: Final | B12: =B4-B11 -> -1.23 | C12: =C4-C11 -> 54.27 | D12: =D4-D11 -> 10 | E12: =E4-E11 -> 35 | F12: =F4-F11 -> 70 | G12: =G4-G11 -> 4500 | M12: =SUM(B12:K12) -> 4668.04
A13: Final for reals | B13: 0 | C13: 0 | D13: 0 | E13: 45 | F13: 71 | G13: 4500 | M13: =SUM(B13:K13) -> 4616
A14: Difference | B14: =B12-B13 -> -1.23 | C14: =C12-C13 -> 54.27 | D14: =D12-D13 -> 10 | E14: =E12-E13 -> -10 | F14: =F12-F13 -> -1 | G14: =G12-G13 -> 0 | H14: =H12-H13 -> 0 | I14: =I12-I13 -> 0 | ... L14: =L12-L13 -> 0 | M14: =SUM(B14:K14) -> 52.04

Sheet Obra cash flow
A1: From | B1: 10k1 | C1: 10k2 | D1: 10k3 | E1: 5k4 | F1: 5k5 | G1: 2025 | H1: Bank | I1: Revolut | J1: Total
A2: Opening | B2: 10000 | C2: 10000 | D2: 10000 | E2: 5000 | F2: 5000
A3: Cafe/food-Cafe | B3: 418.5 | C3: 10 | D3: 0 | E3: 0 | F3: 0 | G3: 0 | H3: 409.32 | I3: 0 | J3: 837.82
A4: Furnitures-Cafe | B4: 0 | C4: 7000 | D4: 50 | E4: 1200 | F4: 1665 | G4: 0 | H4: 8196.86 | I4: 0 | J4: 18111.86
A5: Maodeobra-Cafe | B5: 6605.4 | C5: 2600 | D5: 8690 | E5: 3765 | F5: 700 | G5: 0 | H5: 1245.13 | I5: 0 | J5: 23605.53
A6: Material/Tools-Cafe | B6: 2927.33 | C6: 320.73 | D6: 900 | E6: 0 | F6: 0 | G6: 337.59 | H6: 22285.12 | I6: 0 | J6: 26770.77
A7: Project/Admin-Cafe | B7: 0 | C7: 15 | D7: 350 | E7: 0 | F7: 0 | G7: 2380.1 | H7: 6340.51 | I7: 0 | J7: 9085.61
A8: Uber/ Transporte-Cafe | B8: 50 | C8: 0 | D8: 0 | E8: 0 | F8: 0 | G8: 0 | H8: 338.85 | I8: 7.52 | J8: 396.37
A9: Total OUT | B9: 10001.23 | C9: 9945.73 | D9: 9990 | E9: 4965 | F9: 2365 | G9: 2717.69 | H9: 38815.79 | I9: 7.52 | J9: 78807.96

Sheet Receptor
A1: Receptor
A3: Ano | B3: 2025 | C3: 2025 | D3: 2025 | E3: 2025 | F3: 2025 | G3: 2025 | H3: 2025 | I3: 2025 | J3: 2025 | K3: 2025 | L3: 2025 | M3: 2025 | N3: 2025
A4: By Check in / No commission | B4: 1 | C4: 2 | D4: 3 | E4: 4 | F4: 5 | G4: 6 | H4: 7 | I4: 8 | J4: 9 | K4: 10 | L4: 11 | M4: 12 | N4: TOTAL
A5: Booking | F5: =sumifs(CloudBed!$V:$V,CloudBed!$K:$K,$A$5,CloudBed!$E:$E,F4) -> 6758 | G5: =sumifs(CloudBed!$V:$V,CloudBed!$K:$K,$A$5,CloudBed!$E:$E,G4) -> 8459.71 | H5: =sumifs(CloudBed!$V:$V,CloudBed!$K:$K,$A$5,CloudBed!$E:$E,H4) -> 9070.84 | I5: =sumifs(CloudBed!$V:$V,CloudBed!$K:$K,$A$5,CloudBed!$E:$E,I4) -> 11429.85 | J5: =sumifs(CloudBed!$V:$V,CloudBed!$K:$K,$A$5,CloudBed!$E:$E,J4) -> 10253.09 | K5: =sumifs(CloudBed!$V:$V,CloudBed!$K:$K,$A$5,CloudBed!$E:$E,K4) -> 0 | L5: =sumifs(CloudBed!$V:$V,CloudBed!$K:$K,$A$5,CloudBed!$E:$E,L4) -> 0 | M5: =sumifs(CloudBed!$V:$V,CloudBed!$K:$K,$A$5,CloudBed!$E:$E,M4) -> 0 | N5: =SUM(B5:M5) -> 45971.49
A6: HW | F6: =sumifs(CloudBed!$V:$V,CloudBed!$K:$K,$A$6,CloudBed!$E:$E,F4) -> 2470.5 | G6: =sumifs(CloudBed!$V:$V,CloudBed!$K:$K,$A$6,CloudBed!$E:$E,G4) -> 5678 | H6: =sumifs(CloudBed!$V:$V,CloudBed!$K:$K,$A$6,CloudBed!$E:$E,H4) -> 8233.95 | I6: =sumifs(CloudBed!$V:$V,CloudBed!$K:$K,$A$6,CloudBed!$E:$E,I4) -> 8113.25 | J6: =sumifs(CloudBed!$V:$V,CloudBed!$K:$K,$A$6,CloudBed!$E:$E,J4) -> 5962.2 | K6: =sumifs(CloudBed!$V:$V,CloudBed!$K:$K,$A$6,CloudBed!$E:$E,K4) -> 0 | L6: =sumifs(CloudBed!$V:$V,CloudBed!$K:$K,$A$6,CloudBed!$E:$E,L4) -> 0 | M6: =sumifs(CloudBed!$V:$V,CloudBed!$K:$K,$A$6,CloudBed!$E:$E,M4) -> 0 | N6: =SUM(B6:M6) -> 30457.9
A7: Airbnb | F7: =sumifs(CloudBed!$V:$V,CloudBed!$K:$K,$A$7,CloudBed!$E:$E,F4) -> 5253.2089 | G7: =sumifs(CloudBed!$V:$V,CloudBed!$K:$K,$A$7,CloudBed!$E:$E,G4) -> 6570.14 | H7: =sumifs(CloudBed!$V:$V,CloudBed!$K:$K,$A$7,CloudBed!$E:$E,H4) -> 5139.55 | I7: =sumifs(CloudBed!$V:$V,CloudBed!$K:$K,$A$7,CloudBed!$E:$E,I4) -> 7180.46 | J7: =sumifs(CloudBed!$V:$V,CloudBed!$K:$K,$A$7,CloudBed!$E:$E,J4) -> 4088.91 | K7: =sumifs(CloudBed!$J:$J,CloudBed!$H:$H,"Airbnb (API) (Channel Collect Booking)",CloudBed!$U:$U,K4) -> 0 | L7: =sumifs(CloudBed!$J:$J,CloudBed!$H:$H,"Airbnb (API) (Channel Collect Booking)",CloudBed!$U:$U,L4) -> 0 | M7: =sumifs(CloudBed!$J:$J,CloudBed!$H:$H,"Airbnb (API) (Channel Collect Booking)",CloudBed!$U:$U,M4) -> 0 | N7: =SUM(B7:M7) -> 28232.269
A8: Website | F8: =sumifs(CloudBed!$V:$V,CloudBed!$K:$K,"*Website*",CloudBed!$E:$E,F4) -> 0 | G8: =sumifs(CloudBed!$V:$V,CloudBed!$K:$K,"*Website*",CloudBed!$E:$E,G4) -> 483.26 | H8: =sumifs(CloudBed!$V:$V,CloudBed!$K:$K,"*Website*",CloudBed!$E:$E,H4) -> 224.5 | I8: =sumifs(CloudBed!$V:$V,CloudBed!$K:$K,"*Website*",CloudBed!$E:$E,I4) -> 42.53 | J8: =sumifs(CloudBed!$V:$V,CloudBed!$K:$K,"*Website*",CloudBed!$E:$E,J4) -> 57.94 | K8: =sumifs(CloudBed!$V:$V,CloudBed!$K:$K,"*Website*",CloudBed!$E:$E,K4) -> 0 | L8: =sumifs(CloudBed!$V:$V,CloudBed!$K:$K,"*Website*",CloudBed!$E:$E,L4) -> 0 | M8: =sumifs(CloudBed!$V:$V,CloudBed!$K:$K,"*Website*",CloudBed!$E:$E,M4) -> 0 | N8: =SUM(B8:M8) -> 808.23
A9: TotalOTA | B9: =SUM(B5:B8) -> 0 | C9: =SUM(C5:C8) -> 0 | D9: =SUM(D5:D8) -> 0 | E9: =SUM(E5:E8) -> 0 | F9: =SUM(F5:F8) -> 14481.709 | G9: =SUM(G5:G8) -> 21191.11 | H9: =SUM(H5:H8) -> 22668.84 | I9: =SUM(I5:I8) -> 26766.09 | ... M9: =SUM(M5:M8) -> 0 | N9: =SUM(B9:M9) -> 105469.89
A10: Walk-In | F10: =sumifs(CloudBed!$V:$V,CloudBed!$K:$K,"Walk-In",CloudBed!$E:$E,F4) -> 0 | G10: =sumifs(CloudBed!$V:$V,CloudBed!$K:$K,"Walk-In",CloudBed!$E:$E,G4) -> 32 | H10: =sumifs(CloudBed!$V:$V,CloudBed!$K:$K,"Walk-In",CloudBed!$E:$E,H4) -> 0 | I10: =sumifs(CloudBed!$V:$V,CloudBed!$K:$K,"Walk-In",CloudBed!$E:$E,I4) -> 0 | N10: =SUM(B10:M10) -> 32
A11: Friends & Family | F11: =sumifs(CloudBed!$V:$V,CloudBed!$K:$K,$A$11,CloudBed!$E:$E,F4) -> 0 | G11: =sumifs(CloudBed!$V:$V,CloudBed!$K:$K,$A$11,CloudBed!$E:$E,G4) -> 214.5 | H11: =sumifs(CloudBed!$V:$V,CloudBed!$K:$K,$A$11,CloudBed!$E:$E,H4) -> 220 | I11: =sumifs(CloudBed!$V:$V,CloudBed!$K:$K,$A$11,CloudBed!$E:$E,I4) -> 0 | J11: =sumifs(CloudBed!$V:$V,CloudBed!$K:$K,$A$11,CloudBed!$E:$E,J4) -> 0 | K11: =sumifs(FF!$E:$E,FF!$C:$C,K4) -> 0 | L11: =sumifs(FF!$E:$E,FF!$C:$C,L4) -> 0 | M11: =sumifs(FF!$E:$E,FF!$C:$C,M4) -> 0 | N11: =SUM(B11:M11) -> 434.5
A12: Friends & Family | F12: =sumifs(FF!$E:$E,FF!$C:$C,F4) -> 1331 | G12: =sumifs(FF!$E:$E,FF!$C:$C,G4) -> 2027 | H12: =sumifs(FF!$E:$E,FF!$C:$C,H4) -> 2825 | I12: =sumifs(FF!$E:$E,FF!$C:$C,I4) -> 5989.66 | J12: =sumifs(FF!$E:$E,FF!$C:$C,J4) -> 2117.99
A13: Friends & Family | F13: =F11+F12 -> 1331 | G13: =G11+G12 -> 2241.5 | H13: =H11+H12 -> 3045 | I13: =I11+I12 -> 5989.66 | J13: =J11+J12 -> 2117.99 | K13: =K11+K12 -> 0 | L13: =L11+L12 -> 0 | M13: =M11+M12 -> 0 | N13: =N11+N12 -> 434.5
A14: TotalWalk | B14: =SUM(B10:B12) -> 0 | C14: =SUM(C10:C12) -> 0 | D14: =SUM(D10:D12) -> 0 | E14: =SUM(E10:E12) -> 0 | F14: =F10+F13 -> 1331 | G14: =G10+G13 -> 2273.5 | H14: =H10+H13 -> 3045 | I14: =I10+I13 -> 5989.66 | J14: =J10+J13 -> 2117.99 | K14: =K10+K13 -> 0 | L14: =L10+L13 -> 0 | M14: =M10+M13 -> 0 | N14: =SUM(B14:M14) -> 14757.15
A16: CityTax | F16: =sumifs(CloudBed!$P:$P,CloudBed!$E:$E,F4) -> 666 | G16: =sumifs(CloudBed!$P:$P,CloudBed!$E:$E,G4) -> 1216 | H16: =sumifs(CloudBed!$P:$P,CloudBed!$E:$E,H4) -> 1230 | I16: =sumifs(CloudBed!$P:$P,CloudBed!$E:$E,I4) -> 1160 | J16: =sumifs(CloudBed!$P:$P,CloudBed!$E:$E,J4) -> 1182 | K16: =sumifs(CloudBed!$P:$P,CloudBed!$E:$E,K4) -> 0 | L16: =sumifs(CloudBed!$P:$P,CloudBed!$E:$E,L4) -> 0 | M16: =sumifs(CloudBed!$P:$P,CloudBed!$E:$E,M4) -> 0 | N16: =SUM(B16:M16) -> 5454
A18: TotalAcomodation | E18: 0 | F18: =F9+F14 -> 15812.709 | G18: =G9+G14 -> 23464.61 | H18: =H9+H14 -> 25713.84 | I18: =I9+I14 -> 32755.75 | J18: =J9+J14 -> 22480.13 | K18: =K9+K14 -> 0 | L18: =L9+L14 -> 0 | M18: =M9+M14 -> 0 | N18: =SUM(B18:M18) -> 120227.04
A19: Acomodation + CT | F19: =F16+F18 -> 16478.709 | G19: =G16+G18 -> 24680.61 | H19: =H16+H18 -> 26943.84 | I19: =I16+I18 -> 33915.75 | J19: =J16+J18 -> 23662.13 | K19: =K16+K18 -> 0 | L19: =L16+L18 -> 0 | M19: =M16+M18 -> 0 | N19: =N16+N18 -> 125681.04
A20: Lastyear(planilha2025) | E20: 5662.45 | F20: 17227.5 | G20: 19341.4 | H20: 29382.36 | I20: 38978.5 | J20: 29857.66 | K20: 21511.08 | L20: 0 | M20: 0 | N20: =SUM(B20:M20) -> 161960.95
A21: %comparação | E21: =(E18-E20)/E20 -> -1 | F21: =(F18-F20)/F20 -> -0.082123995 | G21: =(G18-G20)/G20 -> 0.21318054 | H21: =(H18-H20)/H20 -> -0.1248545 | I21: =(I18-I20)/I20 -> -0.1596457 | J21: =(J18-J20)/J20 -> -0.24709003 | K21: =(K18-K20)/K20 -> -1 | N21: =AVERAGE(D21:K21) -> -0.34293338
A23: Number of Guest cloudbed | F23: 177 | G23: 286 | H23: 295 | I23: 254 | J23: 372
A24: Number of Beds | F24: 391 | G24: 619 | H24: 515 | I24: 607 | J24: 754
A25: FF | C25: =SUMIFS(FF!$M:$M,FF!$C:$C,C4) -> 0 | D25: =SUMIFS(FF!$M:$M,FF!$C:$C,D4) -> 0 | E25: =SUMIFS(FF!$M:$M,FF!$C:$C,E4) -> 0 | F25: =SUMIFS(FF!$M:$M,FF!$C:$C,F4) -> 34 | G25: =SUMIFS(FF!$M:$M,FF!$C:$C,G4) -> 57 | H25: =SUMIFS(FF!$M:$M,FF!$C:$C,H4) -> 76 | I25: =SUMIFS(FF!$M:$M,FF!$C:$C,I4) -> 138 | J25: =SUMIFS(FF!$M:$M,FF!$C:$C,J4) -> 27 | ... M25: =SUMIFS(FF!$M:$M,FF!$C:$C,M4) -> 0
A26: Number of Beds Total | C26: =C24+C25 -> 0 | D26: =D24+D25 -> 0 | E26: =E24+E25 -> 0 | F26: =F24+F25 -> 425 | G26: =G24+G25 -> 676 | H26: =H24+H25 -> 591 | I26: =I24+I25 -> 745 | J26: =J24+J25 -> 781 | ... M26: =M24+M25 -> 0
A27: Occupancy Rate | F27: =F26/732 -> 0.58060109 | G27: =G26/732 -> 0.92349727 | H27: =H26/732 -> 0.80737705 | I27: =I26/732 -> 1.0177596 | J27: =J26/732 -> 1.0669399 | K27: =K26/732 -> 0 | L27: =L26/732 -> 0 | M27: =M26/732 -> 0
A28: Last Year | E28: 0.35101254 | F28: 0.81581485 | G28: 0.87753134 | H28: 0.9057377 | I28: 1.0177596 | J28: 0.97404372 | K28: 0.84153005
A29: %comparação | F29: =F27-F28 -> -0.23521376 | G29: =G27-G28 -> 0.045965927 | H29: =H27-H28 -> -0.098360656 | I29: =I27-I28 -> 0 | J29: =J27-J28 -> 0.092896175
A31: Average Price | F31: 37.9 | G31: 34.19 | H31: 34.55 | I31: 43.63 | J31: 33.54
A32: FF | F32: =AVERAGEIFS(FF!$N:$N,FF!$C:$C,F4) -> 43.718426 | G32: =AVERAGEIFS(FF!$N:$N,FF!$C:$C,G4) -> 36.536765 | H32: =AVERAGEIFS(FF!$N:$N,FF!$C:$C,H4) -> 35.645833 | I32: =AVERAGEIFS(FF!$N:$N,FF!$C:$C,I4) -> 41.61386 | J32: =AVERAGEIFS(FF!$N:$N,FF!$C:$C,J4) -> 34.1554 | K32: =AVERAGEIFS(FF!$N:$N,FF!$C:$C,K4) -> #DIV/0! | L32: =AVERAGEIFS(FF!$N:$N,FF!$C:$C,L4) -> #DIV/0! | M32: =AVERAGEIFS(FF!$N:$N,FF!$C:$C,M4) -> #DIV/0!
A33: Average Price Total | F33: =AVERAGE(F31:F32) -> 40.809213 | G33: =AVERAGE(G31:G32) -> 35.363382 | H33: =AVERAGE(H31:H32) -> 35.097917 | I33: =AVERAGE(I31:I32) -> 42.62193 | J33: =AVERAGE(J31:J32) -> 33.8477 | K33: =AVERAGE(K31:K32) -> #DIV/0! | L33: =AVERAGE(L31:L32) -> #DIV/0! | M33: =AVERAGE(M31:M32) -> #DIV/0!
A34: Last Year | E34: 31.112363 | F34: 39.391253 | G34: 40.763516 | H34: 42.786365 | I34: 51.269128 | J34: 40.209902 | K34: 33.186088
A35: %comparação | F35: =F31/F34 -> 0.96214254 | G35: =G31/G34 -> 0.8387402 | H35: =H31/H34 -> 0.80750024 | I35: =I31/I34 -> 0.85099946 | J35: =J31/J34 -> 0.8341229 | K35: =K31/K34 -> 0 | L35: =L31/L34 -> #DIV/0! | M35: =M31/M34 -> #DIV/0!
A37: Bed Cost by nights | F37: ='Final Result'!F20/F24 -> 25.609898 | G37: ='Final Result'!G20/G24 -> 23.19643 | H37: ='Final Result'!H20/H24 -> 25.02934 | I37: ='Final Result'!I20/I24 -> 26.779259 | J37: ='Final Result'!J20/J24 -> 15.572812 | K37: ='Final Result'!K20/K24 -> #DIV/0! | L37: ='Final Result'!L20/L24 -> #DIV/0! | M37: ='Final Result'!M20/M24 -> #DIV/0!
A38: Last Year | E38: 22.824894 | F38: 19.62553 | G38: 24.827332 | H38: 25.706003 | I38: 22.821302 | J38: 19.086553 | K38: 20.938889
A39: %comparação | F39: =F37/F38 -> 1.3049277 | G39: =G37/G38 -> 0.93431019 | H39: =H37/H38 -> 0.97367684
A41: Bed Cost if full | E41: ='Final Result'!E20/(24*30.5) -> 2.5428142 | F41: ='Final Result'!F20/(24*30.5) -> 13.679604 | G41: ='Final Result'!G20/(24*30.5) -> 19.61556 | H41: ='Final Result'!H20/(24*30.5) -> 17.60944 | I41: ='Final Result'!I20/(24*30.5) -> 22.206298 | J41: ='Final Result'!J20/(24*30.5) -> 16.040847 | K41: ='Final Result'!K20/(24*30.5) -> 0 | L41: ='Final Result'!L20/(24*30.5) -> 0 | M41: ='Final Result'!M20/(24*30.5) -> 0
A42: Last Year | E42: 8.0118238 | F42: 16.010799 | G42: 21.786762 | H42: 23.282896 | I42: 23.226598 | J42: 18.591137 | K42: 17.620705 | L42: 10.454495 | M42: 9.632582 | N42: 13.302401
A43: %comparação | F43: =F41/F42 -> 0.85439856 | G43: =G41/G42 -> 0.90034305 | H43: =H41/H42 -> 0.75632515 | I43: =I41/I42 -> 0.95607189 | J43: =J41/J42 -> 0.86282229 | K43: =K41/K42 -> 0 | L43: =L41/L42 -> 0 | M43: =M41/M42 -> 0

Sheet Receptor by pay
A1: Receptor
A3: Ano | B3: 2025 | C3: 2025 | D3: 2025 | E3: 2025 | F3: 2025 | G3: 2025 | H3: 2025 | I3: 2025 | J3: 2025 | K3: 2025 | L3: 2025 | M3: 2025 | N3: 2025
A4: By Payment/ No commission | B4: 1 | C4: 2 | D4: 3 | E4: 4 | F4: 5 | G4: 6 | H4: 7 | I4: 8 | J4: 9 | K4: 10 | L4: 11 | M4: 12 | N4: TOTAL
A5: Booking | F5: =sumifs(CloudBed!$V:$V,CloudBed!$K:$K,$A$5,CloudBed!$Y:$Y,F4) -> 0 | G5: =sumifs(CloudBed!$V:$V,CloudBed!$K:$K,$A$5,CloudBed!$Y:$Y,G4) -> 6419.64 | H5: =sumifs(CloudBed!$V:$V,CloudBed!$K:$K,$A$5,CloudBed!$Y:$Y,H4) -> 8072.45 | I5: =sumifs(CloudBed!$V:$V,CloudBed!$K:$K,$A$5,CloudBed!$Y:$Y,I4) -> 8751.41 | J5: =sumifs(CloudBed!$V:$V,CloudBed!$K:$K,$A$5,CloudBed!$Y:$Y,J4) -> 11805.35 | K5: =sumifs(CloudBed!$V:$V,CloudBed!$K:$K,$A$5,CloudBed!$Y:$Y,K4) -> 10922.64 | L5: =sumifs(CloudBed!$V:$V,CloudBed!$K:$K,$A$5,CloudBed!$Y:$Y,L4) -> 0 | M5: =sumifs(CloudBed!$V:$V,CloudBed!$K:$K,$A$5,CloudBed!$Y:$Y,M4) -> 0 | N5: =SUM(B5:M5) -> 45971.49
A6: HW | F6: =sumifs(CloudBed!$V:$V,CloudBed!$K:$K,$A$6,CloudBed!$Y:$Y,F4) -> 2470.5 | G6: =sumifs(CloudBed!$V:$V,CloudBed!$K:$K,$A$6,CloudBed!$Y:$Y,G4) -> 5610 | H6: =sumifs(CloudBed!$V:$V,CloudBed!$K:$K,$A$6,CloudBed!$Y:$Y,H4) -> 7634.7 | I6: =sumifs(CloudBed!$V:$V,CloudBed!$K:$K,$A$6,CloudBed!$Y:$Y,I4) -> 8780.5 | J6: =sumifs(CloudBed!$V:$V,CloudBed!$K:$K,$A$6,CloudBed!$Y:$Y,J4) -> 5962.2 | K6: =sumifs(CloudBed!$V:$V,CloudBed!$K:$K,$A$6,CloudBed!$Y:$Y,K4) -> 0 | L6: =sumifs(CloudBed!$V:$V,CloudBed!$K:$K,$A$6,CloudBed!$Y:$Y,L4) -> 0 | M6: =sumifs(CloudBed!$V:$V,CloudBed!$K:$K,$A$6,CloudBed!$Y:$Y,M4) -> 0 | N6: =SUM(B6:M6) -> 30457.9
A7: Airbnb | F7: =sumifs(CloudBed!$V:$V,CloudBed!$K:$K,"Airbnb",CloudBed!$Y:$Y,F4) -> 4244.3589 | G7: =sumifs(CloudBed!$V:$V,CloudBed!$K:$K,"Airbnb",CloudBed!$Y:$Y,G4) -> 7211.42 | H7: =sumifs(CloudBed!$V:$V,CloudBed!$K:$K,"Airbnb",CloudBed!$Y:$Y,H4) -> 5127.72 | I7: =sumifs(CloudBed!$V:$V,CloudBed!$K:$K,"Airbnb",CloudBed!$Y:$Y,I4) -> 7285.24 | J7: =sumifs(CloudBed!$V:$V,CloudBed!$K:$K,"Airbnb",CloudBed!$Y:$Y,J4) -> 4363.53 | K7: =sumifs(CloudBed!$V:$V,CloudBed!$K:$K,"Airbnb",CloudBed!$Y:$Y,K4) -> 0 | L7: =sumifs(CloudBed!$V:$V,CloudBed!$K:$K,"Airbnb",CloudBed!$Y:$Y,L4) -> 0 | M7: =sumifs(CloudBed!$V:$V,CloudBed!$K:$K,"Airbnb",CloudBed!$Y:$Y,M4) -> 0 | N7: =SUM(B7:M7) -> 28232.269
A8: Website | F8: =sumifs(CloudBed!$V:$V,CloudBed!$K:$K,"*Website*",CloudBed!$Y:$Y,F4) -> 0 | G8: =sumifs(CloudBed!$V:$V,CloudBed!$K:$K,"*Website*",CloudBed!$Y:$Y,G4) -> 450 | H8: =sumifs(CloudBed!$V:$V,CloudBed!$K:$K,"*Website*",CloudBed!$Y:$Y,H4) -> 257.76 | I8: =sumifs(CloudBed!$V:$V,CloudBed!$K:$K,"*Website*",CloudBed!$Y:$Y,I4) -> 42.53 | J8: =sumifs(CloudBed!$V:$V,CloudBed!$K:$K,"*Website*",CloudBed!$Y:$Y,J4) -> 57.94 | N8: =SUM(B8:M8) -> 808.23
A9: TotalOTA | B9: =SUM(B5:B8) -> 0 | C9: =SUM(C5:C8) -> 0 | D9: =SUM(D5:D8) -> 0 | E9: =SUM(E5:E8) -> 0 | F9: =SUM(F5:F8) -> 6714.8589 | G9: =SUM(G5:G8) -> 19691.06 | H9: =SUM(H5:H8) -> 21092.63 | I9: =SUM(I5:I8) -> 24859.68 | ... M9: =SUM(M5:M8) -> 0 | N9: =SUM(B9:M9) -> 105469.89
A10: Walk-In | F10: =sumifs(CloudBed!$V:$V,CloudBed!$K:$K,"Walk-In",CloudBed!$Y:$Y,F4) -> 0 | G10: =sumifs(CloudBed!$V:$V,CloudBed!$K:$K,"Walk-In",CloudBed!$Y:$Y,G4) -> 32 | H10: =sumifs(CloudBed!$V:$V,CloudBed!$K:$K,"Walk-In",CloudBed!$Y:$Y,H4) -> 0 | I10: =sumifs(CloudBed!$V:$V,CloudBed!$K:$K,"Walk-In",CloudBed!$Y:$Y,I4) -> 0 | N10: =SUM(B10:M10) -> 32
A11: Friends & Family | F11: =sumifs(CloudBed!$V:$V,CloudBed!$K:$K,$A$11,CloudBed!$Y:$Y,F4) -> 0 | G11: =sumifs(CloudBed!$V:$V,CloudBed!$K:$K,$A$11,CloudBed!$Y:$Y,G4) -> 214.5 | H11: =sumifs(CloudBed!$V:$V,CloudBed!$K:$K,$A$11,CloudBed!$Y:$Y,H4) -> 220 | I11: =sumifs(CloudBed!$V:$V,CloudBed!$K:$K,$A$11,CloudBed!$Y:$Y,I4) -> 0 | J11: =sumifs(CloudBed!$V:$V,CloudBed!$K:$K,$A$11,CloudBed!$Y:$Y,J4) -> 0 | K11: =sumifs(FF!$X:$X,FF!$C:$C,K4) -> 0 | L11: =sumifs(FF!$X:$X,FF!$C:$C,L4) -> 0 | M11: =sumifs(FF!$X:$X,FF!$C:$C,M4) -> 0 | N11: =SUM(B11:M11) -> 434.5
A12: Friends & Family from the paper | F12: =sumifs(FF!$E:$E,FF!$C:$C,F4) -> 1331 | G12: =sumifs(FF!$E:$E,FF!$C:$C,G4) -> 2027 | H12: =sumifs(FF!$E:$E,FF!$C:$C,H4) -> 2825 | I12: =sumifs(FF!$E:$E,FF!$C:$C,I4) -> 5989.66 | J12: =sumifs(FF!$E:$E,FF!$C:$C,J4) -> 2117.99 | K12: =sumifs(FF!$E:$E,FF!$C:$C,K4) -> 0 | L12: =sumifs(FF!$E:$E,FF!$C:$C,L4) -> 0 | M12: =sumifs(FF!$E:$E,FF!$C:$C,M4) -> 0
A13: Friends & Family | F13: =F11+F12 -> 1331 | G13: =G11+G12 -> 2241.5 | H13: =H11+H12 -> 3045 | I13: =I11+I12 -> 5989.66 | J13: =J11+J12 -> 2117.99 | K13: =K11+K12 -> 0 | L13: =L11+L12 -> 0 | M13: =M11+M12 -> 0 | N13: =SUM(B13:M13) -> 14725.15
A14: TotalWalk | B14: =SUM(B10:B12) -> 0 | C14: =SUM(C10:C12) -> 0 | D14: =SUM(D10:D12) -> 0 | E14: =SUM(E10:E12) -> 0 | F14: =F10+F13 -> 1331 | G14: =G10+G13 -> 2273.5 | H14: =H10+H13 -> 3045 | I14: =I10+I13 -> 5989.66 | J14: =J10+J13 -> 2117.99 | K14: =K10+K13 -> 0 | L14: =L10+L13 -> 0 | M14: =M10+M13 -> 0 | N14: =SUM(B14:M14) -> 14757.15
A16: CityTax | F16: =sumifs(CloudBed!$P:$P,CloudBed!$Y:$Y,F4) -> 260 | G16: =sumifs(CloudBed!$P:$P,CloudBed!$Y:$Y,G4) -> 1094 | H16: =sumifs(CloudBed!$P:$P,CloudBed!$Y:$Y,H4) -> 1156 | I16: =sumifs(CloudBed!$P:$P,CloudBed!$Y:$Y,I4) -> 1176 | J16: =sumifs(CloudBed!$P:$P,CloudBed!$Y:$Y,J4) -> 1142 | K16: =sumifs(CloudBed!$P:$P,CloudBed!$Y:$Y,K4) -> 626 | L16: =sumifs(CloudBed!$P:$P,CloudBed!$Y:$Y,L4) -> 0 | M16: =sumifs(CloudBed!$P:$P,CloudBed!$Y:$Y,M4) -> 0 | N16: =SUM(B16:M16) -> 5454
A17: Total com CT | E17: =Receptor!E9+Receptor!E14 -> 0 | F17: =F9+F14+F16 -> 8305.8589 | G17: =G9+G14+G16 -> 23058.56 | H17: =H9+H14+H16 -> 25293.63 | I17: =I9+I14+I16 -> 32025.34 | J17: =J9+J14+J16 -> 25449.01 | K17: =K9+K14+K16 -> 11548.64 | L17: =L9+L14+L16 -> 0 | M17: =M9+M14+M16 -> 0 | N17: =N9+N14+N16 -> 125681.04
A18: Receptor by event | F18: =Receptor!F9+Receptor!F14+Receptor!F16 -> 16478.709 | G18: =Receptor!G9+Receptor!G14+Receptor!G16 -> 24680.61 | H18: =Receptor!H9+Receptor!H14+Receptor!H16 -> 26943.84 | I18: =Receptor!I9+Receptor!I14+Receptor!I16 -> 33915.75 | J18: =Receptor!J9+Receptor!J14+Receptor!J16 -> 23662.13 | K18: =Receptor!K9+Receptor!K14+Receptor!K16 -> 0 | L18: =Receptor!L9+Receptor!L14+Receptor!L16 -> 0 | M18: =Receptor!M9+Receptor!M14+Receptor!M16 -> 0 | N18: =Receptor!N9+Receptor!N14+Receptor!N16 -> 125681.04
A19: Diferença | F19: =F17-F18 -> -8172.85 | G19: =G17-G18 -> -1622.05 | H19: =H17-H18 -> -1650.21 | I19: =I17-I18 -> -1890.41 | J19: =J17-J18 -> 1786.88 | K19: =K17-K18 -> 11548.64 | L19: =L17-L18 -> 0 | M19: =M17-M18 -> 0 | N19: =N17-N18 -> 0

Sheet Analysis OUT by pay
D1: 2026
A2: PELA DATA DO PAGAMENTO
A3: CATEGORIA | B3: PRODUTO | D3: TOTAL2026 | E3: Jan | F3: Fev | G3: Mar | H3: Apr | I3: May | J3: Jun | K3: Jul | L3: Aug | M3: Sep | N3: Oct | O3: Nov | P3: Dez
D4: TOTAL | E4: 1 | F4: 2 | G4: 3 | H4: 4 | I4: 5 | J4: 6 | K4: 7 | L4: 8 | M4: 9 | N4: 10 | O4: 11 | P4: 12
B5: Aqua Lab Water Test | D5: =SUM(E5:P5) -> 435.86 | E5: =sumifs(Dados!$N:$N,Dados!$B:$B,B5,Dados!$H:$H,$D$1,Dados!$G:$G,$E$4) -> 0 | F5: =sumifs(Dados!$N:$N,Dados!$B:$B,B5,Dados!$H:$H,$D$1,Dados!$G:$G,$F$4) -> 0 | G5: =sumifs(Dados!$N:$N,Dados!$B:$B,B5,Dados!$H:$H,$D$1,Dados!$G:$G,$G$4) -> 0 | H5: =sumifs(Dados!$N:$N,Dados!$B:$B,B5,Dados!$H:$H,$D$1,Dados!$G:$G,$H$4) -> 0 | I5: =sumifs(Dados!$N:$N,Dados!$B:$B,B5,Dados!$H:$H,$D$1,Dados!$G:$G,$I$4) -> 0 | J5: =sumifs(Dados!$N:$N,Dados!$B:$B,B5,Dados!$H:$H,$D$1,Dados!$G:$G,$J$4) -> 435.86 | K5: =sumifs(Dados!$N:$N,Dados!$B:$B,B5,Dados!$H:$H,$D$1,Dados!$G:$G,$K$4) -> 0 | L5: =sumifs(Dados!$N:$N,Dados!$B:$B,B5,Dados!$H:$H,$D$1,Dados!$G:$G,$L$4) -> 0 | M5: =sumifs(Dados!$N:$N,Dados!$B:$B,B5,Dados!$H:$H,$D$1,Dados!$G:$G,$M$4) -> 0 | N5: =sumifs(Dados!$N:$N,Dados!$B:$B,B5,Dados!$H:$H,$D$1,Dados!$G:$G,$N$4) -> 0 | O5: =sumifs(Dados!$N:$N,Dados!$B:$B,B5,Dados!$H:$H,$D$1,Dados!$G:$G,$O$4) -> 0 | P5: =sumifs(Dados!$N:$N,Dados!$B:$B,B5,Dados!$H:$H,$D$1,Dados!$G:$G,$P$4) -> 0
B6: Gas inspection | D6: =SUM(E6:P6) -> 0 | E6: =sumifs(Dados!$N:$N,Dados!$B:$B,B6,Dados!$H:$H,$D$1,Dados!$G:$G,$E$4) -> 0 | F6: =sumifs(Dados!$N:$N,Dados!$B:$B,B6,Dados!$H:$H,$D$1,Dados!$G:$G,$F$4) -> 0 | G6: =sumifs(Dados!$N:$N,Dados!$B:$B,B6,Dados!$H:$H,$D$1,Dados!$G:$G,$G$4) -> 0 | H6: =sumifs(Dados!$N:$N,Dados!$B:$B,B6,Dados!$H:$H,$D$1,Dados!$G:$G,$H$4) -> 0 | I6: =sumifs(Dados!$N:$N,Dados!$B:$B,B6,Dados!$H:$H,$D$1,Dados!$G:$G,$I$4) -> 0 | J6: =sumifs(Dados!$N:$N,Dados!$B:$B,B6,Dados!$H:$H,$D$1,Dados!$G:$G,$J$4) -> 0 | K6: =sumifs(Dados!$N:$N,Dados!$B:$B,B6,Dados!$H:$H,$D$1,Dados!$G:$G,$K$4) -> 0 | L6: =sumifs(Dados!$N:$N,Dados!$B:$B,B6,Dados!$H:$H,$D$1,Dados!$G:$G,$L$4) -> 0 | M6: =sumifs(Dados!$N:$N,Dados!$B:$B,B6,Dados!$H:$H,$D$1,Dados!$G:$G,$M$4) -> 0 | N6: =sumifs(Dados!$N:$N,Dados!$B:$B,B6,Dados!$H:$H,$D$1,Dados!$G:$G,$N$4) -> 0 | O6: =sumifs(Dados!$N:$N,Dados!$B:$B,B6,Dados!$H:$H,$D$1,Dados!$G:$G,$O$4) -> 0 | P6: =sumifs(Dados!$N:$N,Dados!$B:$B,B6,Dados!$H:$H,$D$1,Dados!$G:$G,$P$4) -> 0
B7: INTERPREV-Fiscalisacao | D7: =SUM(E7:P7) -> 285.85 | E7: =sumifs(Dados!$N:$N,Dados!$B:$B,B7,Dados!$H:$H,$D$1,Dados!$G:$G,$E$4) -> 0 | F7: =sumifs(Dados!$N:$N,Dados!$B:$B,B7,Dados!$H:$H,$D$1,Dados!$G:$G,$F$4) -> 0 | G7: =sumifs(Dados!$N:$N,Dados!$B:$B,B7,Dados!$H:$H,$D$1,Dados!$G:$G,$G$4) -> 0 | H7: =sumifs(Dados!$N:$N,Dados!$B:$B,B7,Dados!$H:$H,$D$1,Dados!$G:$G,$H$4) -> 0 | I7: =sumifs(Dados!$N:$N,Dados!$B:$B,B7,Dados!$H:$H,$D$1,Dados!$G:$G,$I$4) -> 0 | J7: =sumifs(Dados!$N:$N,Dados!$B:$B,B7,Dados!$H:$H,$D$1,Dados!$G:$G,$J$4) -> 285.85 | K7: =sumifs(Dados!$N:$N,Dados!$B:$B,B7,Dados!$H:$H,$D$1,Dados!$G:$G,$K$4) -> 0 | L7: =sumifs(Dados!$N:$N,Dados!$B:$B,B7,Dados!$H:$H,$D$1,Dados!$G:$G,$L$4) -> 0 | M7: =sumifs(Dados!$N:$N,Dados!$B:$B,B7,Dados!$H:$H,$D$1,Dados!$G:$G,$M$4) -> 0 | N7: =sumifs(Dados!$N:$N,Dados!$B:$B,B7,Dados!$H:$H,$D$1,Dados!$G:$G,$N$4) -> 0 | O7: =sumifs(Dados!$N:$N,Dados!$B:$B,B7,Dados!$H:$H,$D$1,Dados!$G:$G,$O$4) -> 0 | P7: =sumifs(Dados!$N:$N,Dados!$B:$B,B7,Dados!$H:$H,$D$1,Dados!$G:$G,$P$4) -> 0
B8: INTERPREV-Segurancaesaude | D8: =SUM(E8:P8) -> 0 | E8: =sumifs(Dados!$N:$N,Dados!$B:$B,B8,Dados!$H:$H,$D$1,Dados!$G:$G,$E$4) -> 0 | F8: =sumifs(Dados!$N:$N,Dados!$B:$B,B8,Dados!$H:$H,$D$1,Dados!$G:$G,$F$4) -> 0 | G8: =sumifs(Dados!$N:$N,Dados!$B:$B,B8,Dados!$H:$H,$D$1,Dados!$G:$G,$G$4) -> 0 | H8: =sumifs(Dados!$N:$N,Dados!$B:$B,B8,Dados!$H:$H,$D$1,Dados!$G:$G,$H$4) -> 0 | I8: =sumifs(Dados!$N:$N,Dados!$B:$B,B8,Dados!$H:$H,$D$1,Dados!$G:$G,$I$4) -> 0 | J8: =sumifs(Dados!$N:$N,Dados!$B:$B,B8,Dados!$H:$H,$D$1,Dados!$G:$G,$J$4) -> 0 | K8: =sumifs(Dados!$N:$N,Dados!$B:$B,B8,Dados!$H:$H,$D$1,Dados!$G:$G,$K$4) -> 0 | L8: =sumifs(Dados!$N:$N,Dados!$B:$B,B8,Dados!$H:$H,$D$1,Dados!$G:$G,$L$4) -> 0 | M8: =sumifs(Dados!$N:$N,Dados!$B:$B,B8,Dados!$H:$H,$D$1,Dados!$G:$G,$M$4) -> 0 | N8: =sumifs(Dados!$N:$N,Dados!$B:$B,B8,Dados!$H:$H,$D$1,Dados!$G:$G,$N$4) -> 0 | O8: =sumifs(Dados!$N:$N,Dados!$B:$B,B8,Dados!$H:$H,$D$1,Dados!$G:$G,$O$4) -> 0 | P8: =sumifs(Dados!$N:$N,Dados!$B:$B,B8,Dados!$H:$H,$D$1,Dados!$G:$G,$P$4) -> 0
B9: License | D9: =SUM(E9:P9) -> 0 | E9: =sumifs(Dados!$N:$N,Dados!$B:$B,B9,Dados!$H:$H,$D$1,Dados!$G:$G,$E$4) -> 0 | F9: =sumifs(Dados!$N:$N,Dados!$B:$B,B9,Dados!$H:$H,$D$1,Dados!$G:$G,$F$4) -> 0 | G9: =sumifs(Dados!$N:$N,Dados!$B:$B,B9,Dados!$H:$H,$D$1,Dados!$G:$G,$G$4) -> 0 | H9: =sumifs(Dados!$N:$N,Dados!$B:$B,B9,Dados!$H:$H,$D$1,Dados!$G:$G,$H$4) -> 0 | I9: =sumifs(Dados!$N:$N,Dados!$B:$B,B9,Dados!$H:$H,$D$1,Dados!$G:$G,$I$4) -> 0 | J9: =sumifs(Dados!$N:$N,Dados!$B:$B,B9,Dados!$H:$H,$D$1,Dados!$G:$G,$J$4) -> 0 | K9: =sumifs(Dados!$N:$N,Dados!$B:$B,B9,Dados!$H:$H,$D$1,Dados!$G:$G,$K$4) -> 0 | L9: =sumifs(Dados!$N:$N,Dados!$B:$B,B9,Dados!$H:$H,$D$1,Dados!$G:$G,$L$4) -> 0 | M9: =sumifs(Dados!$N:$N,Dados!$B:$B,B9,Dados!$H:$H,$D$1,Dados!$G:$G,$M$4) -> 0 | N9: =sumifs(Dados!$N:$N,Dados!$B:$B,B9,Dados!$H:$H,$D$1,Dados!$G:$G,$N$4) -> 0 | O9: =sumifs(Dados!$N:$N,Dados!$B:$B,B9,Dados!$H:$H,$D$1,Dados!$G:$G,$O$4) -> 0 | P9: =sumifs(Dados!$N:$N,Dados!$B:$B,B9,Dados!$H:$H,$D$1,Dados!$G:$G,$P$4) -> 0
B10: SOPFOGO-Extinctores | D10: =SUM(E10:P10) -> 0 | E10: =sumifs(Dados!$N:$N,Dados!$B:$B,B10,Dados!$H:$H,$D$1,Dados!$G:$G,$E$4) -> 0 | F10: =sumifs(Dados!$N:$N,Dados!$B:$B,B10,Dados!$H:$H,$D$1,Dados!$G:$G,$F$4) -> 0 | G10: =sumifs(Dados!$N:$N,Dados!$B:$B,B10,Dados!$H:$H,$D$1,Dados!$G:$G,$G$4) -> 0 | H10: =sumifs(Dados!$N:$N,Dados!$B:$B,B10,Dados!$H:$H,$D$1,Dados!$G:$G,$H$4) -> 0 | I10: =sumifs(Dados!$N:$N,Dados!$B:$B,B10,Dados!$H:$H,$D$1,Dados!$G:$G,$I$4) -> 0 | J10: =sumifs(Dados!$N:$N,Dados!$B:$B,B10,Dados!$H:$H,$D$1,Dados!$G:$G,$J$4) -> 0 | K10: =sumifs(Dados!$N:$N,Dados!$B:$B,B10,Dados!$H:$H,$D$1,Dados!$G:$G,$K$4) -> 0 | L10: =sumifs(Dados!$N:$N,Dados!$B:$B,B10,Dados!$H:$H,$D$1,Dados!$G:$G,$L$4) -> 0 | M10: =sumifs(Dados!$N:$N,Dados!$B:$B,B10,Dados!$H:$H,$D$1,Dados!$G:$G,$M$4) -> 0 | N10: =sumifs(Dados!$N:$N,Dados!$B:$B,B10,Dados!$H:$H,$D$1,Dados!$G:$G,$N$4) -> 0 | O10: =sumifs(Dados!$N:$N,Dados!$B:$B,B10,Dados!$H:$H,$D$1,Dados!$G:$G,$O$4) -> 0 | P10: =sumifs(Dados!$N:$N,Dados!$B:$B,B10,Dados!$H:$H,$D$1,Dados!$G:$G,$P$4) -> 0
B11: SOPFOGO-Manutencao Central Incendio | D11: =SUM(E11:P11) -> 0 | E11: =sumifs(Dados!$N:$N,Dados!$B:$B,B11,Dados!$H:$H,$D$1,Dados!$G:$G,$E$4) -> 0 | F11: =sumifs(Dados!$N:$N,Dados!$B:$B,B11,Dados!$H:$H,$D$1,Dados!$G:$G,$F$4) -> 0 | G11: =sumifs(Dados!$N:$N,Dados!$B:$B,B11,Dados!$H:$H,$D$1,Dados!$G:$G,$G$4) -> 0 | H11: =sumifs(Dados!$N:$N,Dados!$B:$B,B11,Dados!$H:$H,$D$1,Dados!$G:$G,$H$4) -> 0 | I11: =sumifs(Dados!$N:$N,Dados!$B:$B,B11,Dados!$H:$H,$D$1,Dados!$G:$G,$I$4) -> 0 | J11: =sumifs(Dados!$N:$N,Dados!$B:$B,B11,Dados!$H:$H,$D$1,Dados!$G:$G,$J$4) -> 0 | K11: =sumifs(Dados!$N:$N,Dados!$B:$B,B11,Dados!$H:$H,$D$1,Dados!$G:$G,$K$4) -> 0 | L11: =sumifs(Dados!$N:$N,Dados!$B:$B,B11,Dados!$H:$H,$D$1,Dados!$G:$G,$L$4) -> 0 | M11: =sumifs(Dados!$N:$N,Dados!$B:$B,B11,Dados!$H:$H,$D$1,Dados!$G:$G,$M$4) -> 0 | N11: =sumifs(Dados!$N:$N,Dados!$B:$B,B11,Dados!$H:$H,$D$1,Dados!$G:$G,$N$4) -> 0 | O11: =sumifs(Dados!$N:$N,Dados!$B:$B,B11,Dados!$H:$H,$D$1,Dados!$G:$G,$O$4) -> 0 | P11: =sumifs(Dados!$N:$N,Dados!$B:$B,B11,Dados!$H:$H,$D$1,Dados!$G:$G,$P$4) -> 0
B12: SPA | D12: =SUM(E12:P12) -> 0 | E12: =sumifs(Dados!$N:$N,Dados!$B:$B,B12,Dados!$H:$H,$D$1,Dados!$G:$G,$E$4) -> 0 | F12: =sumifs(Dados!$N:$N,Dados!$B:$B,B12,Dados!$H:$H,$D$1,Dados!$G:$G,$F$4) -> 0 | G12: =sumifs(Dados!$N:$N,Dados!$B:$B,B12,Dados!$H:$H,$D$1,Dados!$G:$G,$G$4) -> 0 | H12: =sumifs(Dados!$N:$N,Dados!$B:$B,B12,Dados!$H:$H,$D$1,Dados!$G:$G,$H$4) -> 0 | I12: =sumifs(Dados!$N:$N,Dados!$B:$B,B12,Dados!$H:$H,$D$1,Dados!$G:$G,$I$4) -> 0 | J12: =sumifs(Dados!$N:$N,Dados!$B:$B,B12,Dados!$H:$H,$D$1,Dados!$G:$G,$J$4) -> 0 | K12: =sumifs(Dados!$N:$N,Dados!$B:$B,B12,Dados!$H:$H,$D$1,Dados!$G:$G,$K$4) -> 0 | L12: =sumifs(Dados!$N:$N,Dados!$B:$B,B12,Dados!$H:$H,$D$1,Dados!$G:$G,$L$4) -> 0 | M12: =sumifs(Dados!$N:$N,Dados!$B:$B,B12,Dados!$H:$H,$D$1,Dados!$G:$G,$M$4) -> 0 | N12: =sumifs(Dados!$N:$N,Dados!$B:$B,B12,Dados!$H:$H,$D$1,Dados!$G:$G,$N$4) -> 0 | O12: =sumifs(Dados!$N:$N,Dados!$B:$B,B12,Dados!$H:$H,$D$1,Dados!$G:$G,$O$4) -> 0 | P12: =sumifs(Dados!$N:$N,Dados!$B:$B,B12,Dados!$H:$H,$D$1,Dados!$G:$G,$P$4) -> 0
A13: Annualidad-Fixa | B13: =sumifs(Dados!$N:$N,Dados!$A:$A,A13,Dados!$H:$H,$D$1) -> 721.71 | C13: =B13-D13 -> 0 | D13: =SUM(D5:D12) -> 721.71 | E13: =SUM(E5:E12) -> 0 | F13: =SUM(F5:F12) -> 0 | G13: =SUM(G5:G12) -> 0 | H13: =SUM(H5:H12) -> 0 | I13: =SUM(I5:I12) -> 0 | J13: =SUM(J5:J12) -> 721.71 | K13: =SUM(K5:K12) -> 0 | ... P13: =SUM(P5:P12) -> 0
B14: Desinfection | D14: =SUM(E14:P14) -> 0 | E14: =sumifs(Dados!$N:$N,Dados!$B:$B,B14,Dados!$H:$H,$D$1,Dados!$G:$G,$E$4) -> 0 | F14: =sumifs(Dados!$N:$N,Dados!$B:$B,B14,Dados!$H:$H,$D$1,Dados!$G:$G,$F$4) -> 0 | G14: =sumifs(Dados!$N:$N,Dados!$B:$B,B14,Dados!$H:$H,$D$1,Dados!$G:$G,$G$4) -> 0 | H14: =sumifs(Dados!$N:$N,Dados!$B:$B,B14,Dados!$H:$H,$D$1,Dados!$G:$G,$H$4) -> 0 | I14: =sumifs(Dados!$N:$N,Dados!$B:$B,B14,Dados!$H:$H,$D$1,Dados!$G:$G,$I$4) -> 0 | J14: =sumifs(Dados!$N:$N,Dados!$B:$B,B14,Dados!$H:$H,$D$1,Dados!$G:$G,$J$4) -> 0 | K14: =sumifs(Dados!$N:$N,Dados!$B:$B,B14,Dados!$H:$H,$D$1,Dados!$G:$G,$K$4) -> 0 | L14: =sumifs(Dados!$N:$N,Dados!$B:$B,B14,Dados!$H:$H,$D$1,Dados!$G:$G,$L$4) -> 0 | M14: =sumifs(Dados!$N:$N,Dados!$B:$B,B14,Dados!$H:$H,$D$1,Dados!$G:$G,$M$4) -> 0 | N14: =sumifs(Dados!$N:$N,Dados!$B:$B,B14,Dados!$H:$H,$D$1,Dados!$G:$G,$N$4) -> 0 | O14: =sumifs(Dados!$N:$N,Dados!$B:$B,B14,Dados!$H:$H,$D$1,Dados!$G:$G,$O$4) -> 0 | P14: =sumifs(Dados!$N:$N,Dados!$B:$B,B14,Dados!$H:$H,$D$1,Dados!$G:$G,$P$4) -> 0
B15: Diverso – bed bug | D15: =SUM(E15:P15) -> 0 | E15: =sumifs(Dados!$N:$N,Dados!$B:$B,B15,Dados!$H:$H,$D$1,Dados!$G:$G,$E$4) -> 0 | F15: =sumifs(Dados!$N:$N,Dados!$B:$B,B15,Dados!$H:$H,$D$1,Dados!$G:$G,$F$4) -> 0 | G15: =sumifs(Dados!$N:$N,Dados!$B:$B,B15,Dados!$H:$H,$D$1,Dados!$G:$G,$G$4) -> 0 | H15: =sumifs(Dados!$N:$N,Dados!$B:$B,B15,Dados!$H:$H,$D$1,Dados!$G:$G,$H$4) -> 0 | I15: =sumifs(Dados!$N:$N,Dados!$B:$B,B15,Dados!$H:$H,$D$1,Dados!$G:$G,$I$4) -> 0 | J15: =sumifs(Dados!$N:$N,Dados!$B:$B,B15,Dados!$H:$H,$D$1,Dados!$G:$G,$J$4) -> 0 | K15: =sumifs(Dados!$N:$N,Dados!$B:$B,B15,Dados!$H:$H,$D$1,Dados!$G:$G,$K$4) -> 0 | L15: =sumifs(Dados!$N:$N,Dados!$B:$B,B15,Dados!$H:$H,$D$1,Dados!$G:$G,$L$4) -> 0 | M15: =sumifs(Dados!$N:$N,Dados!$B:$B,B15,Dados!$H:$H,$D$1,Dados!$G:$G,$M$4) -> 0 | N15: =sumifs(Dados!$N:$N,Dados!$B:$B,B15,Dados!$H:$H,$D$1,Dados!$G:$G,$N$4) -> 0 | O15: =sumifs(Dados!$N:$N,Dados!$B:$B,B15,Dados!$H:$H,$D$1,Dados!$G:$G,$O$4) -> 0 | P15: =sumifs(Dados!$N:$N,Dados!$B:$B,B15,Dados!$H:$H,$D$1,Dados!$G:$G,$P$4) -> 0
B16: laundry | D16: =SUM(E16:P16) -> 0 | E16: =sumifs(Dados!$N:$N,Dados!$B:$B,B16,Dados!$H:$H,$D$1,Dados!$G:$G,$E$4) -> 0 | F16: =sumifs(Dados!$N:$N,Dados!$B:$B,B16,Dados!$H:$H,$D$1,Dados!$G:$G,$F$4) -> 0 | G16: =sumifs(Dados!$N:$N,Dados!$B:$B,B16,Dados!$H:$H,$D$1,Dados!$G:$G,$G$4) -> 0 | H16: =sumifs(Dados!$N:$N,Dados!$B:$B,B16,Dados!$H:$H,$D$1,Dados!$G:$G,$H$4) -> 0 | I16: =sumifs(Dados!$N:$N,Dados!$B:$B,B16,Dados!$H:$H,$D$1,Dados!$G:$G,$I$4) -> 0 | J16: =sumifs(Dados!$N:$N,Dados!$B:$B,B16,Dados!$H:$H,$D$1,Dados!$G:$G,$J$4) -> 0 | K16: =sumifs(Dados!$N:$N,Dados!$B:$B,B16,Dados!$H:$H,$D$1,Dados!$G:$G,$K$4) -> 0 | L16: =sumifs(Dados!$N:$N,Dados!$B:$B,B16,Dados!$H:$H,$D$1,Dados!$G:$G,$L$4) -> 0 | M16: =sumifs(Dados!$N:$N,Dados!$B:$B,B16,Dados!$H:$H,$D$1,Dados!$G:$G,$M$4) -> 0 | N16: =sumifs(Dados!$N:$N,Dados!$B:$B,B16,Dados!$H:$H,$D$1,Dados!$G:$G,$N$4) -> 0 | O16: =sumifs(Dados!$N:$N,Dados!$B:$B,B16,Dados!$H:$H,$D$1,Dados!$G:$G,$O$4) -> 0 | P16: =sumifs(Dados!$N:$N,Dados!$B:$B,B16,Dados!$H:$H,$D$1,Dados!$G:$G,$P$4) -> 0
B17: Weapons | D17: =SUM(E17:P17) -> 0 | E17: =sumifs(Dados!$N:$N,Dados!$B:$B,B17,Dados!$H:$H,$D$1,Dados!$G:$G,$E$4) -> 0 | F17: =sumifs(Dados!$N:$N,Dados!$B:$B,B17,Dados!$H:$H,$D$1,Dados!$G:$G,$F$4) -> 0 | G17: =sumifs(Dados!$N:$N,Dados!$B:$B,B17,Dados!$H:$H,$D$1,Dados!$G:$G,$G$4) -> 0 | H17: =sumifs(Dados!$N:$N,Dados!$B:$B,B17,Dados!$H:$H,$D$1,Dados!$G:$G,$H$4) -> 0 | I17: =sumifs(Dados!$N:$N,Dados!$B:$B,B17,Dados!$H:$H,$D$1,Dados!$G:$G,$I$4) -> 0 | J17: =sumifs(Dados!$N:$N,Dados!$B:$B,B17,Dados!$H:$H,$D$1,Dados!$G:$G,$J$4) -> 0 | K17: =sumifs(Dados!$N:$N,Dados!$B:$B,B17,Dados!$H:$H,$D$1,Dados!$G:$G,$K$4) -> 0 | L17: =sumifs(Dados!$N:$N,Dados!$B:$B,B17,Dados!$H:$H,$D$1,Dados!$G:$G,$L$4) -> 0 | M17: =sumifs(Dados!$N:$N,Dados!$B:$B,B17,Dados!$H:$H,$D$1,Dados!$G:$G,$M$4) -> 0 | N17: =sumifs(Dados!$N:$N,Dados!$B:$B,B17,Dados!$H:$H,$D$1,Dados!$G:$G,$N$4) -> 0 | O17: =sumifs(Dados!$N:$N,Dados!$B:$B,B17,Dados!$H:$H,$D$1,Dados!$G:$G,$O$4) -> 0 | P17: =sumifs(Dados!$N:$N,Dados!$B:$B,B17,Dados!$H:$H,$D$1,Dados!$G:$G,$P$4) -> 0
A18: bedbugsprotocol | B18: =sumifs(Dados!$N:$N,Dados!$A:$A,A18,Dados!$H:$H,$D$1) -> 0 | C18: =B18-D18 -> 0 | D18: =SUM(D14:D17) -> 0 | E18: =SUM(E14:E17) -> 0 | F18: =SUM(F14:F17) -> 0 | G18: =SUM(G14:G17) -> 0 | H18: =SUM(H14:H17) -> 0 | I18: =SUM(I14:I17) -> 0 | J18: =SUM(J14:J17) -> 0 | K18: =SUM(K14:K17) -> 0 | ... P18: =SUM(P14:P17) -> 0
B25: Airbnb cancelation | D25: =SUM(E25:P25) -> 0 | E25: =sumifs(Dados!$N:$N,Dados!$B:$B,B25,Dados!$H:$H,$D$1,Dados!$G:$G,$E$4) -> 0 | F25: =sumifs(Dados!$N:$N,Dados!$B:$B,B25,Dados!$H:$H,$D$1,Dados!$G:$G,$F$4) -> 0 | G25: =sumifs(Dados!$N:$N,Dados!$B:$B,B25,Dados!$H:$H,$D$1,Dados!$G:$G,$G$4) -> 0 | H25: =sumifs(Dados!$N:$N,Dados!$B:$B,B25,Dados!$H:$H,$D$1,Dados!$G:$G,$H$4) -> 0 | I25: =sumifs(Dados!$N:$N,Dados!$B:$B,B25,Dados!$H:$H,$D$1,Dados!$G:$G,$I$4) -> 0 | J25: =sumifs(Dados!$N:$N,Dados!$B:$B,B25,Dados!$H:$H,$D$1,Dados!$G:$G,$J$4) -> 0 | K25: =sumifs(Dados!$N:$N,Dados!$B:$B,B25,Dados!$H:$H,$D$1,Dados!$G:$G,$K$4) -> 0 | L25: =sumifs(Dados!$N:$N,Dados!$B:$B,B25,Dados!$H:$H,$D$1,Dados!$G:$G,$L$4) -> 0 | M25: =sumifs(Dados!$N:$N,Dados!$B:$B,B25,Dados!$H:$H,$D$1,Dados!$G:$G,$M$4) -> 0 | N25: =sumifs(Dados!$N:$N,Dados!$B:$B,B25,Dados!$H:$H,$D$1,Dados!$G:$G,$N$4) -> 0 | O25: =sumifs(Dados!$N:$N,Dados!$B:$B,B25,Dados!$H:$H,$D$1,Dados!$G:$G,$O$4) -> 0 | P25: =sumifs(Dados!$N:$N,Dados!$B:$B,B25,Dados!$H:$H,$D$1,Dados!$G:$G,$P$4) -> 0
B26: Airbnb comission | D26: =SUM(E26:P26) -> 0 | E26: =sumifs(Dados!$N:$N,Dados!$B:$B,B26,Dados!$H:$H,$D$1,Dados!$G:$G,$E$4) -> 0 | F26: =sumifs(Dados!$N:$N,Dados!$B:$B,B26,Dados!$H:$H,$D$1,Dados!$G:$G,$F$4) -> 0 | G26: =sumifs(Dados!$N:$N,Dados!$B:$B,B26,Dados!$H:$H,$D$1,Dados!$G:$G,$G$4) -> 0 | H26: =sumifs(Dados!$N:$N,Dados!$B:$B,B26,Dados!$H:$H,$D$1,Dados!$G:$G,$H$4) -> 0 | I26: =sumifs(Dados!$N:$N,Dados!$B:$B,B26,Dados!$H:$H,$D$1,Dados!$G:$G,$I$4) -> 0 | J26: =sumifs(Dados!$N:$N,Dados!$B:$B,B26,Dados!$H:$H,$D$1,Dados!$G:$G,$J$4) -> 0 | K26: =sumifs(Dados!$N:$N,Dados!$B:$B,B26,Dados!$H:$H,$D$1,Dados!$G:$G,$K$4) -> 0 | L26: =sumifs(Dados!$N:$N,Dados!$B:$B,B26,Dados!$H:$H,$D$1,Dados!$G:$G,$L$4) -> 0 | M26: =sumifs(Dados!$N:$N,Dados!$B:$B,B26,Dados!$H:$H,$D$1,Dados!$G:$G,$M$4) -> 0 | N26: =sumifs(Dados!$N:$N,Dados!$B:$B,B26,Dados!$H:$H,$D$1,Dados!$G:$G,$N$4) -> 0 | O26: =sumifs(Dados!$N:$N,Dados!$B:$B,B26,Dados!$H:$H,$D$1,Dados!$G:$G,$O$4) -> 0 | P26: =sumifs(Dados!$N:$N,Dados!$B:$B,B26,Dados!$H:$H,$D$1,Dados!$G:$G,$P$4) -> 0
B27: Booking Other taxs | D27: =SUM(E27:P27) -> 0 | E27: =sumifs(Dados!$N:$N,Dados!$B:$B,$B$27,Dados!$H:$H,$D$1,Dados!$G:$G,E4) -> 0 | F27: =sumifs(Dados!$N:$N,Dados!$B:$B,$B$27,Dados!$H:$H,$D$1,Dados!$G:$G,F4) -> 0 | G27: =sumifs(Dados!$N:$N,Dados!$B:$B,$B$27,Dados!$H:$H,$D$1,Dados!$G:$G,G4) -> 0 | H27: =sumifs(Dados!$N:$N,Dados!$B:$B,$B$27,Dados!$H:$H,$D$1,Dados!$G:$G,H4) -> 0 | I27: =sumifs(Dados!$N:$N,Dados!$B:$B,$B$27,Dados!$H:$H,$D$1,Dados!$G:$G,I4) -> 0 | J27: =sumifs(Dados!$N:$N,Dados!$B:$B,$B$27,Dados!$H:$H,$D$1,Dados!$G:$G,J4) -> 0 | K27: =sumifs(Dados!$N:$N,Dados!$B:$B,$B$27,Dados!$H:$H,$D$1,Dados!$G:$G,K4) -> 0 | L27: =sumifs(Dados!$N:$N,Dados!$B:$B,$B$27,Dados!$H:$H,$D$1,Dados!$G:$G,L4) -> 0 | ... P27: =sumifs(Dados!$N:$N,Dados!$B:$B,$B$27,Dados!$H:$H,$D$1,Dados!$G:$G,P4) -> 0
B28: Booking Payment commision | D28: =SUM(E28:P28) -> 0 | E28: =sumifs(Dados!$N:$N,Dados!$B:$B,$B$28,Dados!$H:$H,$D$1,Dados!$G:$G,E4) -> 0 | F28: =sumifs(Dados!$N:$N,Dados!$B:$B,$B$28,Dados!$H:$H,$D$1,Dados!$G:$G,F4) -> 0 | G28: =sumifs(Dados!$N:$N,Dados!$B:$B,$B$28,Dados!$H:$H,$D$1,Dados!$G:$G,G4) -> 0 | H28: =sumifs(Dados!$N:$N,Dados!$B:$B,$B$28,Dados!$H:$H,$D$1,Dados!$G:$G,H4) -> 0 | I28: =sumifs(Dados!$N:$N,Dados!$B:$B,$B$28,Dados!$H:$H,$D$1,Dados!$G:$G,I4) -> 0 | J28: =sumifs(Dados!$N:$N,Dados!$B:$B,$B$28,Dados!$H:$H,$D$1,Dados!$G:$G,J4) -> 0 | K28: =sumifs(Dados!$N:$N,Dados!$B:$B,$B$28,Dados!$H:$H,$D$1,Dados!$G:$G,K4) -> 0 | L28: =sumifs(Dados!$N:$N,Dados!$B:$B,$B$28,Dados!$H:$H,$D$1,Dados!$G:$G,L4) -> 0 | ... P28: =sumifs(Dados!$N:$N,Dados!$B:$B,$B$28,Dados!$H:$H,$D$1,Dados!$G:$G,P4) -> 0
A29: Commission | B29: =sumifs(Dados!$N:$N,Dados!$A:$A,A29,Dados!$H:$H,$D$1) -> 0 | C29: =B29-D29 -> 0 | D29: =SUM(D25:D28) -> 0 | E29: =SUM(E25:E28) -> 0 | F29: =SUM(F25:F28) -> 0 | G29: =SUM(G25:G28) -> 0 | H29: =SUM(H25:H28) -> 0 | I29: =SUM(I25:I28) -> 0 | J29: =SUM(J25:J28) -> 0 | K29: =SUM(K25:K28) -> 0 | ... P29: =SUM(P25:P28) -> 0
B30: Aliguer TPEREDUNICRE MENSAL | D30: =SUM(E30:P30) -> 0 | E30: =sumifs(Dados!$N:$N,Dados!$B:$B,B30,Dados!$H:$H,$D$1,Dados!$G:$G,$E$4) -> 0 | F30: =sumifs(Dados!$N:$N,Dados!$B:$B,B30,Dados!$H:$H,$D$1,Dados!$G:$G,$F$4) -> 0 | G30: =sumifs(Dados!$N:$N,Dados!$B:$B,B30,Dados!$H:$H,$D$1,Dados!$G:$G,$G$4) -> 0 | H30: =sumifs(Dados!$N:$N,Dados!$B:$B,B30,Dados!$H:$H,$D$1,Dados!$G:$G,$H$4) -> 0 | I30: =sumifs(Dados!$N:$N,Dados!$B:$B,B30,Dados!$H:$H,$D$1,Dados!$G:$G,$I$4) -> 0 | J30: =sumifs(Dados!$N:$N,Dados!$B:$B,B30,Dados!$H:$H,$D$1,Dados!$G:$G,$J$4) -> 0 | K30: =sumifs(Dados!$N:$N,Dados!$B:$B,B30,Dados!$H:$H,$D$1,Dados!$G:$G,$K$4) -> 0 | L30: =sumifs(Dados!$N:$N,Dados!$B:$B,B30,Dados!$H:$H,$D$1,Dados!$G:$G,$L$4) -> 0 | M30: =sumifs(Dados!$N:$N,Dados!$B:$B,B30,Dados!$H:$H,$D$1,Dados!$G:$G,$M$4) -> 0 | N30: =sumifs(Dados!$N:$N,Dados!$B:$B,B30,Dados!$H:$H,$D$1,Dados!$G:$G,$N$4) -> 0 | O30: =sumifs(Dados!$N:$N,Dados!$B:$B,B30,Dados!$H:$H,$D$1,Dados!$G:$G,$O$4) -> 0 | P30: =sumifs(Dados!$N:$N,Dados!$B:$B,B30,Dados!$H:$H,$D$1,Dados!$G:$G,$P$4) -> 0
B31: Fees | D31: =SUM(E31:P31) -> 49.83 | E31: =sumifs(Dados!$N:$N,Dados!$B:$B,$B$31,Dados!$H:$H,$D$1,Dados!$G:$G,E4) -> 5.19 | F31: =sumifs(Dados!$N:$N,Dados!$B:$B,$B$31,Dados!$H:$H,$D$1,Dados!$G:$G,F4) -> 8.31 | G31: =sumifs(Dados!$N:$N,Dados!$B:$B,$B$31,Dados!$H:$H,$D$1,Dados!$G:$G,G4) -> 5.19 | H31: =sumifs(Dados!$N:$N,Dados!$B:$B,$B$31,Dados!$H:$H,$D$1,Dados!$G:$G,H4) -> 5.19 | I31: =sumifs(Dados!$N:$N,Dados!$B:$B,$B$31,Dados!$H:$H,$D$1,Dados!$G:$G,I4) -> 5.19 | J31: =sumifs(Dados!$N:$N,Dados!$B:$B,$B$31,Dados!$H:$H,$D$1,Dados!$G:$G,J4) -> 5.19 | K31: =sumifs(Dados!$N:$N,Dados!$B:$B,$B$31,Dados!$H:$H,$D$1,Dados!$G:$G,K4) -> 5.19 | L31: =sumifs(Dados!$N:$N,Dados!$B:$B,$B$31,Dados!$H:$H,$D$1,Dados!$G:$G,L4) -> 5.19 | ... P31: =sumifs(Dados!$N:$N,Dados!$B:$B,$B$31,Dados!$H:$H,$D$1,Dados!$G:$G,P4) -> 0
B32: Madalena8-BPI | D32: =SUM(E32:P32) -> 0 | E32: =sumifs(Dados!$N:$N,Dados!$B:$B,B32,Dados!$H:$H,$D$1,Dados!$G:$G,$E$4) -> 0 | F32: =sumifs(Dados!$N:$N,Dados!$B:$B,B32,Dados!$H:$H,$D$1,Dados!$G:$G,$F$4) -> 0 | G32: =sumifs(Dados!$N:$N,Dados!$B:$B,B32,Dados!$H:$H,$D$1,Dados!$G:$G,$G$4) -> 0 | H32: =sumifs(Dados!$N:$N,Dados!$B:$B,B32,Dados!$H:$H,$D$1,Dados!$G:$G,$H$4) -> 0 | I32: =sumifs(Dados!$N:$N,Dados!$B:$B,B32,Dados!$H:$H,$D$1,Dados!$G:$G,$I$4) -> 0 | J32: =sumifs(Dados!$N:$N,Dados!$B:$B,B32,Dados!$H:$H,$D$1,Dados!$G:$G,$J$4) -> 0 | K32: =sumifs(Dados!$N:$N,Dados!$B:$B,B32,Dados!$H:$H,$D$1,Dados!$G:$G,$K$4) -> 0 | L32: =sumifs(Dados!$N:$N,Dados!$B:$B,B32,Dados!$H:$H,$D$1,Dados!$G:$G,$L$4) -> 0 | M32: =sumifs(Dados!$N:$N,Dados!$B:$B,B32,Dados!$H:$H,$D$1,Dados!$G:$G,$M$4) -> 0 | N32: =sumifs(Dados!$N:$N,Dados!$B:$B,B32,Dados!$H:$H,$D$1,Dados!$G:$G,$N$4) -> 0 | O32: =sumifs(Dados!$N:$N,Dados!$B:$B,B32,Dados!$H:$H,$D$1,Dados!$G:$G,$O$4) -> 0 | P32: =sumifs(Dados!$N:$N,Dados!$B:$B,B32,Dados!$H:$H,$D$1,Dados!$G:$G,$P$4) -> 0
B33: Paylink | D33: =SUM(E33:P33) -> 21.01 | E33: =sumifs(Dados!$N:$N,Dados!$B:$B,B33,Dados!$H:$H,$D$1,Dados!$G:$G,$E$4) -> 0 | F33: =sumifs(Dados!$N:$N,Dados!$B:$B,B33,Dados!$H:$H,$D$1,Dados!$G:$G,$F$4) -> 0 | G33: =sumifs(Dados!$N:$N,Dados!$B:$B,B33,Dados!$H:$H,$D$1,Dados!$G:$G,$G$4) -> 0 | H33: =sumifs(Dados!$N:$N,Dados!$B:$B,B33,Dados!$H:$H,$D$1,Dados!$G:$G,$H$4) -> 0 | I33: =sumifs(Dados!$N:$N,Dados!$B:$B,B33,Dados!$H:$H,$D$1,Dados!$G:$G,$I$4) -> 0 | J33: =sumifs(Dados!$N:$N,Dados!$B:$B,B33,Dados!$H:$H,$D$1,Dados!$G:$G,$J$4) -> 21.01 | K33: =sumifs(Dados!$N:$N,Dados!$B:$B,B33,Dados!$H:$H,$D$1,Dados!$G:$G,$K$4) -> 0 | L33: =sumifs(Dados!$N:$N,Dados!$B:$B,B33,Dados!$H:$H,$D$1,Dados!$G:$G,$L$4) -> 0 | M33: =sumifs(Dados!$N:$N,Dados!$B:$B,B33,Dados!$H:$H,$D$1,Dados!$G:$G,$M$4) -> 0 | N33: =sumifs(Dados!$N:$N,Dados!$B:$B,B33,Dados!$H:$H,$D$1,Dados!$G:$G,$N$4) -> 0 | O33: =sumifs(Dados!$N:$N,Dados!$B:$B,B33,Dados!$H:$H,$D$1,Dados!$G:$G,$O$4) -> 0 | P33: =sumifs(Dados!$N:$N,Dados!$B:$B,B33,Dados!$H:$H,$D$1,Dados!$G:$G,$P$4) -> 0
A34: Bpi | B34: =sumifs(Dados!$N:$N,Dados!$A:$A,A34,Dados!$H:$H,$D$1) -> 70.84 | C34: =B34-D34 -> 0 | D34: =SUM(D30:D33) -> 70.84 | E34: =SUM(E30:E33) -> 5.19 | F34: =SUM(F30:F33) -> 8.31 | G34: =SUM(G30:G33) -> 5.19 | H34: =SUM(H30:H33) -> 5.19 | I34: =SUM(I30:I33) -> 5.19 | J34: =SUM(J30:J33) -> 26.2 | K34: =SUM(K30:K33) -> 5.19 | ... P34: =SUM(P30:P33) -> 0
B35: Banana | D35: =SUM(E35:P35) -> 15.05 | E35: =sumifs(Dados!$N:$N,Dados!$B:$B,B35,Dados!$H:$H,$D$1,Dados!$G:$G,$E$4) -> 0 | F35: =sumifs(Dados!$N:$N,Dados!$B:$B,B35,Dados!$H:$H,$D$1,Dados!$G:$G,$F$4) -> 0 | G35: =sumifs(Dados!$N:$N,Dados!$B:$B,B35,Dados!$H:$H,$D$1,Dados!$G:$G,$G$4) -> 0 | H35: =sumifs(Dados!$N:$N,Dados!$B:$B,B35,Dados!$H:$H,$D$1,Dados!$G:$G,$H$4) -> 0 | I35: =sumifs(Dados!$N:$N,Dados!$B:$B,B35,Dados!$H:$H,$D$1,Dados!$G:$G,$I$4) -> 0 | J35: =sumifs(Dados!$N:$N,Dados!$B:$B,B35,Dados!$H:$H,$D$1,Dados!$G:$G,$J$4) -> 5.1 | K35: =sumifs(Dados!$N:$N,Dados!$B:$B,B35,Dados!$H:$H,$D$1,Dados!$G:$G,$K$4) -> 1.16 | L35: =sumifs(Dados!$N:$N,Dados!$B:$B,B35,Dados!$H:$H,$D$1,Dados!$G:$G,$L$4) -> 3.64 | M35: =sumifs(Dados!$N:$N,Dados!$B:$B,B35,Dados!$H:$H,$D$1,Dados!$G:$G,$M$4) -> 5.15 | N35: =sumifs(Dados!$N:$N,Dados!$B:$B,B35,Dados!$H:$H,$D$1,Dados!$G:$G,$N$4) -> 0 | O35: =sumifs(Dados!$N:$N,Dados!$B:$B,B35,Dados!$H:$H,$D$1,Dados!$G:$G,$O$4) -> 0 | P35: =sumifs(Dados!$N:$N,Dados!$B:$B,B35,Dados!$H:$H,$D$1,Dados!$G:$G,$P$4) -> 0
B36: Butter | D36: =SUM(E36:P36) -> 107.88 | E36: =sumifs(Dados!$N:$N,Dados!$B:$B,B36,Dados!$H:$H,$D$1,Dados!$G:$G,$E$4) -> 0 | F36: =sumifs(Dados!$N:$N,Dados!$B:$B,B36,Dados!$H:$H,$D$1,Dados!$G:$G,$F$4) -> 0 | G36: =sumifs(Dados!$N:$N,Dados!$B:$B,B36,Dados!$H:$H,$D$1,Dados!$G:$G,$G$4) -> 0 | H36: =sumifs(Dados!$N:$N,Dados!$B:$B,B36,Dados!$H:$H,$D$1,Dados!$G:$G,$H$4) -> 25.08 | I36: =sumifs(Dados!$N:$N,Dados!$B:$B,B36,Dados!$H:$H,$D$1,Dados!$G:$G,$I$4) -> 10.45 | J36: =sumifs(Dados!$N:$N,Dados!$B:$B,B36,Dados!$H:$H,$D$1,Dados!$G:$G,$J$4) -> 29.4 | K36: =sumifs(Dados!$N:$N,Dados!$B:$B,B36,Dados!$H:$H,$D$1,Dados!$G:$G,$K$4) -> 22.05 | L36: =sumifs(Dados!$N:$N,Dados!$B:$B,B36,Dados!$H:$H,$D$1,Dados!$G:$G,$L$4) -> 20.9 | M36: =sumifs(Dados!$N:$N,Dados!$B:$B,B36,Dados!$H:$H,$D$1,Dados!$G:$G,$M$4) -> 0 | N36: =sumifs(Dados!$N:$N,Dados!$B:$B,B36,Dados!$H:$H,$D$1,Dados!$G:$G,$N$4) -> 0 | O36: =sumifs(Dados!$N:$N,Dados!$B:$B,B36,Dados!$H:$H,$D$1,Dados!$G:$G,$O$4) -> 0 | P36: =sumifs(Dados!$N:$N,Dados!$B:$B,B36,Dados!$H:$H,$D$1,Dados!$G:$G,$P$4) -> 0
B37: Cacao | D37: =SUM(E37:P37) -> 4.29 | E37: =sumifs(Dados!$N:$N,Dados!$B:$B,B37,Dados!$H:$H,$D$1,Dados!$G:$G,$E$4) -> 0 | F37: =sumifs(Dados!$N:$N,Dados!$B:$B,B37,Dados!$H:$H,$D$1,Dados!$G:$G,$F$4) -> 0 | G37: =sumifs(Dados!$N:$N,Dados!$B:$B,B37,Dados!$H:$H,$D$1,Dados!$G:$G,$G$4) -> 0 | H37: =sumifs(Dados!$N:$N,Dados!$B:$B,B37,Dados!$H:$H,$D$1,Dados!$G:$G,$H$4) -> 4.29 | I37: =sumifs(Dados!$N:$N,Dados!$B:$B,B37,Dados!$H:$H,$D$1,Dados!$G:$G,$I$4) -> 0 | J37: =sumifs(Dados!$N:$N,Dados!$B:$B,B37,Dados!$H:$H,$D$1,Dados!$G:$G,$J$4) -> 0 | K37: =sumifs(Dados!$N:$N,Dados!$B:$B,B37,Dados!$H:$H,$D$1,Dados!$G:$G,$K$4) -> 0 | L37: =sumifs(Dados!$N:$N,Dados!$B:$B,B37,Dados!$H:$H,$D$1,Dados!$G:$G,$L$4) -> 0 | M37: =sumifs(Dados!$N:$N,Dados!$B:$B,B37,Dados!$H:$H,$D$1,Dados!$G:$G,$M$4) -> 0 | N37: =sumifs(Dados!$N:$N,Dados!$B:$B,B37,Dados!$H:$H,$D$1,Dados!$G:$G,$N$4) -> 0 | O37: =sumifs(Dados!$N:$N,Dados!$B:$B,B37,Dados!$H:$H,$D$1,Dados!$G:$G,$O$4) -> 0 | P37: =sumifs(Dados!$N:$N,Dados!$B:$B,B37,Dados!$H:$H,$D$1,Dados!$G:$G,$P$4) -> 0
B38: Canela | D38: =SUM(E38:P38) -> 6.85 | E38: =sumifs(Dados!$N:$N,Dados!$B:$B,B38,Dados!$H:$H,$D$1,Dados!$G:$G,$E$4) -> 0 | F38: =sumifs(Dados!$N:$N,Dados!$B:$B,B38,Dados!$H:$H,$D$1,Dados!$G:$G,$F$4) -> 0 | G38: =sumifs(Dados!$N:$N,Dados!$B:$B,B38,Dados!$H:$H,$D$1,Dados!$G:$G,$G$4) -> 0 | H38: =sumifs(Dados!$N:$N,Dados!$B:$B,B38,Dados!$H:$H,$D$1,Dados!$G:$G,$H$4) -> 2.49 | I38: =sumifs(Dados!$N:$N,Dados!$B:$B,B38,Dados!$H:$H,$D$1,Dados!$G:$G,$I$4) -> 0 | J38: =sumifs(Dados!$N:$N,Dados!$B:$B,B38,Dados!$H:$H,$D$1,Dados!$G:$G,$J$4) -> 0 | K38: =sumifs(Dados!$N:$N,Dados!$B:$B,B38,Dados!$H:$H,$D$1,Dados!$G:$G,$K$4) -> 0 | L38: =sumifs(Dados!$N:$N,Dados!$B:$B,B38,Dados!$H:$H,$D$1,Dados!$G:$G,$L$4) -> 0 | M38: =sumifs(Dados!$N:$N,Dados!$B:$B,B38,Dados!$H:$H,$D$1,Dados!$G:$G,$M$4) -> 4.36 | N38: =sumifs(Dados!$N:$N,Dados!$B:$B,B38,Dados!$H:$H,$D$1,Dados!$G:$G,$N$4) -> 0 | O38: =sumifs(Dados!$N:$N,Dados!$B:$B,B38,Dados!$H:$H,$D$1,Dados!$G:$G,$O$4) -> 0 | P38: =sumifs(Dados!$N:$N,Dados!$B:$B,B38,Dados!$H:$H,$D$1,Dados!$G:$G,$P$4) -> 0
B39: Coffee | D39: =SUM(E39:P39) -> 507.5 | E39: =sumifs(Dados!$N:$N,Dados!$B:$B,B39,Dados!$H:$H,$D$1,Dados!$G:$G,$E$4) -> 0 | F39: =sumifs(Dados!$N:$N,Dados!$B:$B,B39,Dados!$H:$H,$D$1,Dados!$G:$G,$F$4) -> 0 | G39: =sumifs(Dados!$N:$N,Dados!$B:$B,B39,Dados!$H:$H,$D$1,Dados!$G:$G,$G$4) -> 0 | H39: =sumifs(Dados!$N:$N,Dados!$B:$B,B39,Dados!$H:$H,$D$1,Dados!$G:$G,$H$4) -> 59 | I39: =sumifs(Dados!$N:$N,Dados!$B:$B,B39,Dados!$H:$H,$D$1,Dados!$G:$G,$I$4) -> 59.1 | J39: =sumifs(Dados!$N:$N,Dados!$B:$B,B39,Dados!$H:$H,$D$1,Dados!$G:$G,$J$4) -> 94.6 | K39: =sumifs(Dados!$N:$N,Dados!$B:$B,B39,Dados!$H:$H,$D$1,Dados!$G:$G,$K$4) -> 121.11 | L39: =sumifs(Dados!$N:$N,Dados!$B:$B,B39,Dados!$H:$H,$D$1,Dados!$G:$G,$L$4) -> 85.19 | M39: =sumifs(Dados!$N:$N,Dados!$B:$B,B39,Dados!$H:$H,$D$1,Dados!$G:$G,$M$4) -> 88.5 | N39: =sumifs(Dados!$N:$N,Dados!$B:$B,B39,Dados!$H:$H,$D$1,Dados!$G:$G,$N$4) -> 0 | O39: =sumifs(Dados!$N:$N,Dados!$B:$B,B39,Dados!$H:$H,$D$1,Dados!$G:$G,$O$4) -> 0 | P39: =sumifs(Dados!$N:$N,Dados!$B:$B,B39,Dados!$H:$H,$D$1,Dados!$G:$G,$P$4) -> 0
B40: Coffee filter | D40: =SUM(E40:P40) -> 0 | E40: =sumifs(Dados!$N:$N,Dados!$B:$B,B40,Dados!$H:$H,$D$1,Dados!$G:$G,$E$4) -> 0 | F40: =sumifs(Dados!$N:$N,Dados!$B:$B,B40,Dados!$H:$H,$D$1,Dados!$G:$G,$F$4) -> 0 | G40: =sumifs(Dados!$N:$N,Dados!$B:$B,B40,Dados!$H:$H,$D$1,Dados!$G:$G,$G$4) -> 0 | H40: =sumifs(Dados!$N:$N,Dados!$B:$B,B40,Dados!$H:$H,$D$1,Dados!$G:$G,$H$4) -> 0 | I40: =sumifs(Dados!$N:$N,Dados!$B:$B,B40,Dados!$H:$H,$D$1,Dados!$G:$G,$I$4) -> 0 | J40: =sumifs(Dados!$N:$N,Dados!$B:$B,B40,Dados!$H:$H,$D$1,Dados!$G:$G,$J$4) -> 0 | K40: =sumifs(Dados!$N:$N,Dados!$B:$B,B40,Dados!$H:$H,$D$1,Dados!$G:$G,$K$4) -> 0 | L40: =sumifs(Dados!$N:$N,Dados!$B:$B,B40,Dados!$H:$H,$D$1,Dados!$G:$G,$L$4) -> 0 | M40: =sumifs(Dados!$N:$N,Dados!$B:$B,B40,Dados!$H:$H,$D$1,Dados!$G:$G,$M$4) -> 0 | N40: =sumifs(Dados!$N:$N,Dados!$B:$B,B40,Dados!$H:$H,$D$1,Dados!$G:$G,$N$4) -> 0 | O40: =sumifs(Dados!$N:$N,Dados!$B:$B,B40,Dados!$H:$H,$D$1,Dados!$G:$G,$O$4) -> 0 | P40: =sumifs(Dados!$N:$N,Dados!$B:$B,B40,Dados!$H:$H,$D$1,Dados!$G:$G,$P$4) -> 0
B41: Flakes | D41: =SUM(E41:P41) -> 35.88 | E41: =sumifs(Dados!$N:$N,Dados!$B:$B,B41,Dados!$H:$H,$D$1,Dados!$G:$G,$E$4) -> 0 | F41: =sumifs(Dados!$N:$N,Dados!$B:$B,B41,Dados!$H:$H,$D$1,Dados!$G:$G,$F$4) -> 0 | G41: =sumifs(Dados!$N:$N,Dados!$B:$B,B41,Dados!$H:$H,$D$1,Dados!$G:$G,$G$4) -> 0 | H41: =sumifs(Dados!$N:$N,Dados!$B:$B,B41,Dados!$H:$H,$D$1,Dados!$G:$G,$H$4) -> 8.97 | I41: =sumifs(Dados!$N:$N,Dados!$B:$B,B41,Dados!$H:$H,$D$1,Dados!$G:$G,$I$4) -> 0 | J41: =sumifs(Dados!$N:$N,Dados!$B:$B,B41,Dados!$H:$H,$D$1,Dados!$G:$G,$J$4) -> 8.97 | K41: =sumifs(Dados!$N:$N,Dados!$B:$B,B41,Dados!$H:$H,$D$1,Dados!$G:$G,$K$4) -> 0 | L41: =sumifs(Dados!$N:$N,Dados!$B:$B,B41,Dados!$H:$H,$D$1,Dados!$G:$G,$L$4) -> 0 | M41: =sumifs(Dados!$N:$N,Dados!$B:$B,B41,Dados!$H:$H,$D$1,Dados!$G:$G,$M$4) -> 17.94 | N41: =sumifs(Dados!$N:$N,Dados!$B:$B,B41,Dados!$H:$H,$D$1,Dados!$G:$G,$N$4) -> 0 | O41: =sumifs(Dados!$N:$N,Dados!$B:$B,B41,Dados!$H:$H,$D$1,Dados!$G:$G,$O$4) -> 0 | P41: =sumifs(Dados!$N:$N,Dados!$B:$B,B41,Dados!$H:$H,$D$1,Dados!$G:$G,$P$4) -> 0
B42: Flour | D42: =SUM(E42:P42) -> 322.98 | E42: =sumifs(Dados!$N:$N,Dados!$B:$B,B42,Dados!$H:$H,$D$1,Dados!$G:$G,$E$4) -> 0 | F42: =sumifs(Dados!$N:$N,Dados!$B:$B,B42,Dados!$H:$H,$D$1,Dados!$G:$G,$F$4) -> 0 | G42: =sumifs(Dados!$N:$N,Dados!$B:$B,B42,Dados!$H:$H,$D$1,Dados!$G:$G,$G$4) -> 0 | H42: =sumifs(Dados!$N:$N,Dados!$B:$B,B42,Dados!$H:$H,$D$1,Dados!$G:$G,$H$4) -> 39.8 | I42: =sumifs(Dados!$N:$N,Dados!$B:$B,B42,Dados!$H:$H,$D$1,Dados!$G:$G,$I$4) -> 59.7 | J42: =sumifs(Dados!$N:$N,Dados!$B:$B,B42,Dados!$H:$H,$D$1,Dados!$G:$G,$J$4) -> 40.27 | K42: =sumifs(Dados!$N:$N,Dados!$B:$B,B42,Dados!$H:$H,$D$1,Dados!$G:$G,$K$4) -> 99.5 | L42: =sumifs(Dados!$N:$N,Dados!$B:$B,B42,Dados!$H:$H,$D$1,Dados!$G:$G,$L$4) -> 37.28 | M42: =sumifs(Dados!$N:$N,Dados!$B:$B,B42,Dados!$H:$H,$D$1,Dados!$G:$G,$M$4) -> 46.43 | N42: =sumifs(Dados!$N:$N,Dados!$B:$B,B42,Dados!$H:$H,$D$1,Dados!$G:$G,$N$4) -> 0 | O42: =sumifs(Dados!$N:$N,Dados!$B:$B,B42,Dados!$H:$H,$D$1,Dados!$G:$G,$O$4) -> 0 | P42: =sumifs(Dados!$N:$N,Dados!$B:$B,B42,Dados!$H:$H,$D$1,Dados!$G:$G,$P$4) -> 0
B43: Fruits | D43: =SUM(E43:P43) -> 25.13 | E43: =sumifs(Dados!$N:$N,Dados!$B:$B,B43,Dados!$H:$H,$D$1,Dados!$G:$G,$E$4) -> 0 | F43: =sumifs(Dados!$N:$N,Dados!$B:$B,B43,Dados!$H:$H,$D$1,Dados!$G:$G,$F$4) -> 0 | G43: =sumifs(Dados!$N:$N,Dados!$B:$B,B43,Dados!$H:$H,$D$1,Dados!$G:$G,$G$4) -> 0 | H43: =sumifs(Dados!$N:$N,Dados!$B:$B,B43,Dados!$H:$H,$D$1,Dados!$G:$G,$H$4) -> 0 | I43: =sumifs(Dados!$N:$N,Dados!$B:$B,B43,Dados!$H:$H,$D$1,Dados!$G:$G,$I$4) -> 5.45 | J43: =sumifs(Dados!$N:$N,Dados!$B:$B,B43,Dados!$H:$H,$D$1,Dados!$G:$G,$J$4) -> 0 | K43: =sumifs(Dados!$N:$N,Dados!$B:$B,B43,Dados!$H:$H,$D$1,Dados!$G:$G,$K$4) -> 0 | L43: =sumifs(Dados!$N:$N,Dados!$B:$B,B43,Dados!$H:$H,$D$1,Dados!$G:$G,$L$4) -> 8.51 | M43: =sumifs(Dados!$N:$N,Dados!$B:$B,B43,Dados!$H:$H,$D$1,Dados!$G:$G,$M$4) -> 11.17 | N43: =sumifs(Dados!$N:$N,Dados!$B:$B,B43,Dados!$H:$H,$D$1,Dados!$G:$G,$N$4) -> 0 | O43: =sumifs(Dados!$N:$N,Dados!$B:$B,B43,Dados!$H:$H,$D$1,Dados!$G:$G,$O$4) -> 0 | P43: =sumifs(Dados!$N:$N,Dados!$B:$B,B43,Dados!$H:$H,$D$1,Dados!$G:$G,$P$4) -> 0
B44: Gas-Café da manhã | D44: =SUM(E44:P44) -> 0 | E44: =sumifs(Dados!$N:$N,Dados!$B:$B,B44,Dados!$H:$H,$D$1,Dados!$G:$G,$E$4) -> 0 | F44: =sumifs(Dados!$N:$N,Dados!$B:$B,B44,Dados!$H:$H,$D$1,Dados!$G:$G,$F$4) -> 0 | G44: =sumifs(Dados!$N:$N,Dados!$B:$B,B44,Dados!$H:$H,$D$1,Dados!$G:$G,$G$4) -> 0 | H44: =sumifs(Dados!$N:$N,Dados!$B:$B,B44,Dados!$H:$H,$D$1,Dados!$G:$G,$H$4) -> 0 | I44: =sumifs(Dados!$N:$N,Dados!$B:$B,B44,Dados!$H:$H,$D$1,Dados!$G:$G,$I$4) -> 0 | J44: =sumifs(Dados!$N:$N,Dados!$B:$B,B44,Dados!$H:$H,$D$1,Dados!$G:$G,$J$4) -> 0 | K44: =sumifs(Dados!$N:$N,Dados!$B:$B,B44,Dados!$H:$H,$D$1,Dados!$G:$G,$K$4) -> 0 | L44: =sumifs(Dados!$N:$N,Dados!$B:$B,B44,Dados!$H:$H,$D$1,Dados!$G:$G,$L$4) -> 0 | M44: =sumifs(Dados!$N:$N,Dados!$B:$B,B44,Dados!$H:$H,$D$1,Dados!$G:$G,$M$4) -> 0 | N44: =sumifs(Dados!$N:$N,Dados!$B:$B,B44,Dados!$H:$H,$D$1,Dados!$G:$G,$N$4) -> 0 | O44: =sumifs(Dados!$N:$N,Dados!$B:$B,B44,Dados!$H:$H,$D$1,Dados!$G:$G,$O$4) -> 0 | P44: =sumifs(Dados!$N:$N,Dados!$B:$B,B44,Dados!$H:$H,$D$1,Dados!$G:$G,$P$4) -> 0
